File: RHTT_L_LUB_Ex_true_stress_strain.csv
True Strain,True Stress (MPa),Lower Bound (MPa),Upper Bound (MPa)
-0.00038621357086070874,2.084236550762542,2.084236550762542,2.084236550762542
-2.310195153269507e-05,0.5758889098217925,-0.852731962769479,2.0045097824130638
0.0003398778656046868,26.46278884099298,8.3586354422203,44.56694223976566
0.0007027259761999017,58.39122090778703,40.486080408116464,76.2963614074576
0.0010654424757968906,85.36280657025442,67.92038319135841,102.80522994915044
0.001428027459836443,116.88970104597207,99.72936437394668,134.05003771799747
0.0017904810236549036,137.71080350597396,122.66134401105245,152.76026300089546
0.0021528032624849908,161.71181821394615,151.1605195128105,172.2631169150818
0.00251499427145661,190.39235630024828,176.7064744423637,204.07823815813285
0.0028770541455956735,214.30910113326328,201.86123089357687,226.75697137294966
0.003238982979824916,243.7434334851008,228.86088845737012,258.6259785128315
0.0036007808689647084,264.8666759517052,246.5097060271661,283.22364587624435
0.003962447907731655,286.54829011866195,277.16646159756516,295.93011863975875
0.004323984190740516,294.90331517210404,285.9789827783553,303.82764756585277
0.004685389812502803,304.2632478564636,300.4514030858862,308.075092627041
0.005046664867427596,308.93288611242514,305.455369028774,312.41040319607623
0.005407809449822352,312.84648877189665,310.36706326414514,315.32591427964815
0.005768823653891724,315.19417727037154,312.9000056211288,317.48834891961434
0.006129707573738375,317.130161090302,314.798391377981,319.4619308026231
0.006490461303363788,318.7795634211142,316.39647236020267,321.16265448202563
0.006851084936667085,320.15330436852616,317.87902610690594,322.4275826301464
0.00721157856744584,321.2627776165403,319.10720506609647,323.41835016698406
0.007571942289396881,322.1391903939703,320.0016117758402,324.2767690121004
0.007932176196114901,322.982059815466,320.8162764042113,325.1478432267207
0.008292280381094357,323.58046043590883,321.48014542147337,325.6807754503443
0.008652254937728083,324.20188480704155,321.9475198817636,326.4562497323196
0.00901209995930809,324.76849018085034,322.5784701516732,326.9585102100275
0.009371815539026376,325.15146382486165,322.9588447862396,327.3440828634837
0.009731401769973742,325.74737777293024,323.62324611563713,327.87150943022334
0.010090858745140608,326.1087607184107,323.9644433448537,328.25307809196767
0.01045018655741781,326.46080016282093,324.34938537456986,328.57221495107194
0.010809385299595424,327.0514187123196,324.90080576138405,329.2020316632551
0.011168455064363574,327.3195631351949,325.1493910829149,329.48973518747493
0.01152739594431323,327.56161669716505,325.45759432153756,329.6656390727925
0.011886208031935035,327.97647491890797,325.9287315809528,330.0242182568632
0.01224489141962011,328.3186864874453,326.2462261161564,330.39114685873415
0.012603446199660851,328.7546719605368,326.5742218124455,330.93512210862815
0.012961872464249536,329.17435058728705,327.137514758799,331.2111864157751
0.013320170305480222,329.3990746311932,327.39163370622646,331.40651555615995
0.013678339815347357,329.6361382246711,327.5543054829126,331.71797096642956
0.01403638108574657,330.0214584868813,327.88894380100595,332.15397317275654
0.01439429420847548,330.42551229697796,328.4196944546344,332.4313301393215
0.014752079275232515,330.7526646022263,328.7858985728456,332.7194306316069
0.015109736377617713,331.1463111175729,329.15956762874555,333.1330546064002
0.015467265607133521,331.4218565801606,329.5971168784909,333.2465962818303
0.01582466705518362,331.7098358160096,329.84617402742373,333.5734976045955
0.01618194081307372,332.14434549368616,330.26581672536645,334.0228742620059
0.01653908697201236,332.482687433754,330.68279595556,334.282578911948
0.01689610562310952,332.7804987838358,330.936688742702,334.6243088249696
0.017252996857378498,333.0463319320307,331.1964372193065,334.89622664475485
0.01760976076573453,333.29482848573383,331.42833246912824,335.16132450233937
0.017966397438995578,333.6252282782424,331.8167365415952,335.43372001488956
0.01832290696788313,334.0574283612144,332.27176158851074,335.84309513391815
0.01867928944302102,334.400551374111,332.5410393407979,336.260063407424
0.019035544954936232,334.7075802907276,332.75007024124835,336.66509034020686
0.01939167359405968,334.9798642177352,333.15524132725716,336.8044871082132
0.019747675450725054,335.3489304058658,333.52060535496946,337.1772554567622
0.020103550615169583,335.6438959965089,333.7687118535183,337.5190801394994
0.020459299177534866,336.00102911763713,334.12596837726556,337.87608985800864
0.02081492122786566,336.2873844763232,334.3804805070665,338.19428844557984
0.021170416856110708,336.56880331844815,334.76531840576,338.3722882311363
0.0215257861521235,336.9053314617054,335.08330973984545,338.7273531835653
0.021881029205660894,337.24035986995443,335.44145074796216,339.0392689919467
0.022236146106385003,337.72125908206846,335.8072232106263,339.63529495351065
0.0225911369438618,338.01855523062187,336.1506464472503,339.8864640139934
0.0229460018075619,338.27016806896216,336.5170136971283,340.02332244079605
0.023300740786861358,338.5074897182312,336.75462366434783,340.2603557721146
0.023655353971040495,338.98032607693057,337.1086211191362,340.852031034725
0.024009841449284686,339.3656845970769,337.51832678006565,341.21304241408814
0.02436420331068515,339.5487598523125,337.72964880231507,341.36787090230996
0.024718439644237762,339.8934197382696,338.1088886477441,341.67795082879513
0.02507255053884387,340.18638945810847,338.4160543480525,341.95672456816436
0.02542653608331106,340.5428653344922,338.7562788683988,342.3294518005856
0.025780396366351765,341.01363933089476,339.2216310380549,342.8056476237346
0.026134131476585155,341.33095069036807,339.54464069665505,343.11726068408103
0.02648774150253573,341.60621519035806,339.7893595681947,343.42307081252136
0.02684122653263412,341.967107663179,340.25732249957974,343.6768928267782
0.027194586655217862,342.21562497334634,340.5492025283619,343.8820474183308
0.027547821958530224,342.6189051835176,340.97492481138323,344.26288555565196
0.027900932530721,342.9223289745669,341.2713268575685,344.57333109156525
0.02825391845984729,343.2701738417128,341.63867144530013,344.9016762381254
0.028606779833872328,343.6870448530436,342.04563763484833,345.3284520712388
0.028959516740666255,343.9123581574824,342.2379896021134,345.5867267128514
0.02931212926800692,344.3028855705531,342.6547533816702,345.9510177594359
0.02966461750357848,344.5786336619651,342.98919404109444,346.16807328283585
0.030016981534973262,344.88098434185537,343.1330192722449,346.6289494114659
0.03036922144969039,345.1604273378691,343.4948774264007,346.8259772493376
0.030721337335136566,345.4583626550179,343.84517089375146,347.0715544162843
0.031073329278626823,345.89926491834126,344.2947377956491,347.5037920410334
0.03142519736738339,346.22104591118557,344.5710498743211,347.87104194805
0.031776941688536446,346.4411963257044,344.78677514010883,348.09561751129996
0.032128562329124914,346.74989206120733,345.11669147806754,348.3830926443471
0.03248005937609529,347.1157936984311,345.4445541593035,348.7870332375587
0.03283143291630242,347.3936920825819,345.6971140652822,349.09027009988154
0.03318268303651025,347.71571813522525,346.0624590545117,349.3689772159388
0.03353380982339072,348.113911762485,346.5799806577457,349.6478428672242
0.033884813363524474,348.339044674914,346.76758553097676,349.9105038188513
0.034235693743401685,348.79129094152887,347.09014876942615,350.4924331136316
0.03458645104942063,349.0190228584729,347.4228677677008,350.61517794924504
0.03493708536788959,349.2131732042881,347.69579320651997,350.7305532020562
0.03528759678502543,349.5063609842391,347.9249739001621,351.0877480683161
0.03563798538695438,349.90373760208877,348.2021170797144,351.6053581244631
0.03598825125971284,350.1838034126951,348.41167810404306,351.95592872134716
0.03633839448924616,350.5191643874463,348.8232419738446,352.2150868010481
0.03668841516140946,350.83248440259496,349.21566735970225,352.4493014454877
0.03703831336196837,351.04347300113517,349.4486409671785,352.6383050350918
0.037388089176597895,351.282827394514,349.65794325257514,352.9077115364529
0.03773774269088317,351.6227048187507,349.89489971432886,353.3505099231725
0.038087273990320206,352.06849025252,350.369201633634,353.76777887140594
0.038436683160314566,352.35773817301,350.61448231833833,354.10099402768157
0.038785970286183157,352.58555428278817,350.80263661432724,354.3684719512491
0.039135135453152885,352.88015177118325,351.11409719849036,354.6462063438761
0.03948417874636141,353.0878774617374,351.42165588663266,354.75409903684204
0.03983310025085791,353.3349782390815,351.63354263478664,355.0364138433764
0.04018190005160193,353.69303813708905,352.07409510273845,355.31198117143964
0.04053057823346415,353.94943719200023,352.23896181777866,355.65991256622186
0.04087913488122714,354.2550137637436,352.4714838309426,356.0385436965446
0.041227570079584185,354.5413282470663,352.8175067432911,356.2651497508415
0.04157588391314011,354.7476124368069,353.1276400290827,356.36758484453105
0.04192407646641198,355.1142111312009,353.49175491228243,356.73666735011926
0.04227214782382797,355.3434321363907,353.5056460161114,357.1812182566699
0.04262009806972811,355.5940448518628,353.82297300910255,357.36511669462305
0.04296792728836509,355.9429309270753,354.25974202865086,357.62611982549976
0.043315635563902846,356.24350672540174,354.5991909741653,357.88782247663823
0.04366322298041841,356.4717639085671,354.7799492444868,358.1635785726474
0.04401068962190051,356.74697546632405,355.0174945291935,358.4764564034545
0.04435803557225038,357.034726915536,355.2757168892348,358.79373694183727
0.0447052609152825,357.22815440093007,355.4828933184096,358.9734154834505
0.045052365734723404,357.52556158966075,355.7837181444599,359.2674050348616
0.0453993501142125,357.760701520689,356.0818395845448,359.4395634568332
0.045746214137302774,358.0292815306971,356.2761801408809,359.7823829205134
0.04609295788745969,358.38643018780806,356.59423701971815,360.17862335589797
0.046439581448061894,358.63427477249434,356.9330140645018,360.33553548048684
0.046786084902402,358.8102987889433,357.1638684407884,360.45672913709825
0.04713246833368523,359.0902765143191,357.4778639463946,360.7026890822436
0.047478731825031206,359.3617878354727,357.7552221627178,360.96835350822755
0.04782487545947262,359.5600701393748,357.9160390834377,361.20410119531186
0.04817089931995596,359.8715135818152,358.1867063429669,361.55632082066353
0.048516803489342265,360.1657039695751,358.4260714492836,361.9053364898666
0.048862588050406,360.39394012265103,358.6492860447653,362.1385942005368
0.049208253085835776,360.6559441064176,358.95669444198876,362.3551937708464
0.049553798678235145,360.91113947500907,359.2064335426878,362.6158454073303
0.04989922491012139,361.0851122109139,359.36619304016534,362.80403138166247
0.05024453186392634,361.32417874097104,359.57190856631576,363.0764489156263
0.0505897196219971,361.6705192305154,359.87459470328827,363.4664437577426
0.050934788266594644,361.85431942838466,360.0454057665693,363.66323309020004
0.051279737879895704,362.0731561674173,360.3385023834789,363.80780995135575
0.051624568543991355,362.34728646476964,360.60593737143415,364.08863555810507
0.05196928034088777,362.57373221671503,360.79603474077146,364.3514296926586
0.05231387335250699,362.826345540277,361.02145362850996,364.63123745204393
0.05265834766068575,363.07293113838693,361.3007514614029,364.8451108153709
0.05300270334717626,363.29691414567475,361.56729652254506,365.0265317688045
0.05334694049364692,363.59723235495926,361.87546622390914,365.3189984860093
0.0536910591816812,363.7813444085451,362.06689009806774,365.4957987190225
0.05403505949277835,363.9897853010652,362.23153770135247,365.7480329007779
0.05437894150835421,364.26481756629545,362.47353178423685,366.05610334835404
0.05472270530974001,364.46821043858785,362.6850617040358,366.2513591731399
0.05506635097818312,364.74931505874366,362.94908997019473,366.54954014729265
0.05540987859484782,364.9401305703448,363.20630153812806,366.67395960256164
0.05575328824081393,365.18228819156866,363.44244950035034,366.922126882787
0.056096579997078615,365.3254630579619,363.60349847850154,367.04742763742223
0.056439753944555006,365.49340635839997,363.8042736516223,367.18253906517765
0.056782810164072973,365.6974658117852,363.9458826924081,367.44904893116234
0.05712574873637986,365.99276876225724,364.23601634631643,367.74952117819805
0.05746856974213931,367.02739983407156,365.7280190726741,368.32678059546896
0.057811273261932083,367.385183860969,366.02316419275564,368.74720352918234
0.0581538593762567,367.59078476509444,366.30459863121615,368.87697089897273
0.058496328165528376,367.72970606095055,366.55473902295256,368.9046730989485
0.05883867971007972,367.9635861588923,366.8699342284926,369.05723808929207
0.059180914090161525,368.24631365846767,367.17536553924225,369.3172617776931
0.05952303138594133,368.3445224071336,367.22297441939196,369.46607039487526
0.05986503167750531,368.5146188823517,367.24419385892,369.7850439057835
0.060206915044856826,368.8147089023996,367.5297772961712,370.0996405086281
0.06054868156791724,368.94462147667303,367.6764258521832,370.21281710116284
0.06089033132652663,369.1510738594123,367.9201584479355,370.38198927088916
0.06123186440044262,369.4209703130138,368.2146360133601,370.62730461266756
0.06157328086934116,369.6355197276287,368.43930566093127,370.8317337943262
0.06191458081281725,369.84612233090786,368.65534699629546,371.03689766552026
0.062255764310383765,370.16271845727056,369.0840622475788,371.2413746669624
0.06259683144147225,370.22489999420253,369.0389839499123,371.4108160384928
0.06293778228543363,370.37717175880454,369.1092457819623,371.6450977356468
0.06327861692153706,370.74690493804826,369.5641839154022,371.92962596069435
0.06361933542897066,370.8932825280122,369.6799246498816,372.1066404061428
0.06395993788684227,371.03188077950534,369.8044975486721,372.25926401033865
0.0643004243741781,371.2871095083175,370.09744665486886,372.47677236176617
0.06464079496992446,371.5696991853701,370.3931508270965,372.7462475436436
0.06498104975294652,371.7820718963848,370.50151271284625,373.06263107992345
0.0653211888020289,371.8449184341099,370.6281014718722,373.0617353963476
0.06566121219587653,372.2174722184055,370.9914875617844,373.44345687502647
0.06600112001311344,372.350318294417,371.0356018822152,373.66503470661877
0.0663409123322835,372.48782250636515,371.1374372030075,373.8382078097228
0.06668058923185119,372.7210091609068,371.51089785891725,373.9311204628964
0.0670201507902004,372.80909363940685,371.6402691047126,373.97791817410115
0.06735959708563527,372.89184871888654,371.6833403557322,374.10035708204094
0.06769892819638076,373.240858680811,372.2165879200815,374.2651294415405
0.06803814420058145,373.42616799273253,372.28189967812415,374.5704363073409
0.06837724517630324,373.63560257098663,372.4478460143502,374.823359127623
0.06871623120153202,373.90026522569246,372.7376979105716,375.0628325408133
0.06905510235417439,374.0339053913648,372.84885900438616,375.21895177834335
0.06939385871205841,374.21445652626255,373.01280577037613,375.416107282149
0.06973250035293245,374.40378019610694,373.16677997213714,375.64078042007674
0.0700710273544659,374.55483705708986,373.3256809358499,375.78399317832987
0.07040943979424995,374.83990772286603,373.6597108565985,376.02010458913355
0.07074773774979638,374.94186434948745,373.77989993619803,376.1038287627769
0.07108592129853838,375.2078939853795,374.0137095809101,376.4020783898489
0.07142399051783122,375.327705718721,374.1641693997768,376.49124203766513
0.07176194548495085,375.37269227126984,374.21624835458204,376.52913618795765
0.0720997862770958,375.65098785046655,374.5165418717886,376.78543382914444
0.07243751297138575,375.7115201115362,374.4939168863169,376.9291233367555
0.07277512564486224,375.89512435727784,374.64524343578444,377.14500527877124
0.07311262437448944,376.18045715122093,374.92943711560883,377.431477186833
0.07345000923715303,376.28883874523564,375.09830820489077,377.4793692855805
0.07378728030966085,376.4256045221518,375.14975576270155,377.701453281602
0.0741244376687437,376.7799678442711,375.4264333685908,378.1335023199514
0.07446148139105416,376.9510950173541,375.6908791043387,378.21131093036945
0.07479841155316735,377.0114703488777,375.6952079648903,378.3277327328652
0.0751352282315816,377.1872572256494,375.91286486770827,378.46164958359043
0.0754719315027174,377.399633449824,376.17231069499917,378.6269562046489
0.07580852144291801,377.53845602548125,376.36528597615,378.71162607481256
0.0761449981284503,377.507635737383,376.03478218901864,378.98048928574735
0.07648136163550354,377.6775870161227,376.18090391895674,379.1742701132887
0.07681761204019014,378.1328277571766,376.44632809178256,379.81932742257055
0.07715374941854637,378.2624183329712,376.6117055510367,379.9131311149057
0.07748977384653105,378.29787097830695,376.69111574897977,379.9046262076341
0.07782568540002725,378.4535539107962,376.77049425721407,380.13661356437837
0.07816148415484102,378.5370382452388,376.84984107573956,380.2242354147381
0.07849717018670199,378.69335872861365,377.21406012833233,380.1726573288949
0.07883274357126427,378.8069915557646,377.17038393414293,380.44359917738626
0.07916820438410513,379.13209489865886,377.4235246768309,380.8406651204869
0.07950355270072584,379.2165768447858,377.54575139642844,380.8874022931431
0.07983878859655238,379.55127875132393,378.08835547013445,381.0142020325135
0.08017391214693424,379.7847450856674,377.9879804232212,381.5815097481136
0.0805089234271452,379.7278436774871,377.9749148275924,381.48077252738176
0.08084382251238403,379.9223641281122,378.4572600937242,381.3874681625001
0.08117860947777317,380.0956020531958,378.60261846939915,381.58858563699255
0.08151328439836039,380.2193171275354,378.7479893202325,381.69064493483836
0.08184784734911758,380.34630727511984,378.8933726462242,381.79924190401556
0.08218229840494143,380.594674784784,379.0387684473741,382.1505811221939
0.08251663764065403,380.78710280994056,379.1869438064397,382.38726181344146
0.08285086513100193,380.8302146422476,379.38513765620314,382.2752916282921
0.08318498095065668,380.8956820006514,379.5833792510525,382.20798475025026
0.08351898517421569,381.2133592945043,379.7816685909878,382.64504999802074
0.08385287787620098,381.2856944804483,379.7763020519245,382.79508690897205
0.08418665913105998,381.1334443678881,379.67984062949813,382.58704810627813
0.08452032901316618,381.4278046224907,379.78714070133384,383.06846854364755
0.08485388759681786,381.55209480618805,379.8944278230702,383.20976178930596
0.0851873349562398,381.6521801852381,380.0272742937534,383.27708607672275
0.08552067116558189,382.1614762311088,380.20316200272686,384.1197904594907
0.08585389629891994,381.9796346034274,380.37908249967995,383.5801867071749
0.08618701043025635,382.18395174396517,380.55503578461276,383.8128677033176
0.08652001363351894,382.4077449590431,380.7310218575252,384.08446806056094
0.08685290598256173,382.43196652160236,380.90704071841714,383.9568923247876
0.08718568755116561,382.7419472573535,381.0830923672889,384.4008021474181
0.08751835841303722,382.77618305714424,381.2591768041402,384.29318931014825
0.08785091864180969,382.9115372658704,381.36729083132406,384.4557837004167
0.08818336831104329,383.0500000010845,381.4172507560356,384.68274924613337
0.08851570749422413,383.1486192449873,381.5658678155406,384.73137067443395
0.08884793626476593,383.3294944927273,381.8440574862048,384.8149314992498
0.08918005469600865,383.5047814886831,382.0447631358638,384.9647998415024
0.08951206286121914,383.5706301274192,382.1618418966104,384.9794183582279
0.08984396083359199,383.67115569378024,382.2588797068651,385.08343168069536
0.09017574868624827,383.8221430558716,382.3558977246944,385.2883883870489
0.09050742649223632,384.0563506752636,382.45289595009797,385.65980540042926
0.09083899432453241,384.2561255253971,382.54987438307614,385.9623766677181
0.09117045225603965,384.40828506408764,382.7521230177889,386.0644471103863
0.09150180035958866,384.4460186444633,382.909887525104,385.9821497638226
0.09183303870793832,384.5118253036711,382.9258117357127,386.09783887162956
0.09216416737377463,384.6207441354233,383.00152102686815,386.2399672439785
0.09249518642971137,384.73808851301146,383.0892213271246,386.3869556988983
0.09282609594829087,384.9643467998599,383.28527452203184,386.64341907768795
0.09315689600198265,385.2625200840652,383.51067312242617,387.0143670457043
0.09348758666318517,385.31887592632677,383.73613693709586,386.90161491555773
0.09381816800422443,385.38310990481324,383.9616659660409,386.8045538435856
0.09414864009735478,385.60951513373493,384.187260209261,387.0317700582089
0.09447900301475952,385.87888264580494,384.41291966675647,387.3448456248534
0.09480925682854988,385.9895087729685,384.6879105369122,387.29110700902476
0.0951394016107656,385.88426230257517,384.1122370758984,387.656287529252
0.09546943743337576,385.82399228773767,384.13200858505644,387.51597599041895
0.09579936436827756,385.94411561307857,384.31079730991195,387.5774339162452
0.0961291824872971,386.12477482192196,384.4896203628318,387.75992928101215
0.09645889186219,386.3661043644213,384.66847774381597,388.0637309850266
0.09678849256464035,386.5170326055791,384.8473694528644,388.18669575829387
0.09711798466626137,386.52066706273973,385.0262954899771,388.0150386355024
0.09744736823859612,386.6699914282989,385.2052558551541,388.13472700144365
0.0977766433531162,386.8633422961581,385.3794986268025,388.3471859655138
0.09810581008122339,387.0978285791069,385.52422752744405,388.6714296307697
0.09843486849424844,387.1983292589834,385.61805718138055,388.77860133658623
0.09876381866345167,387.2174603948688,385.7032615443807,388.7316592453568
0.0990926606600237,387.3675247612007,385.7884385000583,388.94661102234306
0.09942139455508438,387.45863016350506,385.87358804841324,389.0436722785969
0.0997500204196834,387.5631631615668,385.9587101894454,389.1676161336883
0.10007853832480103,387.67437539131,386.043804923155,389.304945859465
0.10040694834134704,387.79735506199626,386.12887224954187,389.4658378744506
0.10073525054016134,387.9318870349929,386.21391216860604,389.6498619013798
0.10106344499201468,388.02655851396815,386.29892468034757,389.75419234758874
0.10139153176760739,388.0934705591023,386.38360686394526,389.80333425425925
0.10171951093757099,388.14896179674656,386.47858027268006,389.8193433208131
0.10204738257246697,388.2998105424332,386.59834655522644,390.00127452963994
0.1023751467427874,388.5343087216464,386.7181082680852,390.3505091752077
0.10270280351895568,388.65428103846125,386.8378654112566,390.4706966656659
0.1030303529713254,388.73119412363013,386.9512537752685,390.5111344719917
0.10335779517018104,388.8137040989096,387.0584426074445,390.5689655903748
0.10368513018573866,388.9660319986178,387.1656186478385,390.76644534939703
0.10401235808814481,389.48312659533184,387.2727818964506,391.69347129421305
0.10433947894747718,389.4231700936351,387.3640329555974,391.48230723167285
0.1046664928337453,389.30299851722293,387.4996605785578,391.106336455888
0.10499339981688925,389.18790133777645,387.6457665793124,390.7300360962405
0.10532019996678137,389.29549258911675,387.7477284995749,390.8432566786585
0.10564689335322487,389.6149079183013,387.84967425144305,391.3801415851596
0.10597348004595461,389.7089037494303,387.9516038349166,391.46620366394393
0.10629996011463773,389.44979486505474,388.05351724999576,390.84607248011366
0.10662633362887255,389.7968018451527,388.15541449668063,391.43818919362474
0.10695260065818932,390.1558672205836,388.25729557497084,392.05443886619634
0.10727876127205076,390.3673583969093,388.35916048486666,392.3755563089519
0.10760481553985111,390.531368282994,388.4610092263682,392.6017273396197
0.10793076353091677,390.69774313286774,388.56752385940916,392.8279624063263
0.10825660531450691,390.6049076423524,388.66559148361307,392.5442238010917
0.10858234095981227,390.3944346131959,388.74013309376943,392.0487361326225
0.10890797053595677,390.3484162313354,388.8146407800131,391.88219168265766
0.10923349411199626,390.88506603770116,388.8891145423438,392.8810175330586
0.10955891175691912,391.06617271814264,388.9635543807614,393.1687910555239
0.10988422353964705,391.1023040146407,389.04695704352815,393.1576509857533
0.11020942952903388,390.7322273277995,389.1750344550132,392.2894202005857
0.11053452979386631,390.9895995012004,389.3031128656521,392.6760861367488
0.11085952440286456,391.54749532012283,389.43119227544497,393.66379836480064
0.11118441342468126,391.27856502861965,389.5136845451868,393.04344551205253
0.11150919692790216,391.09395862010797,389.5406801681034,392.6472370721126
0.11183387498104683,391.49323805196616,389.63225049889587,393.3542256050364
0.11215844765256748,391.92500431202205,389.7237981542747,394.12621046976943
0.1124829150108497,391.90519917072135,389.8153231342394,393.99507520720323
0.11280727712421315,391.88529865626384,389.9068254387906,393.86377187373705
0.11313153406091021,391.86530276864937,389.9983050679278,393.73230046937095
0.11345568588912772,392.0424048215236,390.0897620216513,393.9950476213959
0.1136177224088467,392.28761489309295,390.13548199523285,394.43974779095305