File: RHTT_S_DRY_Ex_true_stress_strain.csv
True Strain,True Stress (MPa),Lower Bound (MPa),Upper Bound (MPa)
-0.0006306738329400226,-0.3551788440127812,-0.3551788440127812,-0.3551788440127812
-0.0004739254731262845,7.228774358212007,7.228774358212007,7.228774358212007
-0.0003172016795101898,3.881764007881741,-0.2713686335211575,8.034896649284638
-0.0001605024443928407,6.417614436755374,-2.0584077422061755,14.89363661571692
-3.827760078625078e-06,0.48827197730032973,-0.29688392504449024,1.2734278796451497
0.00015282238112411962,10.558264994197186,-7.6722789459224074,28.788808934316776
0.0003094479869035528,45.524295233222546,18.73603862605433,72.31255184039077
0.0004660490649442221,60.75991761292798,31.76507377354448,89.75476145231147
0.0006226256229268433,79.3756505536059,64.05017758158841,94.70112352562337
0.0007791776685291908,88.97415773337417,71.03015373451855,106.91816173222978
0.000935705209424768,97.15867043265276,80.10798516549903,114.2093556998065
0.0010922082532836973,107.61435507833949,91.93908317877249,123.28962697790648
0.0012486868077725003,121.24329991093207,111.76706868554382,130.7195311363203
0.0014051408805541008,129.8250587307117,119.40164040502296,140.24847705640042
0.0015615704792878258,140.83695141067724,127.80337420673844,153.870528614616
0.0017179756116294089,153.72362460563667,138.93395231079694,168.51329690047643
0.0018743562852307702,165.57743143960212,155.77803686330222,175.37682601590203
0.0020307125077409054,183.60492787058556,172.02630440736272,195.18355133380842
0.002187044286804558,185.88850816983728,172.79203249145928,198.98498384821528
0.0023433516300631085,200.54621063494383,187.03805732003894,214.05436394984872
0.002499634545154355,211.6870465352731,200.55379567901443,222.8202973915318
0.002655893039712514,229.95385308637694,214.1247276024308,245.78297857032305
0.0028121271213682256,235.11499075231978,225.81658647050276,244.4133950341368
0.0029683367977483307,251.56808145416585,231.44225609028288,271.69390681804884
0.0031245220764767627,263.5467932412637,247.3319595178685,279.76162696465883
0.003280682965173217,269.18407984352314,257.0311171778344,281.3370425092119
0.003436819471454043,279.0105044955131,263.63289016395976,294.3881188270665
0.003592931602932023,286.566657037553,272.14846724079916,300.9848468343068
0.003749019367216373,296.1544498834103,284.1868748955384,308.12202487128224
0.003905082771912748,300.41728599207084,290.81920688173614,310.0153651024055
0.004061121824623021,308.6958340986462,299.7032311509856,317.6884370463068
0.00421713653294617,313.3753210730569,301.3432914487826,325.4073506973312
0.004373126904476954,319.50872556480857,310.17585629516736,328.8415948344497
0.0045290929468068,323.4239620445302,315.1749104520916,331.6730136369688
0.004685034667523581,326.5246120734558,319.13563625819296,333.9135878887186
0.0048409520742116255,330.9706328740883,322.88675841021444,339.0545073379622
0.00499684517445171,332.7334487278118,326.35570352828506,339.1111939273385
0.005152713975820848,335.84470489115546,328.57698541526446,343.1124243670465
0.0053085584858931735,337.217731354792,330.8030381397224,343.63242456986166
0.005464378712238616,338.9536944575738,332.0444022843076,345.86298663084006
0.005620174662423787,340.2762165685306,333.88610691654293,346.66632622051816
0.005775946344011764,341.1959935788201,335.51265382375993,346.87933333388025
0.005931693764562091,342.84106537031494,335.91305583322406,349.7690749074058
0.006087416931630777,343.2909505787941,337.7058081458469,348.87609301174126
0.006243115852770305,344.9468641659371,338.05307775533834,351.84065057653584
0.00639879053552941,345.5232255047115,339.2812383027663,351.76521270665665
0.0065544409874539605,346.53223525939586,339.8958009769402,353.16866954185144
0.006710067216085645,347.2527363711162,339.964279579707,354.54119316252536
0.006865669228962849,347.63722169959226,340.8448584087669,354.4295849904176
0.007021247033620441,347.96573169841065,341.88385869993806,354.04760469688324
0.0071768006375897715,348.74965530931286,342.4246917404695,355.0746188781562
0.007332330048398679,349.44824724010516,342.6080551821757,356.2884392980347
0.007487835273571268,349.9104041850249,343.1361544538007,356.6846539162491
0.007643316320628797,350.6700742403483,343.4002371248119,357.9399113558847
0.007798773197088352,351.4091502158853,343.88215362255147,358.9361468092191
0.007954205910463738,351.65740880562015,344.38904284111095,358.9257747701293
0.008109614468265254,351.90785399478403,344.90944390602215,358.90626408354586
0.0082649988779997,352.21321792015743,345.5506921240674,358.87574371624754
0.008420359147170375,352.33332631800045,346.0602605021709,358.60639213383
0.008575695283276867,353.83524638117217,346.35062901424385,361.3198637481005
0.00873100729381592,354.0967675673825,346.9335401135283,361.2599950212367
0.008886295186280134,353.8569381949001,347.51649811705795,360.1973782727423
0.009041558968158836,354.13790162085206,347.7854945144404,360.4903087272637
0.009196798646937863,354.9065507615463,347.8966158270455,361.9164856960471
0.009352014230099572,355.4939480851375,348.2130093227894,362.77488684748556
0.009507205725122831,355.4098231408837,348.684016576357,362.1356297054104
0.009662373139483028,356.76073059803366,348.2228678148136,365.29859338125374
0.009817516480651852,357.0395997129596,349.07224727563994,365.0069521502793
0.009972635756098174,357.47508894157045,350.1393090925865,364.81086879055437
0.010127730973286734,357.32921500580863,350.7950431889919,363.86338682262544
0.010282802139679014,357.58670471812644,350.7767461357729,364.39666330047993
0.010437849262733029,358.3326192920308,350.9904679012005,365.6747706828612
0.010592872349903321,359.1832279684274,351.17603628384217,367.1904196530126
0.010747871408640973,359.3967794166651,351.71924504550765,367.0743137878225
0.010902846446393376,359.65032998137144,352.32130425034455,366.97935571239833
0.011057797470605125,360.52913793424096,352.1576904299682,368.90058543851376
0.01121272448871669,360.64118923203944,352.4336949894655,368.8486834746134
0.01136762750816531,360.6873944096608,352.7124938158042,368.6622950035174
0.01152250653638476,360.72913932061334,353.48473904297384,367.9735395982529
0.011677361580805366,361.4773403981396,353.9167307465582,369.03795004972096
0.011832192648854005,361.976205566712,354.0074246360454,369.94498649737864
0.011986999747953883,362.44840712473456,354.044330520455,370.8524837290141
0.012141782885525414,362.77819817959426,354.70136245807186,370.85503390111666
0.012296542068984912,362.93718250067406,355.36902826486124,370.5053367364869
0.01245127730574547,363.06053472894297,355.93914744998375,370.1819220079022
0.012605988603216737,363.6752770127062,356.04511142287384,371.3054426025385
0.012760675968804924,364.4669451483601,355.75966929999385,373.1742209967263
0.012915339409912805,364.30805607813136,356.180956640639,372.43515551562376
0.013069978933939502,364.5673856578187,356.2851072316681,372.8496640839693
0.01322459454828136,365.23150859380155,356.49057670998354,373.9724404776195
0.013379186260330642,365.2367171754363,357.38763692574344,373.0857974251291
0.013533754077476395,366.0651623188547,357.49608449094745,374.6342401467619
0.013688298007104246,366.62479184212634,357.4327703892513,375.8168132950014
0.013842818056596392,367.4041700399584,357.6955804864726,377.1127595934442
0.013997314233331618,367.52489511556894,358.27778549429235,376.7720047368456
0.014151786544685279,367.55867210968785,358.764325887095,376.3530183322806
0.014306234998029101,367.3228625498353,359.2751378365881,375.3705872630825
0.01446065960073205,367.708983094793,359.57912779748864,375.83883839209733
0.014615060360159018,368.49543308030087,359.40334403154634,377.58752212905534
0.014769437283671711,368.73696072497756,359.61243255835996,377.86148889159523
0.014923790378628423,368.94997030177694,359.8634819478467,378.0364586557072
0.015078119652384042,369.1221510286501,360.41319225933023,377.83110979796993
0.01523242511229005,369.37100859579255,360.94787161625555,377.79414557532954
0.015386706765694307,370.56718006898797,360.4022932890662,380.73206684890977
0.015540964619941932,370.5678236180829,360.9305465035167,380.2051007326491
0.015695198682373988,370.47238586982263,361.81202666426805,379.1327450753772
0.015849408960328357,370.66291893142517,362.3050605528973,379.020777309953
0.016003595461139532,371.279481448604,362.2996712439019,380.2592916533061
0.016157758192138615,371.53613848185273,362.1943574552974,380.8779195084081
0.01631189716065331,371.83018515008365,362.15446227166814,381.50590802849916
0.01646601237400772,372.40197080695174,362.53716823438833,382.2667733795152
0.016620103839523215,371.8842628095471,363.5403221577064,380.2282034613879
0.016774171564517135,373.32621022995977,363.13334497112874,383.51907548879086
0.016928215556303642,373.6077998239861,363.6007432559395,383.6148563920328
0.017082235822193526,373.34286000196715,363.9979558862255,382.68776411770887
0.017236232369494207,373.6831301395496,363.8809952994609,383.4852649796382
0.017390205205509712,374.31894067800397,363.8577264280678,384.78015492794015
0.017544154337540495,374.74344311664527,364.40413255506616,385.0827536782244
0.017698079772884276,374.8680865288176,364.75689492465625,384.97927813297895
0.01785198151883477,374.49260280830265,365.52090603263923,383.4642995839661
0.018005859582682523,375.11105536901596,365.27432188437524,384.9477888536567
0.018159713971714734,375.72525277544787,365.0206242941839,386.4298812567118
0.018313544693215226,376.29543317732845,365.39727816289246,387.19358819176443
0.018467351754464467,376.05543765421356,366.36770276916235,385.7431725392648
0.018621135162739565,376.19156214841394,366.7138036123902,385.6693206844377
0.018774894925314055,376.9210624718957,366.5823289027043,387.25979604108704
0.018928631049458768,377.41584256824433,366.4974863492653,388.3341987872234
0.01908234354244053,376.8347813326091,366.9895639352581,386.6799987299601
0.01923603241152304,377.26019354839127,367.0129510199964,387.5074360767861
0.019389697663966636,377.77056606118026,367.2560512651673,388.2850808571932
0.01954333930702832,378.1986310866283,367.36974196401445,389.02752020924214
0.01969695734796174,378.51255530220135,367.30438648033504,389.7207241240676
0.019850551794017,378.66075508962825,367.3908266610885,389.93068351816794
0.020004122652441496,378.5315806083622,367.77697916238685,389.28618205433753
0.020157669930478652,378.4474744150044,368.31239606223494,388.5825527677739
0.02031119363536876,379.45828273506646,368.6955894487827,390.2209760213503
0.020464693774348786,379.81404907499126,368.6614136185205,390.966684531462
0.020618170354652358,380.1247648156868,368.99126759080133,391.2582620405722
0.02077162338350978,380.0111347571341,369.2644939455656,390.7577755687026
0.0209250528681478,380.56014248726814,369.12299960255945,391.99728537197683
0.021078458815790506,381.17271580616364,369.1171935915704,393.22823802075686
0.021231841233658004,381.24696611472814,369.5542731522153,392.93965907724106
0.02138520012896729,381.27041068506884,369.9103974747536,392.630423895384
0.021538535508932043,381.2218374519003,370.15493741142825,392.2887374923724
0.021691847380762633,381.15919114738915,370.3731188375936,391.9452634571847
0.021845135751666106,381.88455889169967,369.96656358255615,393.8025542008432
0.02199840062884619,381.0413016750101,371.29141277199454,390.79119057802563
0.022151642019503093,381.96359128223753,371.36412588639837,392.5630566780767
0.022304859930834364,382.6819051520494,371.1469764954033,394.21683380869547
0.022458054370033585,382.6758029080826,371.5195140022208,393.83209181394443
0.022611225344291257,382.7161452473016,371.7590556767455,393.67323481785775
0.022764372860794576,383.0502017179426,371.56345614564697,394.53694729023823
0.022917496926727437,383.38982149651326,371.37615281387446,395.4034901791521
0.02307059754927043,383.3899901730726,371.9092223192436,394.8707580269016
0.023223674735600632,383.8219916670295,372.4692309456469,395.17475238841206
0.023376728492892487,384.61262748533113,372.69755024119615,396.52770472946617
0.02352975882831648,385.00628473279784,372.2960665345544,397.71650293104125
0.023682765749040022,385.01487398093155,372.28321118358656,397.74653677827655
0.023835749262227247,384.85731578627815,372.63634515570055,397.07828641685575
0.02398870937503899,384.8567223591064,373.2434149893668,396.4700297288461
0.024141646094632808,384.49194086898177,374.14325374629016,394.84062799167333
0.02429455942816275,385.044847638681,374.0327860458609,396.0569092315011
0.024447449382780238,385.60413952709206,373.7164327786921,397.4918462754921
0.024600315965632766,386.0461271184603,373.5651072549443,398.5271469819763
0.024753159183864764,385.6929147081508,374.0636847307662,397.3221446855353
0.02490597904461739,385.3256914568894,374.53676784104,396.11461507273873
0.02505877555502853,385.94864556616795,374.3413677309851,397.5559234013508
0.025211548722232788,386.3837803165432,374.60308225147037,398.164478381616
0.025364298553361295,386.74756972965014,374.74802662716445,398.7471128321359
0.025517025055542552,386.99649505784646,374.7080841909167,399.28490592477624
0.02566972823590116,386.69093440654785,375.32502171845596,398.0568470946398
0.025822408101558655,387.05566802185825,375.4907471662621,398.6205888774544
0.02597506465963333,387.40206304403483,375.62999734663475,399.1741287414349
0.026127697917240206,387.7225214487347,375.7647974403488,399.68024545712063
0.026280307881491046,388.03093290978836,375.8791160766401,400.1827497429366
0.02643289455949437,388.2580424965403,375.863554926953,400.65253006612767
0.026585457958355214,388.087951987481,376.2319806301831,399.9439233447789
0.026737998085176018,388.4516965429612,376.23593903021094,400.66745405571146
0.026890514947055324,388.7280482455202,376.0969722545687,401.3591242364717
0.02704300855108864,389.1002381938439,376.12117279858006,402.0793035891077
0.02719547890436823,389.2184467678331,376.5262761005293,401.9106174351369
0.02734792601398312,389.14157636320795,376.8998128712882,401.3833398551277
0.027500349887019084,388.8136317654316,377.5045528392417,400.1227106916214
0.02765275053055844,389.09051178690544,377.48957381462697,400.6914497591839
0.02780512795168093,389.40175920301283,377.5340067923725,401.26951161365315
0.027957482157462403,389.8285767885996,377.6252699716975,402.0318836055018
0.02810981315497569,390.1645330639428,377.63803141808876,402.69103470979695
0.028262120951290385,390.22492862733463,377.8517878007654,402.59806945390386
0.02841440555347287,390.4108233754963,377.98961674346987,402.83203000752275
0.028566666968586278,390.7142527805763,378.0445242304359,403.3839813307167
0.028718905203690314,390.9103438540452,377.92942480949546,403.89126289859496
0.028871120265842105,391.0918736748502,377.7904187314939,404.39332861820645
0.029023312162094902,390.96710292358483,377.92775830571514,404.00644754145446
0.02917548089949896,390.9344520665641,378.4999774942772,403.36892663885106
0.029327626485101312,390.94023464759755,379.1725616283373,402.70790766685786
0.02947974892594577,391.40580284334885,379.3426156190523,403.46899006764545
0.029631848229072943,391.68447801651195,379.208141309777,404.1608147232469
0.029783924401520005,391.8525587666744,379.10201930994134,404.60309822340747
0.029935977450321567,392.17767604954287,379.59803831197956,404.75731378710617
0.030088007382508386,391.9233234244992,380.1043387916921,403.7423080573063
0.030240014205108228,392.1064213485177,380.15931200669087,404.05353069034453
0.03039199792514566,392.32638511339724,380.1886096811617,404.46416054563275
0.030543958549642033,392.95297633911986,380.09731236837797,405.80864030986174
0.03069589608561551,393.4964633940608,379.90617101924346,407.0867557688782
0.030847810540081053,393.22895307188566,380.1533337143897,406.3045724293816
0.030999701920050214,392.87194261901897,380.26043392167315,405.4834513163647
0.031151570232531987,392.6167632628584,380.53640648208483,404.697120043632
0.031303415484531534,392.336091831231,381.0319046637633,403.64027899869865
0.03145523768305104,393.0543209286219,380.7226661693538,405.38597568789004
0.031607036835089516,393.53151049362674,380.72908991982194,406.33393106743154
0.03175881294764276,393.8956262435982,380.8310360229471,406.9602164642493
0.031910566027703396,393.729809116589,380.9846704725435,406.4749477606345
0.032062296082260654,393.49501013715354,381.5574262969729,405.4325939773342
0.032214003118301235,393.9255316142692,381.6382477885563,406.21281543998197
0.03236568714280799,394.3578818094644,381.3799543334901,407.3358092854387
0.03251734816276084,394.73245196356095,381.6697813430501,407.7951225840718
0.032668986185136514,394.8470906215876,382.2019321464647,407.4922490967105
0.03282060121690856,394.7579658471679,382.4036006316726,407.1123310626632
0.03297219326504736,394.76070011365283,382.48881002971973,407.032590197586
0.03312376233651993,395.13132215894115,382.3415636818679,407.9210806360144
0.033275308438290734,395.50718810995204,382.2026729711346,408.8117032487695
0.03342683157732045,395.48970718814496,382.3504464517677,408.62896792452227
0.03357833176056679,395.4445918822586,382.5272339032466,408.36194986127055
0.03372980899498432,395.36267540515087,382.725385414594,407.9999653957078
0.03388126328752442,395.26218933794377,382.90252977164624,407.6218489042413
0.03403269464513536,395.44608696999774,382.96628665941427,407.92588728058126
0.034184103074761975,395.6883014955069,383.1263717324343,408.25023125857945
0.03433548858334664,396.08483377728635,383.173045099615,408.9966224549577
0.03448685117782791,396.202219865406,382.8578248474827,409.5466148833293
0.03463819086514143,396.1721642504926,383.34727595832476,408.99705254266036
0.03478950765221965,396.2108892050361,383.79328082702625,408.628497583046
0.034940801545991926,396.4954603347516,383.7262780550295,409.26464261447364
0.03509207255338443,396.79777554667555,383.6661944260429,409.9293566673082
0.03524332068132022,397.0993929296651,383.6048568136573,410.59392904567295
0.035394545936718966,397.04696377777674,383.7667794999788,410.32714805557475
0.03554574832649787,396.95306164596013,383.95537090483873,409.95075238708154
0.03569692785757036,396.91445061529475,384.189811709699,409.63908952089054
0.0358480845368469,397.07032325417197,384.5913996673817,409.54924684096216
0.035999218371234876,397.4698231913611,384.6463351935699,410.2933111891524
0.0361503293676385,397.7033940320606,384.5564871765138,410.85030088760743
0.036301417532958874,397.9337352403595,384.7062772829521,411.161193197767
0.03645248287409375,397.59003485217215,385.1055664974285,410.07450320691584
0.03660352539793841,397.7736090482832,385.27035060914375,410.27686748742263
0.03675454511138436,397.94390252471277,385.4129390160599,410.4748660333657
0.036905542021320195,398.36071273500113,385.33175055022485,411.3896749197774
0.037056516134631394,398.5541726901743,385.2586390313245,411.8497063490241
0.037207467458200326,398.4389639551071,385.3579906554276,411.5199372547866
0.037358395998906224,398.3505626594272,385.4412782738802,411.25984704497426
0.03750930176362502,398.3126259766472,385.5064082100521,411.11884374324234
0.03766018475923014,398.2824538423572,385.5821545152144,410.98275316950003
0.0378110449925913,398.5840837117872,385.43663203907244,411.7315353845019
0.03796188247057529,398.7267651495841,385.5258363532346,411.9276939459336
0.03811269720004579,398.8929384154059,385.7294637779361,412.05641305287577
0.03826348918786341,398.9128653758972,386.0716687100473,411.7540620417471
0.03841425844088561,398.9760298780101,386.14175842689104,411.8103013291291
0.03856500496596679,399.50070070371197,386.1083911517422,412.89301025568176
0.03871572876995802,399.9173752300647,386.2291158106213,413.6056346495081
0.0388664298597079,399.80665687546883,386.6468400177926,412.9664737331451
0.039017108242061324,399.63251441123623,386.9639691963265,412.301059626146
0.03916776392386027,399.5522352407276,387.2329905236011,411.87147995785415
0.03931839691194366,399.58602678363076,387.4208210118318,411.7512325554297
0.03946900721314729,399.80619527950205,387.48114278978375,412.1312477692204
0.039619594834303905,400.02941477853204,387.36119385626137,412.69763570080266
0.03977015978224292,400.1120934047736,387.27375595801055,412.95043085153657
0.03992070206379132,400.0920407639468,387.29044640721725,412.8936351206763
0.040071221685772374,400.14265621504677,387.4258072177526,412.8595052123409
0.04022171865500646,400.08005786907603,387.71685600224765,412.44325973590435
0.040372192978310906,400.60302575327194,387.86440802765486,413.341643478889
0.04052264466249993,400.94199363525536,387.822254290638,414.0617329798727
0.040673073714384715,400.8730514907206,388.0640948445555,413.6820081368857
0.040823480140773125,400.6803356609475,388.0860496522446,413.27462166965034
0.04097386394847059,400.6426085014874,387.9772433325872,413.3079736703876
0.04112422514427887,400.659148900905,387.95841794921546,413.35987985259453
0.04127456373499683,400.8955993556395,388.2078140491289,413.58338466215014
0.041424879727420275,401.0286855969875,388.15971137264137,413.8976598213336
0.04157517312834197,401.1878845527333,388.15502921820126,414.2207398872653
0.0417254439445516,401.39405425014223,388.23537086490956,414.55273763537485
0.041875692182835565,401.4544049663125,388.5902506879535,414.31855924467146
0.04202591784997787,401.3256280401096,388.73883641911567,413.91241966110357
0.04217612095275881,401.2650635318344,388.92576708328886,413.60435998037997
0.04232630149795584,401.4336212684059,388.91187407014456,413.95536846666715
0.04247645949234337,401.72667344659124,388.7958114717888,414.6575354213936
0.04262659494269274,401.8788298946728,389.2838029914004,414.47385679794513
0.04277670785577226,401.8468397084809,389.4917732116731,414.20190620528865
0.04292679823834719,401.8007739145756,389.58029269869553,414.0212551304557
0.04307686609717951,401.8382568884374,389.60527909401446,414.0712346828604
0.043226911439028834,401.9870348493243,389.5796717536894,414.39439794495917
0.043376934270651056,402.1926602591958,389.5158516878886,414.8694688305031
0.04352693459879926,402.39230997236854,389.4473070918472,415.3373128528899
0.043676912430223494,402.3537820982948,389.59755955897276,415.11000463761684
0.04382686777167077,402.31829019158823,389.75282420659715,414.8837561765793
0.04397680062988505,402.22632730465403,389.9559922462649,414.4966623630432
0.04412671101160707,402.4333436958616,389.89137047426215,414.9753169174611
0.04427659892357516,402.4752152274064,389.8258186431229,415.12461181168993
0.04442646437252399,402.5161684313917,389.7579669934215,415.2743698693618
0.04457630736518541,402.5931923799882,389.7473685288287,415.43901623114766
0.04472612790828825,402.6452356887323,389.94432800277053,415.3461433746942
0.04487592600855831,402.5913230104187,390.17092999250343,415.011716028334
0.04502570167271837,402.6337426663388,390.5588735809397,414.7086117517379
0.04517545490748797,402.82830130816944,390.8593953263531,414.79720728998575
0.04532518571958429,402.8416806251075,390.73105779469927,414.9523034555157
0.045474894115720844,402.97459306763307,390.6240495582301,415.325136577036
0.04562458010260833,403.33665262208007,390.86924133279484,415.80406391136535
0.045774243686954444,403.73385524418484,391.1899606342167,416.27774985415294
0.04592388487546389,403.424095190635,391.43998204621056,415.40820833505944
0.04607350367483832,403.3320246182417,391.50973484172397,415.1543143947594
0.04622310009177642,403.5308892242225,391.37011164430174,415.69166680414327
0.04637267413297364,403.512795699229,391.33258192844005,415.69300947001796
0.04652222580512305,403.4692388071069,391.2590921924714,415.6793854217424
0.046671755114914115,403.4417236892181,391.2072542845169,415.67619309391927
0.046821262069033476,403.4893254881037,391.2702316058158,415.7084193703916
0.046970746674164794,403.4639938759608,391.46056655551683,415.4674211964047
0.047120208936988726,403.324748531855,391.56376433605317,415.0857327276569
0.047269648864182945,403.37318133832827,391.7737561797898,414.9726064968667
0.04741906646242191,403.63955843124,391.9837131807863,415.29540368169376
0.04756846173837772,403.5704185632306,391.9039267511089,415.2369103753523
0.04771783469871886,403.9466450576789,391.7913962307398,416.101893884618
0.04786718535011104,403.54430623758464,392.1585709699547,414.9300415052145
0.04801651369921695,403.7744239874089,392.1073758784145,415.4414720964033
0.048165819752696355,403.8777988592502,392.1872374108854,415.5683603076151
0.048315103517205985,403.9551405078631,392.2990124258953,415.611268589831
0.048464364999399406,404.02743418898854,392.40353540836765,415.6513329696095
0.04861360420592783,404.09887876632195,392.5067153462595,415.6910421863844
0.048762821143438856,404.1693430550195,392.6083864148485,415.7302996951905
0.04891201581857733,404.09976627205276,392.581961045028,415.61757149907754
0.049061188237985096,404.0716934360534,392.7484846807068,415.39490219140004
0.04921033840830107,404.0433087428108,392.9144987374547,415.1721187481668
0.04935946633616116,404.21773728120957,393.00572903418754,415.4297455282316
0.04950857202819812,404.4986157911285,393.0889680254672,415.90826355678985
0.04965765549104234,404.1419257369131,393.36222065934254,414.9216308144836
0.049806716731320644,404.10573727350203,393.33496407915965,414.87651046784447
0.0499557557556571,404.0684707289805,393.3055857297258,414.83135572823517
0.050104772570672786,404.1461485114685,393.16159539526114,415.13070162767576
0.050253767182985846,404.2278915788612,392.9382609648984,415.517522192824
0.050402739599211474,404.14997351797143,392.96454468155366,415.3354023543892
0.050551689825961664,404.044313686248,393.0822625531458,415.0063648193502
0.05070061786984612,404.0158970009979,393.15655472074195,414.8752392812538
0.05084952373747095,403.9747722093782,393.17913759917525,414.7704068195811
0.05099840743543952,403.87170478086256,393.0998321904151,414.6435773713101
0.051147268970352246,403.8163826221604,392.984453790581,414.64831145373984
0.051296108348806595,403.9650957695898,392.7988591201399,415.1313324190398
0.0514449255773971,404.0588399878177,392.7599036376963,415.3577763379391
0.05159372066271534,403.91831664455157,392.813406220989,415.0232270681142
0.051742493611349735,403.7177316302246,392.9038599293732,414.531603331076
0.05189124442988642,406.60856469053493,395.6816288196167,417.53550056145315
0.052039973124907934,406.66239458266904,395.76586288786496,417.5589262774731
0.052188679702994116,406.7293336547292,395.8363341914385,417.6223331180199
0.052337364170721844,406.8895148198042,395.86927197491354,417.9097576646949
0.052486026534665074,407.013324580549,395.8332290555798,418.19342010551827
0.05263466680139484,407.16471215239125,395.84838339956855,418.48104090521394
0.05278328497747902,399.4206354062519,397.69237346119644,401.1488973513074
0.0529318810694832,399.49742329772704,397.7865319296781,401.20831466577596
0.05308045508396941,399.5241911965618,397.78279312939685,401.26558926372667
0.05322900702749698,399.5509494116318,397.779035656552,401.32286316671156
0.05337753690662228,399.50723125620965,397.66329892075464,401.3511635916647
0.053526044727898806,399.4461583171701,397.5256835073183,401.3666331270219
0.0536745304978771,399.4586089032612,397.5351282530477,401.38208955347477
0.05382299422310459,399.5114586491321,397.6858112343779,401.3371060638863
0.05397143591012641,399.57332985811513,397.83652142977735,401.31013828645297
0.05411985556548417,399.6767984253741,397.9872588392458,401.36633801150236
0.054268253195716744,399.78028009997433,398.13802346278305,401.4225367371656
0.05441662880736013,399.85586838840004,398.28881530038944,401.42292147641064
0.0545649824069474,399.85050781407693,398.2926935247645,401.40832210338937
0.05471331400100871,399.71379913091715,398.1034421699008,401.3241560919335
0.054861623596071336,399.63055981219037,397.9528955139196,401.3082241104612
0.055009911198659424,399.57605785502443,397.8139992748331,401.33811643521574
0.055158176815294835,399.66785066525387,397.9677013547764,401.36799997573127
0.05530642045249593,399.748621053324,398.1204739465864,401.3767681600616
0.055454642116778356,399.7690786803613,398.1742480564033,401.3639093043193
0.05560284181465488,399.7752715040548,398.1995140073959,401.3510290007137
0.05575101955263536,399.75873911842353,398.2085855073913,401.30889272945575
0.05589917533722677,399.7414113855437,398.21764220932806,401.2651805617594
0.05604730917493298,399.71351923936595,398.22668411320564,401.20035436552627
0.0561954210722556,399.683965376052,398.23571121902444,401.13221953307954
0.056343511035692725,399.6647986165565,398.2447235267845,401.0848737063285
0.05649157907173976,399.66379728971077,398.2537210364856,401.0738735429359
0.05663962518688924,399.70816603660626,398.3023931797538,401.1139388934587
0.05678764938763081,399.7709835936898,398.3787669044364,401.1632002829431
0.05693565168045125,399.75532798918755,398.332202987455,401.17845299092016
0.057083632071834214,399.734099938134,398.2745072375354,401.1936926387326
0.05723159056826114,399.7128480970335,398.2167769676863,401.20891922638066
0.05737952717620994,399.78653749244995,398.3284018114875,401.2446731734125
0.05752744190215589,399.8002034893013,398.3159766623511,401.2844303162515
0.057675334752571354,399.80822053007535,398.3035304078936,401.312910652257
0.05782320573392585,399.7713986044041,398.2910630481151,401.2517341606931
0.05797105485268603,399.7466246617039,398.2785745830152,401.2146747403926
0.05811888211531545,399.7325664604745,398.2660650125942,401.19906790835483
0.058266687528275435,399.7252408355155,398.25353433685206,401.1969473341789
0.05841447109802383,399.71968551212166,398.2409825557888,401.19838846845454
0.05856223283101581,399.71389183164763,398.22840966940436,401.19937399389084
0.058709972733703694,399.6480063928295,398.21581567769874,401.08019710796026
0.05885769081253695,399.58445945723406,398.2032005806718,400.96571833379625
0.05900538707396218,399.5246429936815,398.19056437832387,400.8587216090391
0.05915306152442312,399.4647914288784,398.1779070706548,400.751675787102
0.05930071417036047,399.41280918535335,398.1652286576644,400.6603897130423
0.05944834501821269,399.4018822613562,398.15252913935296,400.6512353833594
0.059595954074414745,399.31465812031195,397.9872553543508,400.6420608862731
0.05974354134539898,399.2145071420812,397.82018252362866,400.60883176053375
0.059891106837594896,399.17094995682544,397.7750431203904,400.56685679326046
0.06003865055742913,399.1677799805314,397.77403965010143,400.56152031096144
0.06018617251132549,399.17602732543384,397.7730185652741,400.5790360855935