File: RHTT AVG/Average_UTT_Engineering.csv
strain,stress (MPa)
4.3261203003002996e-05,3.1196403938920922
0.000145564606006006,12.039209538990692
0.00024786800900900897,18.43766517344344
0.000350171412012012,26.090707422491146
0.000452474815015015,33.17291177058069
0.0005547782180180179,38.80234608100727
0.000657081621021021,47.95575167974217
0.000759385024024024,54.76638856703456
0.000861688427027027,61.72634042220644
0.00096399183003003,68.95262048684779
0.0010662952330330328,76.7656732697739
0.0011685986360360358,83.81048860288814
0.001270902039039039,91.17162964002986
0.0013732054420420418,100.97086864176998
0.001475508845045045,108.19144817402301
0.0015778122480480479,115.41425140205905
0.0016801156510510508,122.36021730158718
0.001782419054054054,128.3626426911883
0.0018847224570570568,135.37090689415973
0.00198702586006006,142.71134978689463
0.0020893292630630627,150.4643406555122
0.002191632666066066,155.8503510915516
0.002293936069069069,162.5005685067567
0.0023962394720720716,170.685030470012
0.0024985428750750748,180.01841772959554
0.002600846278078078,187.67612167100515
0.002703149681081081,195.86142110422443
0.0028054530840840837,201.58833616709796
0.002907756487087087,208.3372330899837
0.00301005989009009,214.33709460051134
0.0031123632930930927,221.14412502693742
0.003214666696096096,227.77119219280576
0.003316970099099099,232.99088055557633
0.0034192735021021017,238.4654605907156
0.003521576905105105,243.46673571558438
0.003623880308108108,248.77581639145905
0.0037261837111111106,254.35260345903802
0.0038284871141141138,258.8093130055954
0.003930790517117117,261.8791401277634
0.0040330939201201205,264.43177632732574
0.004135397323123124,266.6834740399531
0.004237700726126126,268.070007937709
0.004340004129129129,269.7194208783814
0.004442307532132132,271.3050804228566
0.004544610935135135,272.86619808051665
0.004646914338138138,274.1114776486124
0.0047492177411411415,275.1272980198447
0.004851521144144144,276.4239010400232
0.004953824547147147,277.3394788633496
0.00505612795015015,278.4648262567854
0.005158431353153153,279.35099491539495
0.005260734756156156,280.39748763859905
0.0053630381591591595,281.1880961929055
0.005465341562162163,282.33713765053415
0.005567644965165165,283.1973592358999
0.005669948368168168,283.81977520713576
0.005772251771171171,284.6114107394313
0.005874555174174174,285.5826899770694
0.005976858577177177,286.03659165386426
0.0060791619801801805,286.6638635764847
0.006181465383183183,287.3113311961923
0.006283768786186186,288.14635857706963
0.006386072189189189,288.6230479606399
0.006488375592192192,289.26786999171225
0.006590678995195195,289.6311525744989
0.0066929823981981985,290.37166285783655
0.006795285801201202,290.8084359646301
0.006897589204204204,291.34077091712413
0.006999892607207207,291.78754097313293
0.00710219601021021,292.29722410752134
0.007204499413213213,292.6816415736488
0.007306802816216216,293.28536397677647
0.0074091062192192195,294.0524691049283
0.007511409622222222,294.28706524348723
0.007613713025225225,294.4542410474826
0.007716016428228228,294.7269310387308
0.00781831983123123,295.2170589524084
0.007920623234234234,295.85925812377724
0.008022926637237237,296.13294892555666
0.00812523004024024,296.2665578534608
0.008227533443243243,296.5725454135713
0.008329836846246247,296.93184526134166
0.00843214024924925,297.1121485330633
0.008534443652252251,297.3981205510518
0.008636747055255255,297.66752017640334
0.008739050458258258,297.96627230923593
0.008841353861261262,298.36473824076916
0.008943657264264264,298.6093853093892
0.009045960667267268,298.9048677515999
0.00914826407027027,299.15234072948266
0.009250567473273272,299.2659002552281
0.009352870876276276,299.3932470639978
0.009455174279279279,299.80798535481085
0.009557477682282283,299.88788259028416
0.009659781085285285,300.01998117106746
0.009762084488288287,300.30076320514405
0.009864387891291291,300.5384544593163
0.009966691294294294,300.9130152902702
0.010068994697297298,301.05530011507926
0.0101712981003003,301.2060083288908
0.010273601503303304,301.2118239865149
0.010375904906306306,301.23221597482905
0.010478208309309308,301.3794148633058
0.010580511712312312,301.82872341532885
0.010682815115315315,302.0868053206639
0.010785118518318319,302.2932914490079
0.010887421921321321,302.2598132200577
0.010989725324324325,302.1826204768872
0.011092028727327327,302.2885246212263
0.01119433213033033,302.5041803081831
0.011296635533333333,302.77296001010416
0.011398938936336336,303.1945912440842
0.01150124233933934,303.0893299318441
0.011603545742342342,303.08680294878656
0.011705849145345346,303.19398267998764
0.011808152548348348,303.2462208147134
0.01191045595135135,303.58220117420245
0.012012759354354354,303.8355220538171
0.012115062757357357,303.98090073472537
0.01221736616036036,304.05320803567884
0.012319669563363363,304.0020374126452
0.012421972966366365,304.1017910149199
0.01252427636936937,304.1752396047076
0.012626579772372372,304.3591239306483
0.012728883175375376,304.51877272169133
0.012831186578378378,304.63710454749645
0.012933489981381382,304.52760563788
0.013035793384384384,304.68542475226934
0.013138096787387386,304.8548723693906
0.01324040019039039,305.1846891574621
0.013342703593393393,305.20318134556106
0.013445006996396397,305.24156158242033
0.013547310399399399,305.2519422070882
0.013649613802402403,305.45633828884297
0.013751917205405405,305.5222918059191
0.013854220608408407,305.4505501641756
0.013956524011411411,305.6194393412515
0.014058827414414414,305.81501137735034
0.014161130817417418,305.9648358143438
0.01426343422042042,305.92380610844185
0.014365737623423422,306.0070726548657
0.014468041026426426,306.22959389736707
0.014570344429429428,306.2970660390542
0.014672647832432432,306.3528767307786
0.014774951235435435,306.4156501328875
0.014877254638438439,306.54076409040727
0.014979558041441441,306.52716222752684
0.015081861444444443,306.64166714306106
0.015184164847447447,306.8098556728991
0.01528646825045045,306.85516392990417
0.015388771653453454,306.792374583465
0.015491075056456456,306.8442145797862
0.01559337845945946,307.03947904215846
0.01569568186246246,307.19764609553073
0.015797985265465463,307.3511712001414
0.015900288668468467,307.4150598549293
0.01600259207147147,307.28983968398586
0.01610489547447447,307.3208893598901
0.016207198877477475,307.4358207381102
0.01630950228048048,307.6165134039491
0.01641180568348348,307.68388751068983
0.016514109086486484,307.80651605277103
0.016616412489489488,307.98478854182855
0.01671871589249249,307.92774255719735
0.016821019295495492,307.9736949744914
0.016923322698498496,308.1531645546864
0.0170256261015015,308.22451691178264
0.0171279295045045,308.2753183023492
0.017230232907507505,308.31591323866564
0.01733253631051051,308.40432734800186
0.017434839713513513,308.51064295506916
0.017537143116516513,308.4824802628858
0.017639446519519517,308.57394815115754
0.01774174992252252,308.806125205339
0.017844053325525522,308.7872757984093
0.017946356728528526,308.9216307467362
0.01804866013153153,308.942392092385
0.018150963534534534,309.00188264240325
0.018253266937537534,309.0454306342868
0.01835557034054054,309.12784360784514
0.018457873743543542,309.1498564449988
0.018560177146546543,309.36900185838437
0.018662480549549547,309.3849348658251
0.01876478395255255,309.43348760016755
0.018867087355555555,309.39939070615037
0.018969390758558555,309.55068017118487
0.01907169416156156,309.63699765077644
0.019173997564564563,309.66201020213066
0.019276300967567564,309.7468716214841
0.019378604370570568,309.77234631049345
0.019480907773573572,309.8518701881145
0.019583211176576572,309.844543784227
0.019685514579579576,309.96298249577046
0.01978781798258258,310.1294430422808
0.019890121385585584,310.16887532378655
0.019992424788588585,310.24079659704375
0.02009472819159159,310.3633239376229
0.020197031594594593,310.32619378986243
0.020299334997597594,310.44803237802256
0.020401638400600598,310.3440667978239
0.0205039418036036,310.4950902914691
0.020606245206606606,310.76114343085106
0.020708548609609606,310.8018038020533
0.02081085201261261,310.8372585480693
0.020913155415615614,310.78127225523156
0.021015458818618615,311.0509480812531
0.02111776222162162,311.01963243482464
0.021220065624624623,311.12083289472855
0.021322369027627627,311.1743622425102
0.021424672430630627,311.10605869824906
0.02152697583363363,311.14387764287056
0.021629279236636635,311.14165958623136
0.021731582639639636,311.33066077414475
0.02183388604264264,311.4151689022476
0.021936189445645644,311.4966092723993
0.022038492848648648,311.56943795632964
0.022140796251651648,311.659404287268
0.022243099654654652,311.6739180494854
0.022345403057657656,311.76844328990524
0.022447706460660657,311.75579251379014
0.02255000986366366,311.85243564529134
0.022652313266666665,311.76820821200766
0.02275461666966967,311.79470573874653
0.02285692007267267,312.03554513561056
0.022959223475675673,312.26528339872806
0.023061526878678677,312.22023440304747
0.023163830281681678,312.3841676859282
0.023266133684684682,312.3575145460581
0.023368437087687686,312.42049374198575
0.02347074049069069,312.4594719725987
0.02357304389369369,312.4674057108784
0.023675347296696694,312.60026082379005
0.0237776506996997,312.66435139254475
0.0238799541027027,312.7528859277727
0.023982257505705703,312.6599632057675
0.024084560908708707,312.66143781467355
0.024186864311711707,312.92809463539515
0.02428916771471471,312.8185584088891
0.024391471117717715,312.91859705701626
0.02449377452072072,313.14384119587726
0.02459607792372372,313.0131046921705
0.024698381326726724,313.0782969748354
0.024800684729729728,313.24719487072934
0.02490298813273273,313.46779882868043
0.025005291535735732,313.4029051515482
0.025107594938738736,313.56221297133266
0.02520989834174174,313.59497117545015
0.02531220174474474,313.5116139084796
0.025414505147747745,313.48707884329093
0.02551680855075075,313.47255702895296
0.02561911195375375,313.4999286332994
0.025721415356756754,313.69321753265035
0.025823718759759758,313.82212236696597
0.02592602216276276,313.90392871917334
0.026028325565765762,313.9729004158963
0.026130628968768766,314.0581523353587
0.02623293237177177,314.0893718288701
0.02633523577477477,314.2176680053758
0.026437539177777775,314.21041474730856
0.02653984258078078,314.25192322105374
0.026642145983783783,314.32154391352475
0.026744449386786783,314.1924863371627
0.026846752789789787,314.3972504334842
0.02694905619279279,314.4530630213612
0.02705135959579579,314.4018518640262
0.027153662998798796,314.54186008343106
0.0272559664018018,314.5336479395287
0.027358269804804804,314.6107712747293
0.027460573207807804,314.76921129333317
0.027562876610810808,314.7637455271901
0.027665180013813812,314.6958331981936
0.027767483416816813,314.7591490820874
0.027869786819819817,314.8297569688501
0.02797209022282282,315.0997969190381
0.028074393625825825,315.0939813771148
0.028176697028828825,315.2347681962005
0.02827900043183183,315.18416371491384
0.028381303834834833,315.232882197395
0.028483607237837834,315.2304448925786
0.028585910640840838,315.21744431354534
0.028688214043843842,315.2523026227894
0.028790517446846842,315.32880384559047
0.028892820849849846,315.37222510457764
0.02899512425285285,315.49044806602575
0.029097427655855854,315.48455590919673
0.029199731058858855,315.5073731791243
0.02930203446186186,315.6657175627866
0.029404337864864863,315.7569420988658
0.029506641267867863,315.7804808529562
0.029608944670870867,315.9434388830618
0.02971124807387387,315.99190453135003
0.029813551476876875,316.0972561092647
0.029915854879879876,316.15710060291644
0.03001815828288288,316.15236885044607
0.030120461685885884,316.1081522183418
0.030222765088888884,316.109835242115
0.03032506849189189,316.12404056306576
0.030427371894894892,316.14683394352926
0.030529675297897896,316.2231398708579
0.030631978700900897,316.3377701230879
0.0307342821039039,316.4648078254353
0.030836585506906905,316.56978577813265
0.030938888909909906,316.4875302128247
0.03104119231291291,316.58931731455993
0.031143495715915914,316.7201127629097
0.031245799118918918,316.5950313550516
0.031348102521921925,316.7018445987757
0.03145040592492492,316.77275258440386
0.031552709327927926,316.8101232632154
0.03165501273093093,316.96890335332904
0.031757316133933934,316.9303958645711
0.03185961953693694,317.05358524136875
0.03196192293993994,316.99479707064285
0.032064226342942946,316.989802247436
0.03216652974594594,317.1206502361655
0.03226883314894895,317.10405874681913
0.03237113655195195,317.1552380700623
0.032473439954954955,317.20800081819436
0.03257574335795796,317.3623248567349
0.03267804676096096,317.429807830968
0.03278035016396397,317.55913465241014
0.032882653566966964,317.63164822409016
0.03298495696996997,317.59598140579163
0.03308726037297297,317.54877571796624
0.033189563775975976,317.4862120047251
0.03329186717897898,317.5995733367155
0.033394170581981984,317.723568367735
0.03349647398498499,317.7906338680142
0.033598777387987985,317.8302412846466
0.03370108079099099,317.98397354285413
0.03380338419399399,317.95655346001985
0.033905687596997,317.99705130532067
0.034007991,318.0074983693219
0.034110294403003005,317.92278804663306
0.03421259780600601,318.1874663353627
0.034314901209009006,318.2279012377084
0.03441720461201201,318.45044028894415
0.034519508015015014,318.3385192614296
0.03462181141801802,318.44722339246476
0.03472411482102102,318.41215963850107
0.034826418224024026,318.5010479727171
0.03492872162702703,318.4377492564889
0.03503102503003003,318.52728757354214
0.03513332843303303,318.4228633263213
0.035235631836036035,318.5405382077738
0.03533793523903904,318.65586763833556
0.03544023864204204,318.5699707083119
0.03554254204504505,318.67421439121387
0.03564484544804805,318.65300709171686
0.03574714885105105,318.7761037905716
0.03584945225405405,318.90657750396264
0.035951755657057057,318.92045879960244
0.03605405906006006,318.89133757554964
0.036156362463063065,318.8417202825453
0.03625866586606607,318.91890724063023
0.03636096926906907,319.07607289275137
0.03646327267207207,319.2819380870476
0.036565576075075074,319.2494414096459
0.03666787947807808,319.2048887530217
0.03677018288108108,319.21587765575754
0.036872486284084086,319.3974717830713
0.03697478968708709,319.33432656545847
0.037077093090090094,319.45489482288616
0.03717939649309309,319.3722418157145
0.037281699896096095,319.34917448169017
0.0373840032990991,319.41552061461573
0.0374863067021021,319.4736641569635
0.03758861010510511,319.48006000311756
0.03769091350810811,319.55461079308816
0.037793216911111115,319.6735215654955
0.03789552031411411,319.7294645310378
0.037997823717117116,319.79716966551274
0.03810012712012012,319.8920404743232
0.038202430523123124,319.87851337002263
0.03830473392612613,319.9542697503038
0.03840703732912913,319.83418609670855
0.038509340732132136,319.9376757396578
0.03861164413513513,319.9883565831417
0.03871394753813814,319.97034328799015
0.03881625094114114,320.0618562758719
0.038918554344144145,320.1026626990417
0.03902085774714715,320.2449811751643
0.03912316115015015,320.28157876146173
0.03922546455315315,320.2977977003771
0.039327767956156154,320.3589427415199
0.03943007135915916,320.3075636492459
0.03953237476216216,320.38906043224944
0.039634678165165166,320.4090858668157
0.03973698156816817,320.4145078553739
0.039839284971171174,320.6595545834332
0.03994158837417417,320.66661300054534
0.040043891777177175,320.53744017321856
0.04014619518018018,320.64552307899726
0.04024849858318318,320.72922180829886
0.04035080198618619,320.59712433085986
0.04045310538918919,320.6413561103362
0.040555408792192195,320.80773509693194
0.04065771219519519,320.76049121446067
0.040760015598198196,320.8979492417544
0.0408623190012012,320.8894913974823
0.040964622404204204,320.88011261825676
0.04106692580720721,321.2721937778368
0.04116922921021021,321.41562478858657
0.041271532613213216,321.321043361459
0.04137383601621621,321.34143530906505
0.04147613941921922,321.0432323926373
0.04157844282222222,320.8390087843214
0.041680746225225225,320.89006711141377
0.04178304962822823,320.9643137214936
0.04188535303123123,321.09211794719164
0.04198765643423424,321.1410453563834
0.042089959837237234,321.3610021815583
0.04219226324024024,321.3307457742814
0.04229456664324324,321.42661275608253
0.042396870046246246,321.4778037551816
0.04249917344924925,321.5971732687311
0.042601476852252254,321.61311426204963
0.04270378025525526,321.5945843736626
0.042806083658258255,321.58111830568964
0.04290838706126126,321.6156839374466
0.04301069046426426,321.6192963440405
0.04311299386726727,321.78404625236
0.04321529727027027,321.851505250615
0.043317600673273275,321.80837963033986
0.04341990407627628,321.8092733237093
0.043522207479279276,321.87602867415933
0.04362451088228228,321.8584658027956
0.043726814285285284,321.867922119116
0.04382911768828829,321.95899949435795
0.04393142109129129,321.94820825072424
0.044033724494294296,321.9089713341136
0.0441360278972973,321.9516139403741
0.0442383313003003,322.04019778612195
0.0443406347033033,322.1615198338052
0.044442938106306305,322.2582204931341
0.04454524150930931,322.1992098028419
0.04464754491231231,322.1118162964706
0.04474984831531532,322.16266010877564
0.04485215171831832,322.20932789558185
0.04495445512132132,322.3045790224128
0.04505675852432432,322.2848863615528
0.045159061927327326,322.39386387224243
0.04526136533033033,322.47285399916973
0.045363668733333334,322.5188036470993
0.04546597213633634,322.46196930296236
0.04556827553933934,322.5290876251435
0.04567057894234234,322.64083803470197
0.04577288234534534,322.70174768550254
0.04587518574834835,322.635094649961
0.04597748915135135,322.6854531301433
0.046079792554354355,322.53704919358637
0.04618209595735736,322.54720595268924
0.04628439936036036,322.49092923045197
0.04638670276336336,322.69938318773717
0.046489006166366365,322.66610805040597
0.04659130956936937,322.6451735732157
0.04669361297237237,322.73950887830875
0.046795916375375377,322.96508242920356
0.04689821977837838,322.9239952154018
0.047000523181381385,323.1504023577136
0.04710282658438438,323.1912384784185
0.047205129987387386,323.35695426465526
0.04730743339039039,323.375346934574
0.047409736793393394,323.3140076268614
0.0475120401963964,323.32110754875765
0.0476143435993994,323.21724419244634
0.047716647002402406,323.2527514831923
0.0478189504054054,323.16596065168443
0.04792125380840841,323.2465185744976
0.04802355721141141,323.2050025198884
0.048125860614414415,323.22916881875506
0.04822816401741742,323.09323267012786
0.04833046742042042,323.1781716152501
0.04843277082342342,323.23698318418053
0.048535074226426424,323.3038191553482
0.04863737762942943,323.31360519029175
0.04873968103243243,323.4030715592381
0.048841984435435436,323.55493731810986
0.04894428783843844,323.47164495824535
0.049046591241441444,323.634716572092
0.04914889464444444,323.7078682485253
0.049251198047447445,323.69042003833783
0.04935350145045045,323.64273231374216
0.04945580485345345,323.8671365310594
0.04955810825645646,323.70606446139135
0.04966041165945946,323.85247930890006
0.049762715062462465,323.8388326630616
0.04986501846546546,323.8327712224418
0.049967321868468466,323.7872408586635
0.05006962527147147,323.82365766637423
0.050171928674474474,323.8042073760271
0.05027423207747748,323.87090789021363
0.05037653548048048,323.8729225325265
0.050478838883483486,323.9783042646432
0.05058114228648648,324.08422966978793
0.05068344568948949,324.0647585127269
0.05078574909249249,324.13493450589147
0.050888052495495495,324.0453899113682
0.0509903558984985,324.17763717547774
0.0510926593015015,324.2153484231812
0.05119496270450451,324.1327479891831
0.051297266107507504,324.0640870648154
0.05139956951051051,324.21373015183923
0.05150187291351351,324.21154537483073
0.051604176316516516,324.2719441163016
0.05170647971951952,324.18453445173935
0.051808783122522524,324.2820881486412
0.05191108652552553,324.42421392328623
0.052013389928528525,324.37511001762397
0.05211569333153153,324.5600296663149
0.05221799673453453,324.6091079329791
0.05232030013753754,324.62351971875944
0.05242260354054054,324.62266455989635
0.052524906943543545,324.5801613099872
0.05262721034654655,324.5385513248146
0.052729513749549546,324.5741860052929
0.05283181715255255,324.5938298534383
0.052934120555555554,324.4990793269831
0.05303642395855856,324.4512909526928
0.05313872736156156,324.4162965864218
0.053241030764564566,324.48192382899816
0.05334333416756757,324.55581882800175
0.05344563757057057,324.55843522692413
0.05354794097357357,324.62589724594807
0.053650244376576575,324.788288756266
0.05375254777957958,324.81305162917624
0.05385485118258258,324.8526035617957
0.05395715458558559,324.801570495712
0.05405945798858859,324.9379333182466
0.05416176139159159,325.03912948634803
0.05426406479459459,324.97700380590123
0.054366368197597596,324.98349948605494
0.0544686716006006,325.0071616973683
0.054570975003603604,324.99413845013004
0.05467327840660661,324.8753435836283
0.05477558180960961,324.85031682295494
0.05487788521261261,324.8292310890061
0.05498018861561561,324.99135654380683
0.05508249201861862,324.8738989141232
0.05518479542162162,324.9917120903737
0.055287098824624625,325.010654471782
0.05538940222762763,325.11187493957294
0.05549170563063063,325.2033335438911
0.05559400903363363,325.17842443729006
0.055696312436636634,325.1649194377584
0.05579861583963964,325.22242084365666
0.05590091924264264,325.23618682716517
0.056003222645645646,325.27811983061486
0.05610552604864865,325.2310533927582
0.056207829451651654,325.3819736110235
0.05631013285465465,325.3474052158757
0.056412436257657655,325.39324845727236
0.05651473966066066,325.40842296322825
0.05661704306366366,325.5397695317327
0.05671934646666667,325.50047595481016
0.05682164986966967,325.4500609659514
0.05692395327267267,325.4447867634585
0.05702625667567567,325.4272034930644
0.057128560078678677,325.532668119526
0.05723086348168168,325.39906416264057
0.057333166884684685,325.42679321242355
0.05743547028768769,325.34400053896303
0.05753777369069069,325.3307535843017
0.05764007709369369,325.3790125890642
0.057742380496696694,325.3905823665494
0.0578446838996997,325.43189183586924
0.0579469873027027,325.3677837515992
0.058049290705705706,325.4715780523719
0.05815159410870871,325.57071133048896
0.058253897511711714,325.685693946993
0.05835620091471471,325.6795217248631
0.058458504317717715,325.66319879120755
0.05856080772072072,325.7173027173801
0.05866311112372372,325.83746142509347
0.05876541452672673,325.9121590267405
0.05886771792972973,325.9669949614609
0.058970021332732735,325.9286178179129
0.05907232473573573,325.8723233608213
0.059174628138738736,325.68143297666194
0.05927693154174174,325.8166552545748
0.059379234944744744,325.6768300114173
0.05948153834774775,325.7462507667153
0.05958384175075075,325.69133083295804
0.059686145153753756,325.7859215727555
0.05978844855675675,325.7297882962118
0.05989075195975976,325.86661600797123
0.05999305536276276,325.78279292344473
0.060095358765765765,325.88598821607826
0.06019766216876877,325.89966395702237
0.06029996557177177,326.04552068418724
0.06040226897477478,326.010305391664
0.060504572377777774,326.0080957972551
0.06060687578078078,325.9349369787127
0.06070917918378378,325.93448833230224
0.060811482586786786,325.86571993051086
0.06091378598978979,325.88140486619534
0.061016089392792794,325.68624566016643
0.0611183927957958,325.55121065697176
0.061220696198798795,325.2419881823219
0.0613229996018018,325.06055699948627
0.0614253030048048,325.08424491326605
0.06152760640780781,325.0084022672593
0.06162990981081081,324.9809434519038
0.061732213213813815,324.90791789833224
0.06183451661681682,325.0993467473984
0.061936820019819816,325.0083190084169
0.06203912342282282,325.1149547007394
0.062141426825825824,325.1774015731916
0.06224373022882883,325.2723642531601
0.06234603363183183,325.2772604526329
0.062448337034834836,325.41338752600365
0.06255064043783784,325.43718347678924
0.06265294384084084,325.3047510781915
0.06275524724384385,325.4312142662161
0.06285755064684685,325.4423196851143
0.06295985404984984,325.46533346573005
0.06306215745285285,325.4532911586523
0.06316446085585585,325.5531825506456
0.06326676425885885,325.45365596477217
0.06336906766186186,325.4884260719948
0.06347137106486486,325.42406487056803
0.06357367446786787,325.33204111171335
0.06367597787087087,325.4220913659408
0.06377828127387387,325.4244159528558
0.06388058467687688,325.4934921470791
0.06398288807987988,325.4102042022265
0.06408519148288289,325.4625685657447
0.06418749488588589,325.48981884286997
0.0642897982888889,325.393679806576
0.06439210169189188,325.6226613248383
0.06449440509489489,325.4673760846924
0.06459670849789789,325.5487022191782
0.0646990119009009,325.6890636161352
0.0648013153039039,325.6333525257931
0.0649036187069069,325.6154173218679
0.06500592210990991,325.6507707135296
0.06510822551291291,325.4787188165069
0.06521052891591592,325.60151613210945
0.06531283231891892,325.7413056915354
0.06541513572192192,325.66614217092774
0.06551743912492493,325.7958775263436
0.06561974252792793,325.8151379270435
0.06572204593093094,325.7542366769214
0.06582434933393393,325.7523778056462
0.06592665273693693,325.7996458610262
0.06602895613993993,325.82327964024734
0.06613125954294294,325.7943971494343
0.06623356294594594,325.6486544863869
0.06633586634894895,325.749204681334
0.06643816975195195,325.76876656881876
0.06654047315495495,325.73104621797296
0.06664277655795796,325.7877640550144
0.06674507996096096,325.72949303062114
0.06684738336396397,325.75714572210416
0.06694968676696697,325.673994523178
0.06705199016996997,325.7373750456346
0.06715429357297298,325.7828463725489
0.06725659697597597,325.80557428857804
0.06735890037897897,325.7840600383248
0.06746120378198198,325.8005708156576
0.06756350718498498,325.92521610284484
0.06766581058798798,325.7934911541932
0.06776811399099099,325.9572093131786
0.06787041739399399,326.1361222274839
0.067972720796997,326.0988517826008
0.0680750242,326.0137485082338
0.068177327603003,325.96253003842895
0.06827963100600601,326.017000931744
0.06838193440900901,325.9859395995243
0.06848423781201202,325.95022907869026
0.06858654121501502,326.00056803189113
0.06868884461801801,326.0649935452991
0.06879114802102101,325.9769788715506
0.06889345142402402,325.8994770942967
0.06899575482702702,325.96189166666665
0.06909805823003003,325.9238643400087
0.06920036163303303,325.92938469904516
0.06930266503603603,325.8386596095142
0.06940496843903904,325.8523224049435
0.06950727184204204,325.94703580986237
0.06960957524504505,326.02935749347745
0.06971187864804805,326.01580887206313
0.06981418205105105,326.0111496175386
0.06991648545405406,326.09410583808625
0.07001878885705705,326.0730277485453
0.07012109226006005,326.05781802231536
0.07022339566306306,326.0859381740618
0.07032569906606606,326.0926480276594
0.07042800246906906,326.18512696376797
0.07053030587207207,326.1171638757893
0.07063260927507507,326.2086935548996
0.07073491267807808,326.23209491481185
0.07083721608108108,326.2157141265576
0.07093951948408408,326.1027108061151
0.07104182288708709,326.10321964635654
0.07114412629009009,326.0646838801789
0.0712464296930931,326.0558937779496
0.0713487330960961,326.1351038326598
0.07145103649909909,326.16385764316266
0.0715533399021021,326.2724386199143
0.0716556433051051,326.1044202447871
0.0717579467081081,326.24206430009735
0.07186025011111111,326.3020817823245
0.07196255351411411,326.23429450667413
0.07206485691711711,326.113774715968
0.07216716032012012,326.27272012818446
0.07226946372312312,326.25853317040327
0.07237176712612613,326.2666185775668
0.07247407052912913,326.1878777271787
0.07257637393213213,326.2113688264618
0.07267867733513514,326.3866357516388
0.07278098073813814,326.17774868229355
0.07288328414114113,326.2392284594
0.07298558754414414,326.3490990514863
0.07308789094714714,326.2467400046891
0.07319019435015015,326.19251685047936
0.07329249775315315,326.21660654036265
0.07339480115615615,326.1649561148107
0.07349710455915916,326.20661592275343
0.07359940796216216,326.1945244228457
0.07370171136516517,326.30491165898155
0.07380401476816817,326.2975099254368
0.07390631817117117,326.3769815991952
0.07400862157417418,326.55625382040023
0.07411092497717718,326.2844414688641
0.07421322838018019,326.2345168290237
0.07431553178318318,326.15296507707745
0.07441783518618618,326.3173582309207
0.07452013858918918,326.3254002654172
0.07462244199219219,326.2670821467423
0.07472474539519519,326.2299694197987
0.0748270487981982,326.1906085275022
0.0749293522012012,326.41976943676985
0.0750316556042042,326.313105592608
0.07513395900720721,326.45884403939357
0.07523626241021021,326.3698222935834
0.07533856581321322,326.28534962719107
0.07544086921621622,326.35741607826816
0.07554317261921922,326.255144170379
0.07564547602222223,326.29442206260615
0.07574777942522522,326.1064915767156
0.07585008282822822,326.2128359860068
0.07595238623123123,326.2077266881924
0.07605468963423423,326.25838918887194
0.07615699303723723,326.21639486633137
0.07625929644024024,326.27535625676916
0.07636159984324324,326.33883531419286
0.07646390324624625,326.34481151504446
0.07656620664924925,326.3776136964556
0.07666851005225225,326.23846946749256
0.07677081345525526,326.3782192016386
0.07687311685825826,326.44071130537384
0.07697542026126127,326.43567630154837
0.07707772366426427,326.38525747104575
0.07718002706726726,326.3647751598373
0.07728233047027026,326.4688689592291
0.07738463387327327,326.45564061248945
0.07748693727627627,326.4812380666854
0.07758924067927928,326.43813391026157
0.07769154408228228,326.33862468065894
0.07779384748528528,326.3616677668099
0.07789615088828829,326.2763430244263
0.07799845429129129,326.3097160172733
0.0781007576942943,326.30353611438454
0.0782030610972973,326.2057170741535
0.0783053645003003,326.228645452503
0.07840766790330331,326.1964196211346
0.0785099713063063,326.17752304637935
0.0786122747093093,326.20387236199485
0.0787145781123123,326.13506631653945
0.07881688151531531,326.2027254764908
0.07891918491831831,326.31985920874996
0.07902148832132132,326.3675510040958
0.07912379172432432,326.39316092792126
0.07922609512732733,326.27112351441394
0.07932839853033033,326.34497953383726
0.07943070193333333,326.32490523959893
0.07953300533633634,326.4336184487205
0.07963530873933934,326.32992478682723
0.07973761214234235,326.3536223383399
0.07983991554534535,326.39938402578906
0.07994221894834834,326.3500362519715
0.08004452235135134,326.36739896078666
0.08014682575435435,326.3997527531114
0.08024912915735735,326.2066336500369
0.08035143256036036,326.2781001839408
0.08045373596336336,326.1868543855364
0.08055603936636636,326.1856493255813
0.08065834276936937,326.1469825511672
0.08076064617237237,326.12480193014517
0.08086294957537538,326.17784319117516
0.08096525297837838,326.1279249376012
0.08106755638138138,326.1168496874491
0.08116985978438439,326.09949062396004
0.08127216318738739,326.12888961335716
0.08137446659039038,326.16605789866327
0.08147676999339339,326.11340946944165
0.08157907339639639,326.1017209345892
0.0816813767993994,325.9909363377742
0.0817836802024024,326.2310451271032
0.0818859836054054,326.1020675191618
0.0819882870084084,326.10112779555357
0.08209059041141141,326.07859151614554
0.08219289381441441,326.15061907595157
0.08229519721741742,326.07342875258445
0.08239750062042042,326.0935382283748
0.08249980402342343,325.9540580740595
0.08260210742642643,325.96819112527436
0.08270441082942943,326.12628776537036
0.08280671423243242,326.00352269117974
0.08290901763543543,326.165099172021
0.08301132103843843,326.0192679427511
0.08311362444144144,325.942507884958
0.08321592784444444,325.75790472125743
0.08331823124744744,325.7612532566782
0.08342053465045045,325.75335559911804
0.08352283805345345,325.6197559817253
0.08362514145645646,325.4493018534601
0.08372744485945946,325.35222821544596
0.08382974826246246,325.2464832239189
0.08393205166546547,325.2884734734979
0.08403435506846847,325.25918066410156
0.08413665847147148,325.3067661124534
0.08423896187447447,325.2813223925629
0.08434126527747747,325.2943012624839
0.08444356868048047,325.3574444412687
0.08454587208348348,325.34364086396
0.08464817548648648,325.3321089981512
0.08475047888948949,325.3458426605685
0.08485278229249249,325.4603234874646
0.0849550856954955,325.3227682119625
0.0850573890984985,325.39444795106175
0.0851596925015015,325.44936801341885
0.0852619959045045,325.3475294312151
0.08536429930750751,325.2481943442925