File: RHTT AVG/RHTT_L_DRY_Ex_avg_eng_stress_strain.csv
Engineering Strain,Engineering Stress (MPa),Lower Bound (MPa),Upper Bound (MPa)
-0.00023532,2.2653708333333333,2.2653708333333333,2.2653708333333333
-7.047851851851853e-05,-0.3388554066926312,-0.37331602349946774,-0.30439478988579466
9.436296296296294e-05,5.888368216868516,-2.264866762147813,14.041603195884845
0.00025920444444444443,11.582258817256186,-3.007055389990164,26.171573024502536
0.00042404592592592584,29.37113975091213,4.8867273536978075,53.85555214812645
0.0005888874074074073,50.70618330030803,36.574998587935696,64.83736801268036
0.0007537288888888889,60.78321846171252,52.90813948505057,68.65829743837448
0.0009185703703703703,70.66630015977714,63.151487110802066,78.18111320875221
0.0010834118518518517,90.53474586960093,79.59900728880494,101.47048445039691
0.001248253333333333,100.81235426587108,91.20415503012678,110.42055350161537
0.0014130948148148145,115.19335308788682,108.19353198137685,122.19317419439679
0.0015779362962962961,133.7641421314312,128.16326551675218,139.36501874611025
0.0017427777777777778,144.7760895878957,139.77686734887513,149.7753118269163
0.001907619259259259,154.93082863111061,143.54123746148105,166.32041980074018
0.002072460740740741,167.17452825024372,156.72460989169946,177.624446608788
0.002237302222222222,188.52599420757525,184.09611643962532,192.95587197552518
0.0024021437037037036,196.29301036558155,191.39007598345898,201.19594474770412
0.0025669851851851853,205.82028439032374,198.3715595196001,213.26900926104736
0.0027318266666666664,218.1566468118378,206.8435606857965,229.4697329378791
0.002896668148148148,233.24236084613636,224.6818521158842,241.80286957638853
0.0030615096296296293,242.46987327367725,235.8739230168154,249.0658235305391
0.003226351111111111,253.82540920839074,246.45436934207962,261.1964490747019
0.0033911925925925925,267.64318281139083,258.3342023741118,276.9521632486699
0.0035560340740740737,274.4035624992777,266.43572409576205,282.37140090279337
0.0037208755555555558,283.1796149618377,274.59088286122994,291.7683470624454
0.003885717037037037,292.7889036292904,283.7434892405412,301.83431801803965
0.004050558518518518,300.55486222843575,295.94699685709384,305.16272759977767
0.004215399999999999,306.549274710185,303.51178024985535,309.58676917051463
0.004380241481481481,314.11045330529737,310.0098057291703,318.21110088142444
0.004545082962962963,319.3272209558901,317.2639207628466,321.39052114893354
0.004709924444444444,323.29598914521387,320.0539126050066,326.53806568542115
0.004874765925925926,326.5085492756866,322.84986948578165,330.1672290655916
0.005039607407407407,328.9031092527869,325.36544005237107,332.44077845320277
0.005204448888888888,331.2886028989683,328.00877023012737,334.5684355678092
0.00536929037037037,333.2087658498441,330.68526229798135,335.73226940170684
0.0055341318518518515,334.4491586882956,331.53156896998416,337.36674840660703
0.005698973333333333,335.80580821289874,332.6320224510688,338.9795939747287
0.005863814814814815,336.6111226963577,333.43805920451,339.7841861882054
0.006028656296296296,337.4884506518805,334.1781616342468,340.7987396695142
0.006193497777777777,338.16018866773226,334.8648885219427,341.4554888135218
0.006358339259259258,338.7201164777467,335.6345062656308,341.80572668986264
0.00652318074074074,339.2711705932854,336.2825859833353,342.25975520323544
0.006688022222222222,339.8647070843489,337.1129136281934,342.6165005405044
0.006852863703703703,340.1701908806375,337.5294684111033,342.8109133501717
0.007017705185185185,340.8595761382355,337.7968156041535,343.92233667231756
0.007182546666666666,341.3560238192562,338.49574728667415,344.2163003518383
0.007347388148148147,341.8529740157843,338.71263465084706,344.99331338072153
0.007512229629629629,342.07761334157215,338.9824935544075,345.1727331287368
0.007677071111111111,342.5015836188777,339.3615411649696,345.6416260727858
0.00784191259259259,342.8620240516236,339.72316587230705,346.0008822309402
0.008006754074074073,343.19897936503884,339.965977134482,346.4319815955957
0.008171595555555553,343.48964532092197,340.26652082940683,346.7127698124371
0.008336437037037035,343.7592807689687,340.54307760205995,346.9754839358775
0.008501278518518517,343.9982507091034,340.8592838983829,347.1372175198239
0.008666119999999998,344.35688815349476,341.2088942511995,347.50488205579
0.00883096148148148,344.5870308148839,341.34231479362046,347.8317468361474
0.008995802962962962,344.8480885257301,341.51119984561296,348.1849772058472
0.009160644444444442,345.11854138700477,341.82235778150414,348.4147249925054
0.009325485925925924,345.50149271810506,342.23365310128264,348.76933233492747
0.009490327407407406,345.72697425074,342.59608326894056,348.85786523253944
0.009655168888888887,345.9490868898358,342.77352849501256,349.1246452846591
0.009820010370370369,346.15619378104356,342.9155703253136,349.39681723677353
0.00998485185185185,346.48186549224573,343.14429592951865,349.8194350549728
0.010149693333333331,346.7125818916926,343.35407926024794,350.07108452313724
0.010314534814814813,346.9147493587249,343.56264258678794,350.2668561306619
0.010479376296296295,347.11958295990104,343.7576875510201,350.48147836878195
0.010644217777777775,347.22314645658815,343.85148604176334,350.59480687141297
0.010809059259259257,347.4288377916204,344.0954974679193,350.76217811532155
0.01097390074074074,347.74100613566014,344.44563547854756,351.0363767927727
0.01113874222222222,347.89809163136033,344.74402302919765,351.052160233523
0.011303583703703702,347.936245512719,344.9029335029116,350.9695575225264
0.011468425185185184,348.46995051094945,344.92627461732843,352.01362640457046
0.011633266666666664,348.72319644437994,345.05253777381864,352.39385511494123
0.011798108148148146,348.61756768316076,345.5369412298984,351.6981941364231
0.011962949629629628,348.9803031917129,345.8907352461171,352.06987113730867
0.012127791111111109,349.1002007106961,345.9653058851546,352.23509553623757
0.01229263259259259,349.3046100066259,346.07795801115196,352.5312620020999
0.012457474074074073,349.6058298056879,346.2695357118959,352.9421238994799
0.012622315555555553,349.7676350696805,346.3959608860254,353.1393092533356
0.012787157037037035,349.87830556597356,346.47763040302743,353.2789807289197
0.012951998518518516,350.0751270512498,346.648585179913,353.5016689225866
0.013116839999999998,350.2770922418054,346.8638072449239,353.6903772386869
0.01328168148148148,350.53112851809846,347.11432821510965,353.94792882108726
0.01344652296296296,350.6991260628805,347.40828873948806,353.98996338627296
0.013611364444444442,351.03138586616944,347.75328838586205,354.30948334647684
0.013776205925925924,351.1191842079904,347.91882515600213,354.3195432599786
0.013941047407407405,351.3368229632518,348.01420913909647,354.6594367874071
0.014105888888888887,351.4761396025374,348.0777056560626,354.87457354901215
0.014270730370370369,351.6724675735028,348.16818300019617,355.1767521468094
0.014435571851851849,351.8352573138156,348.31496573772455,355.35554888990663
0.014600413333333331,351.9924225680721,348.45505916459746,355.5297859715467
0.014765254814814813,352.1344212654195,348.6447300843385,355.62411244650053
0.014930096296296293,352.3046681378616,348.8610911408199,355.7482451349033
0.015094937777777775,352.455285720685,349.0109380954813,355.89963334588873
0.015259779259259258,352.7855815641743,349.5104596921032,356.06070343624543
0.01542462074074074,352.9850667901314,349.6586156205555,356.31151795970726
0.015589462222222222,353.16739431047455,349.78096277146676,356.55382584948234
0.0157543037037037,353.2927912480344,349.8935539159044,356.6920285801644
0.015919145185185182,353.4276821576301,349.9991251625637,356.8562391526965
0.016083986666666664,353.53331678571493,350.0664091987915,357.00022437263834
0.016248828148148146,353.6432438806099,350.10242142519814,357.1840663360216
0.01641366962962963,353.83874820566535,350.30038585065955,357.37711056067116
0.016578511111111107,354.0359197670178,350.502585393194,357.56925414084157
0.01674335259259259,354.2362051659765,350.6742064278377,357.7982039041153
0.01690819407407407,354.38519081996026,350.8002610214769,357.9701206184436
0.017073035555555553,354.55912468553186,351.11098005630606,358.00726931475765
0.017237877037037035,354.68664160553453,351.26391790493454,358.1093653061345
0.017402718518518517,354.80372519382786,351.3198476114295,358.2876027762262
0.017567559999999996,354.96508397044283,351.48386140450793,358.44630653637773
0.017732401481481478,355.1472889443145,351.6101227361084,358.68445515252057
0.01789724296296296,355.2360923026112,351.76106130994793,358.7111232952745
0.018062084444444442,355.39584575516267,351.88489720358035,358.906794306745
0.018226925925925924,355.6495098773183,352.06980663470097,359.2292131199356
0.018391767407407406,355.8312365572291,352.25004783713956,359.4124252773186
0.018556608888888885,355.97782086754233,352.42119019136476,359.5344515437199
0.018721450370370367,356.11818487913547,352.5736686902432,359.66270106802773
0.01888629185185185,356.40502434635886,352.9507120320481,359.8593366606696
0.01905113333333333,356.5411228804147,353.03249391183374,360.0497518489957
0.019215974814814813,356.6626516108007,353.070627464607,360.2546757569944
0.019380816296296295,356.7756549910064,353.10652091345145,360.4447890685613
0.019545657777777774,356.85768138479693,353.20884562521184,360.50651714438203
0.019710499259259256,357.0333773567634,353.38536861403657,360.6813860994903
0.019875340740740738,357.2029051274686,353.52997259525404,360.8758376596832
0.02004018222222222,357.3520684831986,353.6888047433822,361.015332223015
0.020205023703703702,357.58021114217803,353.98798538456,361.1724368997961
0.020369865185185184,357.7397085796123,354.1530808379529,361.32633632127164
0.020534706666666663,357.9410858797516,354.2902992740061,361.5918724854971
0.020699548148148145,358.1177126941175,354.4330929075448,361.80233248069015
0.020864389629629627,358.22227159144325,354.5423917708645,361.90215141202196
0.02102923111111111,358.36978017176324,354.70723895125565,362.03232139227083
0.02119407259259259,358.5727803800589,354.8510084132248,362.29455234689294
0.02135891407407407,358.669604807459,354.94617558670717,362.3930340282108
0.02152375555555555,358.7708540342041,355.03842683394566,362.5032812344625
0.021688597037037034,358.9132948516377,355.19492505542325,362.6316646478522
0.021853438518518516,359.16566135866503,355.48100132587956,362.8503213914505
0.022018279999999998,359.3795115238712,355.64104948532145,363.11797356242096
0.02218312148148148,359.44437249015175,355.7129919838033,363.1757529965002
0.02234796296296296,359.3751032472423,355.7495482853494,363.00065820913517
0.02251280444444444,359.54197543946543,355.8280764938177,363.25587438511315
0.022677645925925922,359.7334704353749,355.9034680847873,363.5634727859625
0.022842487407407405,359.85263982299693,355.97698842209996,363.7282912238939
0.023007328888888887,360.00150714283916,356.14381428130116,363.85920000437716
0.02317217037037037,360.2108753325492,356.3388663825766,364.08288428252183
0.023337011851851847,360.4171845012781,356.5290805740135,364.30528842854267
0.02350185333333333,360.5940724956566,356.65244582005465,364.5356991712585
0.02366669481481481,360.6636310389963,356.80247105026734,364.52479102772526
0.023831536296296293,360.7616495398309,356.9308783107378,364.592420768924
0.023996377777777776,360.93054727882236,357.0473900379209,364.81370451972384
0.024161219259259258,361.0639180264111,357.239313178229,364.8885228745932
0.024326060740740736,361.10534638704087,357.3181675465484,364.8925252275333
0.024490902222222218,361.2045394518881,357.4008145642674,365.00826433950874
0.0246557437037037,361.3380041793923,357.47687223472997,365.1991361240547
0.024820585185185182,361.4586268456189,357.5794894684583,365.33776422277947
0.024985426666666664,361.5459430209167,357.6987837400429,365.39310230179046
0.025150268148148146,361.655060707341,357.77407401743665,365.5360473972454
0.025315109629629625,361.8563276815918,357.8753284310574,365.83732693212613
0.025479951111111107,362.0310891995124,357.97697276525565,366.08520563376914
0.02564479259259259,362.1084288090617,358.0611272061816,366.1557304119418
0.02580963407407407,362.1510465214302,358.20680202023925,366.09529102262115
0.025974475555555553,362.2293497180276,358.32967331632995,366.12902611972527
0.026139317037037032,362.3479785639806,358.42454026210777,366.2714168658534
0.026304158518518514,362.49377275150044,358.66666046507527,366.3208850379256
0.026468999999999996,362.61172919948666,358.9020286666296,366.32142973234374
0.026633841481481478,362.635936435507,358.8729946906224,366.3988781803916
0.02679868296296296,362.7444690931378,358.855997379845,366.6329408064306
0.026963524444444442,362.7948935700691,358.8916755243665,366.6981116157717
0.02712836592592592,362.90494333678055,358.9974600938681,366.812426579693
0.027293207407407403,363.0374016302113,359.0812418874616,366.99356137296104
0.027458048888888885,363.13716710854334,359.1413093106992,367.13302490638745
0.027622890370370367,363.2069526227127,359.20817764452676,367.2057276008987
0.02778773185185185,363.35236527236134,359.3699016135151,367.3348289312076
0.02795257333333333,363.3344238749572,359.57895179227575,367.0898959576387
0.02811741481481481,363.40537670473896,359.6487101136835,367.16204329579443
0.02828225629629629,363.6791907220445,359.6800985278537,367.6782829162353
0.028447097777777774,363.7214994322896,359.76911254864643,367.67388631593275
0.028611939259259256,363.8165722704729,359.89151226966624,367.7416322712795
0.028776780740740738,364.0068891953051,360.0352122031644,367.97856618744584
0.02894162222222222,363.9491030531534,360.0554408724778,367.842765233829
0.0291064637037037,364.0681611609053,360.10053496681644,368.0357873549941
0.02927130518518518,364.16225414671754,360.13611328720566,368.1883950062294
0.029436146666666663,364.3388261229589,360.2604937334615,368.4171585124563
0.029600988148148145,364.5376030573372,360.4632194701814,368.611986644493
0.029765829629629627,364.73733072581535,360.650309898779,368.8243515528517
0.02993067111111111,364.82016236030074,360.69882393076546,368.941500789836
0.030095512592592587,364.70557935641796,360.6875680529934,368.7235906598425
0.03026035407407407,364.6733280192731,360.72164402557013,368.625012012976
0.03042519555555555,364.84217355394344,360.8925002222136,368.7918468856733
0.030590037037037034,365.0309994983897,361.05984287449735,369.00215612228203
0.030754878518518516,365.3249339583191,361.1854827388975,369.46438517774067
0.030919719999999998,365.01008946057317,361.181066601103,368.83911232004334
0.03108456148148148,364.9511858851786,361.203037052957,368.6993347174002
0.03124940296296296,365.1652263241118,361.2854523082899,369.0450003399337
0.03141424444444445,365.4026613274938,361.45172374901625,369.3535989059713
0.031579085925925926,365.48610711223256,361.60069238126647,369.37152184319865
0.031743927407407405,365.69786319985917,361.6784387922825,369.7172876074358
0.03190876888888889,365.8590095274215,361.74722992053245,369.97078913431056
0.03207361037037037,365.99444439232286,361.84972169183567,370.13916709281006
0.032238451851851854,365.970108412602,361.87869183252747,370.0615249926765
0.03240329333333333,365.82213678947846,361.8931808861226,369.75109269283433
0.03256813481481481,366.1551332766171,362.03257411241657,370.27769244081765
0.0327329762962963,366.30059249638657,362.0783415257061,370.52284346706705
0.032897817777777776,366.36694836478375,362.19016030531344,370.54373642425406
0.03306265925925926,366.0693378150948,362.2887074270523,369.8499682031373
0.03322750074074074,366.2872461212466,362.34456365576307,370.2299285867301
0.03339234222222222,366.28449869242553,362.4938939446817,370.07510344016936
0.033557183703703704,366.5982342038673,362.72514868022307,370.47131972751157
0.03372202518518518,366.8456046985466,362.83704334556813,370.85416605152506
0.03388686666666667,366.8363592715158,362.79407867520973,370.87863986782185
0.034051708148148147,366.89609225578636,362.77196047154314,371.0202240400296
0.03421654962962963,366.7926103726458,362.72821884702086,370.85700189827077
0.03438139111111111,366.732989691639,362.68887332031795,370.77710606296
0.03454623259259259,366.82460872731724,362.8391451537514,370.81007230088306
0.034711074074074075,367.024467277697,363.09075974840937,370.95817480698463
0.03487591555555555,367.1780810130035,363.24745937196576,371.1087026540413
0.03504075703703704,367.2675111411226,363.3251733096009,371.2098489726443
0.03520559851851852,367.31499765223623,363.1907450060439,371.43925029842853
0.035370439999999996,367.2593609618092,363.3002189075584,371.21850301605997
0.03553528148148148,367.476199600818,363.4487497372827,371.5036494643533
0.03570012296296296,367.64901878706735,363.54151684948135,371.75652072465334
0.035864964444444446,367.7043114206874,363.6638128667648,371.74480997461006
0.036029805925925924,367.7282969442357,363.70790229164317,371.7486915968282
0.03619464740740741,367.87349867757894,363.75290142290396,371.9940959322539
0.03635948888888889,367.8531638345578,363.8184394793719,371.8878881897437
0.03652433037037037,367.81557812860564,363.8550929348445,371.7760633223668
0.03668917185185185,367.89489249086864,363.925848951799,371.86393602993826
0.03685401333333333,368.0495473952084,364.1250752562495,371.97401953416727
0.03701885481481482,368.15446852495626,364.18664903249726,372.12228801741526
0.037183696296296295,368.149618890455,364.1865117906756,372.11272599023437
0.037348537777777774,368.1927825759494,364.2108563883029,372.17470876359596
0.03751337925925926,368.19950351594264,364.16628119305363,372.23272583883164
0.03767822074074074,368.29716627874143,364.2131176133605,372.38121494412235
0.037843062222222223,368.3879475288012,364.26825566956813,372.50763938803425
0.0380079037037037,368.466082642853,364.40705746178224,372.52510782392375
0.03817274518518518,368.51675026637173,364.5510700230087,372.48243050973474
0.038337586666666666,368.5582032565136,364.6693107644178,372.4470957486094
0.038502428148148145,368.61571972208947,364.7782176940373,372.4532217501416
0.03866726962962963,368.6937723003067,364.88190451242815,372.50564008818526
0.03883211111111111,368.67457854141855,364.8567964872582,372.49236059557893
0.038996952592592594,368.7444543427148,364.8826724876235,372.6062361978061
0.03916179407407407,368.8213132113416,364.86934920582127,372.7732772168619
0.03932663555555555,368.83485054349705,364.81556642382395,372.85413466317016
0.03949147703703704,368.8819189133761,364.900897378006,372.86294044874626
0.039656318518518516,368.9910519121917,365.0728709354569,372.90923288892657
0.03982116,369.0540901379624,365.1796222205677,372.92855805535714
0.03998600148148148,369.0584630835068,365.15486952390955,372.96205664310406
0.04015084296296296,368.9900664690944,365.0380368097879,372.9420961284009
0.040315684444444444,369.02991859707424,365.0600608799536,372.9997763141949
0.04048052592592592,368.9930378572239,365.1320174168596,372.8540582975882
0.04064536740740741,368.73520777131006,365.25742378377447,372.21299175884565
0.04081020888888889,369.08868604839233,365.3566035088338,372.82076858795085
0.04097505037037037,369.3449433041136,365.43767877782335,373.25220783040385
0.04113989185185185,369.30038578481157,365.5314786326202,373.06929293700296
0.04130473333333333,369.39702209061863,365.6241179878761,373.16992619336116
0.041469574814814815,369.4778954091063,365.61788331841797,373.3379074997946
0.041634416296296294,369.47033288528075,365.6263806547934,373.3142851157681
0.04179925777777778,369.5052462129368,365.67106749869777,373.33942492717586
0.04196409925925926,369.5259768815648,365.7067638749789,373.34518988815074
0.042128940740740736,369.5550939373387,365.7722977820985,373.3378900925789
0.04229378222222222,369.6385024477969,365.83789138458604,373.43911351100775
0.0424586237037037,369.75956152820976,365.9282062143306,373.5909168420889
0.042623465185185186,369.8425559661947,365.9881399838255,373.69697194856394
0.042788306666666664,369.8266682544346,365.9271658291576,373.7261706797116
0.04295314814814814,369.92881213333214,366.0767477104266,373.7808765562377
0.04311798962962963,369.91688882887036,366.0476820548497,373.786095602891
0.04328283111111111,369.8987574661425,366.01724170940213,373.7802732228829
0.04344767259259259,369.9270090431773,366.09790025653786,373.75611782981673
0.04361251407407407,369.9843049606062,366.19173769267746,373.77687222853496
0.04377735555555556,370.0123675479084,366.23451720133903,373.7902178944778
0.043942197037037035,370.01681751698186,366.24421558667245,373.78941944729127
0.044107038518518514,370.0334897237193,366.2607691703654,373.8062102770732
0.04427188,370.0700031665439,366.30901958421055,373.8309867488773
0.04443672148148148,370.12530014332845,366.39094550854685,373.85965477811004
0.044601562962962964,370.15641735638815,366.49896459372786,373.81387011904843
0.04476640444444444,370.19914551726936,366.52345430961066,373.87483672492806
0.04493124592592592,370.18591686743787,366.5211860168,373.8506477180757
0.045096087407407406,370.184538328269,366.52942348639147,373.83965317014656
0.045260928888888885,370.1764859492499,366.546215307429,373.80675659107084
0.04542577037037037,370.21014387497684,366.57669441228103,373.84359333767264
0.04559061185185185,370.2291337189011,366.59957017674134,373.85869726106085
0.045755453333333335,370.26589457329067,366.6471545728601,373.88463457372126
0.04592029481481481,370.29513621212135,366.69021956897336,373.90005285526934
0.04608513629629629,370.3031389390291,366.7013139155237,373.9049639625345
0.04624997777777778,370.2960249085727,366.69988747028947,373.8921623468559
0.046414819259259256,370.3322990217674,366.79196593701835,373.8726321065165
0.04657966074074074,370.36014716552836,366.84513031564484,373.8751640154119
0.04674450222222222,370.40487273362737,366.8050835202392,374.00466194701556
0.0469093437037037,370.4418792715634,366.8094987634648,374.074259779662
0.047074185185185184,370.4419669018911,366.82119612644516,374.062737677337
0.04723902666666666,370.3542170891525,366.87345923083535,373.8349749474696
0.04740386814814815,370.38020556954024,366.8972112185233,373.8631999205572
0.04756870962962963,370.40830747416805,366.91836758383727,373.89824736449884
0.047733551111111105,370.427084471463,366.94671383529396,373.907455107632
0.04789839259259259,370.44853149601335,366.97101617286575,373.92604681916094
0.04806323407407407,370.45468704360223,366.9795874740244,373.92978661318006
0.048228075555555555,370.43381160374327,366.95547888806544,373.9121443194211
0.048392917037037034,370.42043440134864,366.9448984467517,373.89597035594556
0.04855775851851852,370.3959573079287,366.94036649691634,373.8515481189411
0.0487226,370.3762739598184,366.9369758685651,373.8155720510716
0.048887441481481476,370.4492607826023,366.9471448136982,373.9513767515065
0.04905228296296296,370.4119049190508,367.0070688233191,373.8167410147825
0.04921712444444444,370.33700733812617,366.94822234455125,373.7257923317011
0.049381965925925926,370.42599036088814,367.0392812596846,373.81269946209164
0.049546807407407405,370.41563889029356,367.11277622742347,373.71850155316366
0.04971164888888888,370.36961718511895,367.1278532160358,373.6113811542021
0.04987649037037037,370.283499501227,367.0375826822734,373.52941632018064
0.05004133185185185,370.2101350010133,366.96214796816895,373.4581220338577
0.05020617333333333,370.1817264016703,366.9803140541722,373.3831387491684
0.05037101481481481,370.1718149379076,367.03603884615444,373.3075910296607
0.0505358562962963,370.04521700616306,367.0403912477894,373.0500427645367
0.050700697777777776,369.9819232697208,366.9947674896861,372.9690790497555
0.050865539259259254,370.0917171462803,366.8954539959781,373.28798029658253
0.05103038074074074,370.0788087282078,366.87497929587926,373.2826381605363
0.05119522222222222,370.3500437761335,366.6797045669027,374.0203829853642
0.051360063703703704,370.22360659637604,366.7493107357678,373.6979024569843
0.05152490518518518,370.12165580503626,366.801533021661,373.4417785884115
0.05168974666666666,370.13194633695247,366.78092534453003,373.4829673293749
0.05185458814814815,370.13059095156785,366.7450647623507,373.516117140785
0.052019429629629625,370.1228139620741,366.70786443604266,373.5377634881055
0.05218427111111111,370.11409815639854,366.6686034013673,373.5595929114298
0.05234911259259259,370.10505556468854,366.6279831078293,373.58212802154776
0.05251395407407407,370.058787561608,366.6991478285045,373.41842729471153
0.05267879555555555,369.8934069131509,366.75869469575025,373.02811913055154
0.05284363703703703,369.8995903168767,366.68569945260924,373.11348118114415
0.05300847851851852,369.89808801634496,366.59172051117355,373.20445552151637
0.053173319999999996,369.89571714369384,366.4919196856895,373.2995146016982
0.05333816148148148,369.8955445102283,366.3964615989449,373.39462742151176
0.05350300296296296,369.57962036354564,366.49889136693855,372.66034936015274
0.05366784444444444,369.47548864710683,366.387106461158,372.56387083305566
0.053832685925925924,369.39362357257517,366.2772664472634,372.50998069788693
0.0539975274074074,369.32387380779556,366.1652866123134,372.4824610032777
0.05416236888888889,369.3759813185296,366.22107239513804,372.5308902419212
0.05432721037037037,369.4483967703647,366.2844230729046,372.6123704678248
0.054492051851851846,369.4500755454436,366.27111087696426,372.62904021392296
0.05465689333333333,369.4544926612681,366.26129203462597,372.6476932879102
0.05482173481481481,369.4171749429851,366.1989701310915,372.6353797548787
0.054986576296296295,369.3501228360148,366.12822202410183,372.5720236479278
0.055151417777777774,369.28081869577153,366.05709098622526,372.5045464053178
0.05531625925925926,369.21108001628664,365.9832645687924,372.4388954637809
0.05548110074074074,369.14949146023224,365.90144172695335,372.39754119351113
0.05564594222222222,369.0905247152167,365.80234606393793,372.3787033664955
0.0558107837037037,368.96973783468127,365.7128805647019,372.22659510466065
0.05597562518518518,368.9065434113868,365.5737692116579,372.23931761111567
0.056140466666666666,368.7645069742973,365.4683423308424,372.06067161775223
0.056305308148148145,368.61794956660646,365.35554538073274,371.8803537524802
0.056470149629629623,368.50223388855915,365.28557263331066,371.71889514380763
0.05663499111111111,368.37428332063666,365.1937006889077,371.5548659523656
0.05679983259259259,368.24581178199594,365.0542767240179,371.437346839974
0.05696467407407407,368.1719832154501,364.88162042835455,371.46234600254564
0.05712951555555555,368.10190979371583,364.71461731415917,371.4892022732725
0.05729435703703704,368.0369853666935,364.5557955432972,371.5181751900898
0.057459198518518516,367.9189927061341,364.447888946711,371.3900964655572
0.057624039999999994,367.7398397879762,364.3881708510112,371.09150872494126
0.05778888148148148,367.72646441486546,364.1985200736375,371.2544087560934
0.05795372296296296,367.6209796540964,364.0806469689911,371.1613123392017
0.058118564444444444,367.5120437532943,364.02882343067216,370.9952640759164
0.05828340592592592,367.4189826360901,364.0086867289853,370.8292785431949
0.0584482474074074,367.30528478807435,363.946447603148,370.6641219730007
0.05861308888888889,367.197796311788,363.8919573500683,370.5036352735077
0.058777930370370365,367.117318444977,363.826918480965,370.407718408989
0.05894277185185185,367.03650528133176,363.7414414163175,370.331569146346
0.05910761333333333,366.9538140473311,363.65472451478064,370.25290357988155
0.05927245481481481,366.87227107477577,363.5667549558157,370.1777871937358
0.059437296296296294,366.79900122031984,363.4814813309576,370.1165211096821
0.05960213777777777,366.71304763166864,363.306787456155,370.1193078071823
0.05976697925925926,366.5985975892674,363.14458060240486,370.05261457612994
0.059931820740740736,366.52701952287276,362.90829003276986,370.14574901297567
0.06009666222222222,366.3716650168245,362.60536142755325,370.1379686060958
0.0602615037037037,366.0476801114739,362.04136953907727,370.0539906838705
0.06042634518518518,365.7270977014883,361.4550528602943,369.99914254268225
0.060591186666666665,365.5957027900549,361.30327908347743,369.8881264966323
0.06075602814814814,365.51094655553294,361.2757710247895,369.7461220862764
0.06092086962962963,365.4168644709795,361.22896083738743,369.6047681045715
0.06108571111111111,365.3707182010768,361.24239187462956,369.499044527524
0.061250552592592586,365.3927057922108,361.3452703841766,369.44014120024497
0.06141539407407407,365.4150626494911,361.4453658309183,369.3847594680639
0.06158023555555555,365.32516169640803,361.40022154506323,369.25010184775283
0.061745077037037036,365.10756943035943,361.1367754711411,369.07836338957776
0.061909918518518514,364.8314486080495,360.75997272323576,368.9029244928633
0.06207476,364.5774284625897,360.3883764858062,368.7664804393732
0.06223960148148148,364.50831871963584,360.26267865547055,368.7539587838011
0.062404442962962964,364.5502464970963,360.28233462163354,368.818158372559
0.06256928444444444,364.4960183076676,360.1532528896519,368.8387837256833
0.06273412592592592,364.34771899834163,359.89579075170934,368.7996472449739
0.0628989674074074,364.0432937518923,359.23878787764306,368.8477996261415
0.06306380888888889,363.5383323623588,357.77004893170476,369.30661579301284
0.06322865037037037,363.1307686847213,357.0059765232946,369.25556084614806
0.06339349185185185,362.7704359145306,356.43183931287734,369.10903251618385
0.06355833333333333,362.57949151620903,356.36370877867535,368.7952742537427
0.0637231748148148,362.3885471178874,356.2922014049862,368.4848928307886
0.0638880162962963,362.2580492581673,356.246279118999,368.26981939733565
0.06405285777777778,362.2910356037412,356.43837795726404,368.14369325021835
0.06421769925925926,362.3799884361198,356.761962432426,367.9980144398136
0.06438254074074073,362.4464237847886,357.0525081014357,367.84033946814145
0.06454738222222221,362.3237997774442,356.91657996091925,367.73101959396917
0.0647122237037037,362.19433076853875,356.7031070611527,367.6855544759248
0.06487706518518518,362.0648617596332,356.4872706751946,367.6424528440717
0.06504190666666666,361.90215501964474,356.2323424692698,367.5719675700197
0.06520674814814814,361.65831777292215,355.9004503492765,367.41618519656777
0.06537158962962962,361.42289576643293,355.5682834974283,367.27750803543756
0.06553643111111111,361.1760590844352,355.21509615510064,367.1370220137698
0.06570127259259259,361.1469130082796,355.0564062748684,367.23741974169087
0.06586611407407407,360.75737855683906,354.2741481666735,367.2406089470046
0.06603095555555555,360.28724675328664,353.39658444435554,367.17790906221774
0.06619579703703703,359.81703028521315,352.51322012745135,367.12084044297495
0.06636063851851852,359.4848415252456,351.9678832883448,367.0017997621464
0.06652548,359.29585308096557,351.80188284892404,366.7898233130071
0.06669032148148148,359.2044982829099,351.7642573806858,366.64473918513403
0.06685516296296296,359.1106672707688,351.74418055637574,366.4771539851618
0.06702000444444443,359.0335447416025,351.73621080072104,366.33087868248396
0.06718484592592593,358.95632146382684,351.72822793626074,366.18441499139294
0.0673496874074074,358.83504045959023,351.70353549127435,365.9665454279061
0.06751452888888888,358.5852213394329,351.7346457679919,365.43579691087393
0.06767937037037036,358.513217165178,351.78126309387557,365.2451712364804
0.06784421185185185,361.62059109593366,357.37231648724884,365.8688657046185
0.06800905333333333,361.37328324126406,356.9339625527766,365.8126039297515
0.06817389481481481,361.1075611662379,356.4453157795397,365.769806552936
0.06833873629629629,360.8418489732973,355.9437408550839,365.73995709151075
0.06850357777777777,360.57613678035676,355.43100353334734,365.7212700273662
0.06866841925925926,360.2975617367947,354.8940848370525,365.7010386365369
0.06883326074074074,360.296837498761,354.97078180900945,365.6228931885126
0.06899810222222222,360.3558511311246,355.1732345721537,365.5384676900955
0.0691629437037037,360.5636138104653,355.7172336914899,365.4099939294407
0.06932778518518518,360.8365553452188,356.37434639011127,365.29876430032635
0.06949262666666667,360.56671888437114,355.9346748018298,365.1987629669125
0.06965746814814815,360.1285386542085,355.4045107758978,364.85256653251923
0.06982230962962963,359.69993677818405,354.85498211936834,364.54489143699976
0.0699871511111111,359.33004898795474,354.33427974590944,364.32581823000004
0.07015199259259258,359.14548169589443,354.1902571841978,364.1007062075911
0.07031683407407407,358.9609144038341,354.0450637338406,363.87676507382764
0.07048167555555555,358.82013839536666,353.951229262686,363.6890475280473
0.07064651703703703,358.6859200855752,353.83779556987616,363.5340446012743
0.07081135851851851,358.5387517521404,353.70502510380214,363.37247840047866
0.07097619999999999,358.3591707503263,353.5292703090611,363.18907119159155
0.07114104148148148,358.19435749678263,353.37149330185264,363.0172216917126
0.07130588296296296,358.03086155954696,353.2142492644188,362.8474738546751
0.07147072444444444,357.8673656223113,353.0558565040228,362.6788747405998
0.07163556592592592,357.6105846502249,352.72445005234977,362.4967192481
0.0718004074074074,357.2038430891391,352.0746656366158,362.33302054166245
0.07196524888888889,356.7971015280534,351.41719638442805,362.1770066716788
0.07213009037037037,356.38334625510515,350.7458642375144,362.0208282726959
0.07229493185185185,355.93229138463806,350.0322735702667,361.83230919900944
0.07245977333333332,355.52931459990873,349.4240019521527,361.63462724766475
0.07262461481481482,355.4139159716278,349.49189868875334,361.3359332545022
0.0727894562962963,355.30901510601865,349.5989003504079,361.0191298616294
0.07295429777777777,355.26547032595136,349.8567409208136,360.6741997310891
0.07311913925925925,355.2219255458842,350.1009827923574,360.34286829941095
0.07328398074074073,355.22549909168765,350.3887827222754,360.0622154610999
0.07344882222222222,354.95770771783464,350.0290905221396,359.8863249135297
0.07353124296296296,354.74055423234296,349.6778791892143,359.8032292754716