File: RHTT AVG/RHTT_S_LUB_Ex_avg_eng_stress_strain.csv
Engineering Strain,Engineering Stress (MPa),Lower Bound (MPa),Upper Bound (MPa)
-0.000306477,12.388250000000001,12.388250000000001,12.388250000000001
5.405848948948947e-05,1.276504021878608,-0.5979832621772072,3.150991305934423
0.00041459397897897893,34.31167937639485,19.358332358646383,49.26502639414332
0.0007751294684684684,59.70522845501208,55.13346941123564,64.27698749878853
0.001135664957957958,86.40837544430293,78.87552299295166,93.94122789565421
0.0014962004474474472,118.47014670640174,111.66998902615423,125.27030438664924
0.0018567359369369369,139.5122918910692,137.51617081176283,141.50841297037556
0.0022172714264264265,169.52558407694403,158.1557359461077,180.89543220778035
0.002577806915915916,194.68004745000312,189.35690015033734,200.0031947496689
0.002938342405405405,221.13151137466988,214.7230136121924,227.54000913714736
0.0032988778948948947,241.83625386874328,235.46186902395436,248.2106387135322
0.0036594133843843844,263.65165833844264,256.2754857272405,271.0278309496448
0.004019948873873873,282.90637842959393,279.15652669449065,286.6562301646972
0.004380484363363362,295.3713217531841,293.3147591248759,297.4278843814923
0.0047410198528528525,303.7727751401947,301.6779639190381,305.8675863613513
0.005101555342342342,308.9248536422325,306.765522964561,311.084184319904
0.005462090831831831,311.8674338174943,309.5702997012554,314.1645679337332
0.00582262632132132,314.21454634582176,312.0134674822974,316.4156252093461
0.0061831618108108095,316.02883189996066,313.74371679485074,318.3139470050706
0.0065436973003003,317.2901335111641,315.0921422593471,319.48812476298104
0.006904232789789789,318.36990835919653,316.129480914176,320.6103358042171
0.007264768279279278,319.28880509719164,317.1820284084242,321.3955817859591
0.007625303768768768,320.01615885215324,317.8130817550049,322.2192359493016
0.007985839258258258,320.52831212491503,318.3640675611323,322.6925566886978
0.008346374747747748,321.095437819382,318.9182744081698,323.27260123059426
0.008706910237237237,321.5856738652738,319.51087102758675,323.66047670296086
0.009067445726726726,321.8952292311839,319.7178559265525,324.07260253581535
0.009427981216216215,322.1343044275419,320.02784562102335,324.24076323406047
0.009788516705705706,322.6140000962458,320.47592951100756,324.752070681484
0.010149052195195195,322.9172702338291,320.79584795536124,325.0386925122969
0.010509587684684685,323.0807563400635,320.9427781541064,325.21873452602057
0.010870123174174174,323.373397698359,321.27488101745615,325.4719143792618
0.011230658663663663,323.5908948065894,321.45241219983154,325.72937741334727
0.011591194153153152,323.810234335675,321.8166345060369,325.80383416531305
0.011951729642642642,324.00562298593314,321.996732069526,326.0145139023403
0.012312265132132131,324.2098836444748,321.7818820304461,326.6378852585035
0.01267280062162162,324.46640014000536,322.35988198656764,326.5729182934431
0.013033336111111111,324.5754038087199,322.50591786916425,326.64488974827555
0.0133938716006006,324.7155946519977,322.4825601878924,326.94862911610306
0.01375440709009009,324.9571642169832,322.7062603832024,327.208068050764
0.014114942579579579,325.2288198862137,323.09495134015367,327.3626884322738
0.014475478069069068,325.34245975396004,323.2175736725329,327.46734583538716
0.014836013558558557,325.4307654546045,323.30230356058973,327.5592273486193
0.015196549048048047,325.7261883701527,323.58442163366675,327.8679551066387
0.015557084537537538,325.91698344905416,323.7840113920929,328.0499555060154
0.015917620027027027,326.1392619832547,324.05013066116635,328.22839330534305
0.016278155516516516,326.29337403203795,324.24227634127453,328.34447172280136
0.016638691006006005,326.4990171766564,324.3061193717099,328.69191498160296
0.016999226495495495,326.6435781993025,324.40512454295003,328.882031855655
0.017359761984984984,326.7349928051487,324.5926392566115,328.8773463536859
0.017720297474474473,326.87407579328976,324.7489599711672,328.9991916154123
0.018080832963963962,327.1581430738055,325.10552271387303,329.21076343373795
0.01844136845345345,327.3694191301382,325.2529630035505,329.48587525672593
0.01880190394294294,327.60573765226775,325.3118333281066,329.8996419764289
0.01916243943243243,327.8168607348141,325.5971692622094,330.0365522074188
0.01952297492192192,327.84965363499,325.7106368154291,329.98867045455086
0.019883510411411412,327.9693853662035,325.78253588880466,330.1562348436023
0.0202440459009009,328.2918823354255,326.12578051459116,330.45798415625984
0.02060458139039039,328.52546922017007,326.3797019741429,330.67123646619723
0.02096511687987988,328.69191503490924,326.5253909115876,330.8584391582309
0.02132565236936937,328.90508528078647,326.72276480388683,331.0874057576861
0.021686187858858858,328.98853009410163,326.8122061803323,331.164854007871
0.022046723348348347,329.0893647104589,326.89800392965583,331.28072549126193
0.022407258837837837,329.3644389190141,327.18631037729324,331.542567460735
0.022767794327327326,329.7053689030638,327.5527033222198,331.8580344839078
0.023128329816816815,329.76318138385585,327.62506827857754,331.90129448913416
0.023488865306306304,329.87731739412004,327.6727292253705,332.08190556286957
0.023849400795795794,330.1275757636924,327.97391156521627,332.2812399621685
0.024209936285285283,330.41627435824523,328.2300833909768,332.60246532551366
0.024570471774774772,330.6772672161526,328.41637116147,332.93816327083516
0.02493100726426426,330.8038190271151,328.575321445955,333.03231660827515
0.02529154275375375,330.9325301417242,328.8319501456724,333.033110137776
0.02565207824324324,331.0951900352954,328.94611028840944,333.24426978218133
0.026012613732732733,331.2678795943563,329.10233542987896,333.43342375883367
0.026373149222222222,331.6107093378681,329.3374871211904,333.8839315545458
0.02673368471171171,331.8254284887706,329.6085972083969,334.0422597691444
0.0270942202012012,331.9943031311667,329.7984458523205,334.1901604100129
0.02745475569069069,332.08716514522155,329.87581930291896,334.29851098752414
0.02781529118018018,332.2892259930856,330.1365042693511,334.4419477168201
0.028175826669669668,332.5078127110104,330.4159363641336,334.5996890578872
0.028536362159159157,332.71865576145996,330.4803906772826,334.9569208456373
0.028896897648648646,332.8018524010996,330.47756562538683,335.1261391768124
0.029257433138138136,332.97270953008785,330.6241683946538,335.3212506655219
0.029617968627627625,333.1821895042036,330.8865624176106,335.47781659079664
0.029978504117117114,333.4207479365153,331.2648917298325,335.57660414319804
0.030339039606606603,333.5825329523432,331.5137420228506,335.65132388183576
0.030699575096096093,333.7828033190276,331.517218286466,336.0483883515892
0.031060110585585582,334.03392120394284,331.78244084748576,336.2854015603999
0.031420646075075075,334.1510366343589,331.9462321509762,336.3558411177416
0.03178118156456456,334.2303565303033,331.9863751342006,336.474337926406
0.03214171705405405,334.467877982473,332.1614524562833,336.7743035086627
0.03250225254354354,334.53829266391665,332.2413246230959,336.8352607047374
0.03286278803303303,334.7357400438547,332.4423086263082,337.02917146140123
0.03322332352252252,335.0939990069082,332.8779195583182,337.31007845549817
0.03358385901201201,335.1509451649872,332.81853623755376,337.48335409242065
0.033944394501501496,335.3456073261233,333.0402686035294,337.6509460487172
0.03430492999099099,335.4440437408577,333.1658422232762,337.7222452584392
0.03466546548048048,335.5958097162461,333.2495493844098,337.94207004808237
0.03502600096996997,335.7837805276755,333.380183176916,338.18737787843503
0.03538653645945946,336.02312462342593,333.8025637671808,338.24368547967106
0.035747071948948946,336.2131245714374,333.78796497007994,338.63828417279484
0.03610760743843844,336.37600582277025,334.0333165109972,338.7186951345433
0.036468142927927924,336.5641042674568,334.29157461712566,338.83663391778794
0.03682867841741742,336.69828372424524,334.4686474238322,338.9279200246583
0.0371892139069069,336.8053207566473,334.5824155304446,339.02822598284996
0.037549749396396395,336.9369961331041,334.6016734208208,339.2723188453874
0.03791028488588588,337.1636598177177,334.70754201022214,339.61977762521326
0.038270820375375374,337.29418155954653,334.8957658199366,339.69259729915643
0.03863135586486486,337.4860557465669,335.07431699296393,339.8977945001698
0.03899189135435435,337.5737647277558,335.26422915427247,339.88330030123916
0.03935242684384384,337.72150747338594,335.43457376632006,340.0084411804518
0.03971296233333333,337.97355864559523,335.6200546910502,340.32706260014027
0.04007349782282282,338.1976947314055,335.7965622917781,340.59882717103284
0.04043403331231231,338.22516970750314,335.9136914717995,340.5366479432068
0.0407945688018018,338.3015519652039,335.96120507602814,340.64189885437963
0.04115510429129129,338.4954674680124,336.0709605755916,340.91997436043323
0.04151563978078078,338.63508719558695,336.17230172301475,341.09787266815914
0.041876175270270266,338.8075459317719,336.46145427943725,341.1536375841066
0.04223671075975976,338.9379151024519,336.6723115659421,341.20351863896167
0.042597246249249245,339.11719387356754,336.80888326808974,341.42550447904534
0.04295778173873874,339.31703093169426,336.8921775422065,341.741884321182
0.04331831722822822,339.47471057263317,337.03095663475216,341.9184645105142
0.043678852717717716,339.6348292277704,337.19613967093346,342.07351878460736
0.0440393882072072,339.669957216288,337.21841411418563,342.1215003183904
0.044399923696696694,339.7702204198341,337.4613980306666,342.07904280900163
0.04476045918618618,339.95435318606485,337.62130942762633,342.28739694450337
0.04512099467567567,340.1755654276744,337.7213542760018,342.62977657934704
0.04548153016516516,340.33582171694064,337.87466286447835,342.79698056940293
0.04584206565465465,340.33062603093833,337.90332778396066,342.757924277916
0.046202601144144144,340.57115650212535,338.1333306127401,343.0089823915106
0.04656313663363363,340.73778234676433,338.3101042853747,343.165460408154
0.04692367212312312,340.6830807869166,338.3901058661629,342.9760557076703
0.04728420761261261,340.78914710204754,338.5453103706077,343.0329838334874
0.0476447431021021,341.2375850945997,338.6702520715106,343.80491811768877
0.04800527859159159,341.19540137443323,338.73448848324944,343.656314265617
0.04836581408108108,341.2033247676259,338.7763395595067,343.63030997574504
0.048726349570570565,341.32745100801725,338.8862520035266,343.7686500125079
0.04908688506006006,341.50869728366945,339.10558689185456,343.91180767548434
0.049447420549549544,341.678859289484,339.29079381775944,344.0669247612086
0.049807956039039036,341.77714108559957,339.3812683931628,344.1730137780363
0.05016849152852852,341.93037825813224,339.443157046463,344.4175994698015
0.050529027018018015,342.0202379959471,339.5344753627728,344.50600062912144
0.0508895625075075,342.21314965713606,339.8738643352548,344.55243497901733
0.05125009799699699,342.17681098367063,339.80802958975534,344.54559237758593
0.05161063348648648,342.30408063046787,339.87885603089524,344.7293052300405
0.05197116897597597,342.42115999442245,339.88682035103636,344.95549963780854
0.052331704465465465,342.5989559714853,339.9829260403768,345.21498590259375
0.05269223995495495,342.6849682743756,340.2308388333842,345.139097715367
0.05305277544444444,342.7380113545359,340.3471807704297,345.1288419386421
0.05341331093393393,342.8476154004537,340.4476178261595,345.24761297474794
0.05377384642342342,343.04616751689986,340.56077425137255,345.53156078242716
0.05413438191291291,343.0654909386579,340.6419976605103,345.4889842168055
0.0544949174024024,343.18107065253287,340.7375239627721,345.6246173422936
0.054855452891891886,343.3972506333901,340.9858923270557,345.80860893972454
0.05521598838138138,343.52994751093695,341.1602055372097,345.8996894846642
0.055576523870870864,343.6274960593898,341.32436294216336,345.9306291766162
0.05593705936036036,343.42628926030073,340.76473098117793,346.08784753942354
0.05629759484984984,343.4717069975609,340.5784441639205,346.3649698312013
0.056658130339339335,343.85818645396216,341.41482383153374,346.3015490763906
0.05701866582882882,344.02946682593455,341.71010610045624,346.34882755141285
0.057379201318318314,344.0820715316945,341.5867352837381,346.5774077796509
0.05773973680780781,344.1294750016767,341.49817147287047,346.760778530483
0.05810027229729729,344.27792734470404,341.84622915814305,346.70962553126503
0.058460807786786785,344.3412849763416,341.9114233346382,346.77114661804507
0.05882134327627627,344.30753128244095,341.7461625671486,346.8688999977333
0.059181878765765764,344.4920969943488,342.01804279726923,346.96615119142837
0.05954241425525525,344.5891735238821,342.0931739519355,347.0851730958287
0.05990294974474474,344.71481457894265,342.14159221546,347.2880369424253
0.06026348523423423,344.7749034577725,342.2659713888578,347.2838355266872
0.06062402072372372,344.6714647454558,342.2218463946277,347.12108309628394
0.060984556213213206,344.93933437595103,342.4052449659604,347.4734237859417
0.0613450917027027,345.1074936949893,342.5400807997086,347.6749065902699
0.061705627192192185,345.0927836807716,342.6181321638253,347.56743519771794
0.06206616268168168,345.11087919977547,342.6289552503996,347.59280314915134
0.06242669817117116,345.16306617148564,342.62956889167253,347.69656345129874
0.06278723366066065,345.2564858644426,342.8139408762172,347.699030852668
0.06314776915015015,345.3793803016265,342.9644488929479,347.79431171030507
0.06350830463963963,345.4992409320683,343.0009041213222,347.99757774281437
0.06386884012912912,345.57132180026895,343.0665845735184,348.0760590270195
0.06422937561861862,345.62259378900137,343.1797980323089,348.06538954569385
0.0645899111081081,345.7351059084518,343.2497446720569,348.22046714484674
0.06495044659759759,345.76735527001665,343.24996710569343,348.2847434343399
0.06531098208708708,345.8436013844412,343.31975392581757,348.3674488430648
0.06567151757657658,345.9078247852631,343.3541008854664,348.46154868505977
0.06603205306606606,346.0154672378574,343.44612942576873,348.5848050499461
0.06639258855555555,346.086838557325,343.4971651823528,348.6765119322972
0.06675312404504503,346.08389043935443,343.5512539122676,348.61652696644126
0.06711365953453453,346.18906570457733,343.6900362594935,348.68809514966114
0.06747419502402402,346.2525771845841,343.72006720491083,348.78508716425733
0.0678347305135135,346.2705473312563,343.66596861101726,348.87512605149533
0.06819526600300299,346.3653716253028,343.94657839527605,348.7841648553296
0.06855580149249249,346.3290391195685,343.8218633890758,348.8362148500612
0.06891633698198198,346.480599082003,344.0286916294861,348.93250653451986
0.06927687247147146,346.5360039081149,343.92826252717,349.1437452890598
0.06963740796096096,346.5653696231971,343.95325408492306,349.17748516147117
0.06999794345045045,346.68847543599276,344.0971016556059,349.2798492163796
0.07035847893993993,346.81059698221253,344.2205351205908,349.40065884383426
0.07071901442942942,346.82708845371064,344.3646914334802,349.2894854739411
0.07107954991891892,346.85519488048305,344.44006629254284,349.27032346842327
0.0714400854084084,347.01138502669954,344.6448903300649,349.37787972333416
0.07180062089789789,346.95497867637243,344.4459331499118,349.46402420283306
0.07216115638738738,346.885119308073,344.3344000917715,349.4358385243745
0.07252169187687688,346.92428569699825,344.3376066318577,349.5109647621388
0.07288222736636636,346.91870624384245,344.3002743205355,349.5371381671494
0.07324276285585585,346.98408715407464,344.3408465544623,349.627327753687
0.07360329834534533,347.367480460481,344.7399813029662,349.99497961799574
0.07396383383483483,346.94387005670086,344.3230963223658,349.5646437910359
0.07432436932432432,347.06920607638733,344.45848408276885,349.6799280700058
0.0746849048138138,347.4044079605042,344.8950719821307,349.91374393887776
0.0750454403033033,347.4325896938245,344.9386651887974,349.92651419885163
0.07540597579279279,347.3976018053371,344.8436333337149,349.95157027695933
0.07576651128228228,347.47265627297935,344.94041073816715,350.00490180779155
0.07612704677177176,347.50490271449075,344.9951395006287,350.0146659283528
0.07648758226126126,347.54713497556975,345.01299662164286,350.08127332949664
0.07684811775075075,347.5768360548849,345.03862591999393,350.11504618977585
0.07720865324024023,347.6252844645484,345.04955606758506,350.2010128615117
0.07756918872972972,347.7179886197428,345.13008633563317,350.30589090385246
0.07792972421921922,347.7652173839361,345.1565601570293,350.3738746108429
0.0782902597087087,347.7957213200634,345.278196538402,350.3132461017248
0.07865079519819819,347.8137678307322,345.3871226241954,350.24041303726904
0.07901133068768768,347.869154108466,345.4090386648915,350.32926955204044
0.07937186617717717,347.8571655260823,345.3978259410736,350.31650511109103
0.07973240166666666,347.8738241176678,345.4100507484865,350.3375974868491
0.08009293715615615,347.92856996508414,345.3985564575785,350.4585834725898
0.08045347264564565,348.09374849766937,345.43898070451576,350.748516290823
0.08081400813513513,348.02300825512106,345.4147717466115,350.6312447636306
0.08117454362462462,348.0355346737181,345.4294386301095,350.6416307173267
0.0815350791141141,347.92853026339037,345.3533283309268,350.50373219585396
0.0818956146036036,348.0470758988781,345.5739233284647,350.52022846929157
0.08225615009309309,348.05705013874007,345.5242288259089,350.58987145157124
0.08261668558258257,348.0777967146481,345.55756662129454,350.5980268080017
0.08297722107207206,348.18213433817465,345.58713822902376,350.77713044732553
0.08333775656156156,348.17439261758255,345.56507486171756,350.78371037344755
0.08369829205105105,348.2312357806462,345.63397926409596,350.8284922971965
0.08405882754054053,348.28023529846473,345.6962648526384,350.86420574429104
0.08441936303003002,348.3073395284504,345.71617025530395,350.8985088015969
0.08477989851951952,348.35092757573386,345.7826650581033,350.9191900933644
0.085140434009009,348.377188575117,345.80076412875076,350.9536130214832
0.08550096949849849,348.34357038905745,345.74542126440383,350.94171951371106
0.08586150498798797,348.3657363325552,345.775730148013,350.95574251709735
0.08622204047747747,348.43057761080706,345.91654443828475,350.9446107833294
0.08658257596696696,348.4275168149294,345.897964804191,350.95706882566776
0.08694311145645645,348.3978026187849,345.8894445321516,350.90616070541824
0.08730364694594595,348.41945166274866,345.8799905482602,350.9589127772371
0.08766418243543543,348.4319610364855,345.83144346005594,351.0324786129151
0.08802471792492492,348.46116915369197,345.84317812836764,351.0791601790163
0.0883852534144144,348.49276436921167,345.868519041919,351.11700969650434
0.0887457889039039,348.5595038829629,345.8941675212912,351.22484024463455
0.08910632439339339,348.59240557325984,345.88977474680115,351.2950363997185
0.08946685988288287,348.6110928031811,346.0081822468029,351.21400335955934
0.08982739537237236,348.5974525227363,346.0382760053179,351.1566290401547
0.09018793086186186,348.58316782856537,346.0272542701609,351.13908138696985
0.09054846635135134,348.537046436284,345.9983202950994,351.0757725774686
0.09090900184084083,348.6127824413124,346.0773583994022,351.14820648322257
0.09126953733033032,348.56357271454306,346.0774320118543,351.0497134172318
0.09163007281981982,348.5771508828065,346.0698556945082,351.0844460711048
0.0919906083093093,348.64988468844285,346.06066772440795,351.23910165247776
0.09235114379879879,348.6068748480757,345.97567143506404,351.2380782610873
0.09271167928828829,348.6357479271816,346.03714017425887,351.2343556801044
0.09307221477777777,348.6307032493379,346.0221385001256,351.2392679985502
0.09343275026726726,348.71607835715383,346.0641619705511,351.3679947437566
0.09379328575675674,348.7306046601316,346.1303197958475,351.3308895244156
0.09415382124624624,348.74929405447926,346.13072542055266,351.36786268840586
0.09451435673573573,348.7076459415906,346.0533795095424,351.3619123736388
0.09487489222522522,348.72531178452925,346.11113794736985,351.33948562168865
0.0952354277147147,348.7399560057885,346.1230464025574,351.35686560901956
0.0955959632042042,348.75633301884807,346.11210802960693,351.4005580080892
0.09595649869369369,348.74052810156877,346.0900997949475,351.39095640819005
0.09631703418318317,348.75750339624386,346.1167926581789,351.39821413430883
0.09667756967267266,348.7902162167467,346.2192322501023,351.36120018339113
0.09703810516216216,348.81705658866747,346.32196731254487,351.31214586479007
0.09739864065165164,348.7193811395826,346.1404828759357,351.2982794032295
0.09775917614114113,348.7026536564562,346.0907155727355,351.3145917401769
0.09811971163063063,348.6799483329262,346.01674931660176,351.3431473492506
0.09848024712012012,348.7148750636335,346.1968394287121,351.23291069855486
0.0988407826096096,348.62887871939563,346.1155693941978,351.14218804459347
0.09920131809909909,348.80898094884833,346.165360032707,351.4526018649897
0.09956185358858859,348.8617986898204,346.1720280652736,351.55156931436716
0.09992238907807807,348.8515570707768,346.10481623112355,351.59829791043
0.10028292456756756,348.74702281821874,346.1311069762148,351.36293866022265
0.10064346005705704,348.6946551404968,346.15496474778143,351.2343455332122
0.10100399554654654,348.64543816727445,346.1570220699477,351.1338542646012
0.10136453103603603,348.6335328160361,346.10575632309656,351.16130930897566
0.10172506652552551,348.6676746860206,346.13611130776,351.19923806428113
0.102085602015015,348.70785332775915,346.14910644135296,351.26660021416535
0.1024461375045045,348.7320373905432,346.1549084635576,351.3091663175288
0.10280667299399399,348.71037500097725,346.127937065733,351.2928129362215
0.10316720848348347,348.6613892323331,346.10584094096225,351.2169375237039
0.10352774397297296,348.70277290333485,346.12209014120026,351.28345566546943
0.10388827946246246,348.7867717414791,346.116701336664,351.45684214629415
0.10424881495195194,348.7422974852724,346.07633384119464,351.40826112935014
0.10460935044144143,348.74899036944964,346.0987483244421,351.3992324144572
0.10496988593093093,348.7177414721281,346.09207155545704,351.3434113887992
0.10533042142042041,348.67334527901625,346.06463666150154,351.28205389653095
0.1056909569099099,348.6562836084643,346.0486914024588,351.2638758144698
0.10605149239939939,348.619669648871,345.9936738722948,351.24566542544727
0.10641202788888889,348.62578875365614,346.04837461864804,351.20320288866424
0.10677256337837837,348.6095926775922,346.032936722123,351.18624863306144
0.10713309886786786,348.58670775843484,345.9685304266972,351.20488509017247
0.10749363435735734,348.712354542398,346.29960548517425,351.1251035996217
0.10785416984684684,348.53505407018184,345.92122690355905,351.14888123680464
0.10821470533633633,348.48881482330955,345.90000157648336,351.07762807013575
0.10857524082582581,348.5418208699697,345.92923880730626,351.1544029326331
0.1089357763153153,348.53490909227475,345.92044167504696,351.14937650950253
0.1092963118048048,348.39277292113724,345.5583782419549,351.22716760031955
0.10965684729429429,348.4579774273694,345.74621107348264,351.1697437812562
0.11001738278378377,348.44847031949405,345.7534448242375,351.1434958147506
0.11037791827327327,348.45437836507944,345.7865454119919,351.122211318167
0.11073845376276276,348.43749486866074,345.81342471672457,351.0615650205969
0.11109898925225224,348.5334190662092,346.06776169019577,350.99907644222264
0.11145952474174173,348.48723015245065,346.11075563954864,350.86370466535266
0.11182006023123123,348.45187813759475,346.06264730749115,350.84110896769835
0.11218059572072071,348.51535139577317,345.98345244711436,351.047250344432
0.1125411312102102,348.549214568769,345.9405223345321,351.1579068030059
0.11290166669969968,348.5060031917942,345.8615012912642,351.15050509232424
0.11326220218918918,348.40116543913723,345.6567559430558,351.14557493521863
0.11362273767867867,348.3719247635025,345.6485486631982,351.09530086380676
0.11398327316816816,348.3294236378317,345.62681950254347,351.03202777312
0.11434380865765764,348.30848989702145,345.63142668244114,350.98555311160175
0.11470434414714714,348.23244498059756,345.5510176666385,350.91387229455665
0.11506487963663663,348.1407547886539,345.4633671310404,350.8181424462674
0.11542541512612611,348.12815017153264,345.47925025297644,350.77705009008884
0.11578595061561561,348.08343603761335,345.4594848566716,350.7073872185551
0.1161464861051051,348.07314733553164,345.45175901515256,350.6945356559107
0.11650702159459458,348.06844833140843,345.4407035714065,350.69619309141035
0.11686755708408407,348.0622395850061,345.43102301153056,350.6934561584817
0.11722809257357357,348.05939183846726,345.4114712522097,350.7073124247248
0.11758862806306306,348.0116006315166,345.375057564455,350.6481436985782
0.11794916355255254,348.00238878920374,345.37198286386825,350.6327947145392
0.11830969904204203,347.96426370452883,345.32325722931836,350.6052701797393
0.11867023453153153,347.91094653577403,345.2626305370398,350.55926253450826
0.11903077002102101,347.94314834241504,345.31524321883944,350.57105346599064
0.1193913055105105,347.93205059224226,345.2972890791816,350.5668121053029
0.11975184099999998,347.90372518942365,345.29929204997694,350.50815832887037
0.12011237648948948,347.880967750002,345.2799758072199,350.48195969278413
0.12047291197897897,347.8355676670104,345.217457413008,350.45367792101285
0.12083344746846846,347.8022909246795,345.165026953346,350.43955489601296
0.12119398295795795,347.7844927117982,345.1440837239316,350.42490169966476
0.12155451844744744,347.778598496457,345.1420541797956,350.4151428131184
0.12191505393693693,347.7247540443771,345.0727162030697,350.3767918856845
0.12227558942642641,347.661234005662,344.9972133569003,350.32525465442365
0.12263612491591591,347.5920878826254,344.93567708893517,350.2484986763156
0.1229966604054054,347.60891774500976,344.9207578838253,350.29707760619425
0.12335719589489488,347.5404861025976,344.8623216549102,350.21865055028496
0.12371773138438437,347.4898450735985,344.8385508467234,350.1411393004735
0.12407826687387387,347.4548030434723,344.792893638428,350.1167124485166
0.12443880236336335,347.39783203837135,344.7219719408966,350.0736921358461
0.12479933785285285,347.35550380881114,344.66888178642193,350.04212583120034
0.12515987334234233,347.32377971752766,344.57820989876194,350.0693495362934
0.12552040883183183,347.2912061316198,344.51473949515486,350.0676727680847
0.1258809443213213,347.22585683552217,344.4635087957281,349.9882048753162
0.1262414798108108,347.1313744829934,344.3578631530272,349.9048858129596
0.1266020153003003,347.0592586562765,344.1918137530132,349.92670355953976
0.12696255078978977,347.1029952785584,344.374771026162,349.8312195309548
0.12732308627927927,347.10132769947035,344.43783553124575,349.76481986769494
0.12768362176876877,347.06579606525776,344.39131318305596,349.74027894745956
0.12804415725825824,347.04303234287073,344.3470157348222,349.73904895091925
0.12840469274774774,347.0001334104985,344.2903128641283,349.70995395686873
0.12876522823723724,346.9209171299099,344.22481479107455,349.6170194687453
0.1291257637267267,346.82918803161164,344.1671085287432,349.4912675344801
0.1294862992162162,346.80784287441054,344.1060721050352,349.5096136437859
0.12984683470570568,346.7510982431678,344.03161817621253,349.4705783101231
0.13020737019519518,346.6421915484812,343.9108560081169,349.3735270888455
0.13056790568468468,346.58446454799054,343.8743384151035,349.29459068087755
0.13092844117417415,346.538909399903,343.8081668149719,349.26965198483407
0.13128897666366365,346.431834945356,343.6381402340277,349.22552965668433
0.13164951215315315,346.28245330502233,343.3987241038679,349.16618250617677
0.13201004764264263,346.3807386025724,343.6319439469989,349.12953325814595
0.13237058313213212,346.19747985497804,343.3442351374962,349.0507245724599
0.13273111862162162,345.9943457397384,342.97501581059964,349.0136756688771
0.1330916541111111,346.21188028930885,343.38957218306956,349.03418839554814
0.1334521896006006,346.2411122541769,343.46270724933896,349.0195172590149
0.13381272509009007,346.0866113474647,343.2565704354409,348.91665225948856
0.13417326057957957,346.02574353552757,343.2052405778953,348.8462464931598
0.13453379606906907,345.9706501384906,343.172195611559,348.7691046654222
0.13489433155855854,345.95003560349966,343.14888630372235,348.75118490327696
0.13525486704804804,345.90093679856125,343.10982955397947,348.692044043143
0.13561540253753754,345.81200327521026,343.0203947504198,348.6036118000007
0.135975938027027,345.65660368673514,342.8275463715783,348.48566100189197
0.1363364735165165,345.528548593018,342.6353394724933,348.4217577135427
0.13669700900600598,345.4666690656636,342.56165621941994,348.3716819119073
0.13705754449549548,345.37699472349226,342.4775211227511,348.2764683242334
0.13741807998498498,345.30651287389554,342.3831948430517,348.2298309047394
0.13777861547447445,345.24603621686896,342.28443259285433,348.2076398408836
0.13813915096396395,345.18613277208493,342.22037126341405,348.1518942807558
0.13849968645345345,345.13288936278036,342.13868875016067,348.12708997540005
0.13886022194294292,345.0511804844825,342.0407508346474,348.06161013431756
0.13922075743243242,344.9492332499944,341.94515107445227,347.9533154255365
0.13958129292192192,344.8415560787442,341.8498188443646,347.83329331312376
0.1399418284114114,344.734271310066,341.74107765150853,347.72746496862345
0.1403023639009009,344.6484570143171,341.6072932249447,347.6896208036895
0.14066289939039037,344.55793752023385,341.48202616893883,347.63384887152887
0.14102343487987987,344.42816789744285,341.32014593079043,347.53618986409526
0.14138397036936937,344.3301256945041,341.23719598688376,347.4230554021244
0.14174450585885884,344.1418912745502,341.0408773413554,347.24290520774497
0.14210504134834834,343.84711061381006,340.71412008833863,346.9801011392815
0.14246557683783784,343.5136236391528,340.6446646780236,346.382582600282
0.1428261123273273,343.95299060647625,340.6758823622512,347.2300988507013
0.1431866478168168,343.81396467875066,340.64251166393694,346.9854176935644
0.14354718330630628,343.73802645667723,340.58922992365126,346.8868229897032
0.14390771879579578,343.64404246482565,340.4844973928753,346.803587536776
0.14426825428528528,343.5958290647621,340.3696352839096,346.8220228456146
0.14462878977477475,343.51022296475657,340.2210085025087,346.7994374270044
0.14498932526426425,343.3849250189877,340.02993251768595,346.73991752028945
0.14534986075375375,343.0857836939608,339.8382567004994,346.3333106874222
0.14571039624324322,342.96263356717407,339.5862261661492,346.33904096819896
0.14607093173273272,342.7929443863962,339.2576856107299,346.3282031620625
0.14643146722222222,342.4690862792671,338.9664532005841,345.9717193579501
0.1467920027117117,342.4764681157417,338.79843601904855,346.1545002124348
0.1471525382012012,342.42644138302893,338.7549055044883,346.09797726156955
0.14751307369069067,342.3307638824055,338.68104022167415,345.98048754313686
0.14787360918018017,342.1500781357894,338.56681469210287,345.7333415794759
0.14823414466966967,342.0641599933523,338.45213744476695,345.67618254193764
0.14859468015915914,341.97888668386594,338.2933325118092,345.6644408559227
0.14895521564864864,341.82659966867595,338.0720424197791,345.5811569175728
0.14931575113813814,341.61525317001957,337.76992743848876,345.4605789015504
0.1496762866276276,341.3925073847291,337.4614617429521,345.32355302650603
0.1500368221171171,341.1577748262067,337.02316326505314,345.2923863873603
0.1503973576066066,340.9701785359611,336.782028142719,345.1583289292032
0.15075789309609608,340.8482293548614,336.7642273922959,344.93223131742695
0.15111842858558558,340.74208134190405,336.7510463241822,344.7331163596259
0.15147896407507505,340.6609510918232,336.7031380551746,344.61876412847187
0.15183949956456455,340.4938643911163,336.52249519854087,344.4652335836917
0.15220003505405405,339.9610596201208,335.88353136885416,344.03858787138745
0.15256057054354352,339.7252915448113,335.6176860671556,343.83289702246697
0.15292110603303302,339.5273187491063,335.2120193116425,343.8426181865701
0.15328164152252252,339.1934033607535,334.6339652644416,343.7528414570654
0.153642177012012,338.8351455329735,333.7290187373211,343.9412723286259
0.1540027125015015,338.77497147939056,333.7141147183631,343.83582824041804
0.15436324799099096,338.7359214601164,333.7773454405608,343.694497479672
0.15472378348048046,338.679647875907,333.75877826340894,343.60051748840505
0.15508431896996996,338.4788468452597,333.3771563864085,343.58053730411086
0.15544485445945944,338.1740436207499,333.1006318284622,343.2474554130376
0.15580538994894894,337.86067500257775,332.8215516080669,342.8997983970886
0.15616592543843844,337.6622714412973,332.6157883281224,342.70875455447225
0.1565264609279279,337.46660103919805,332.35466540214037,342.57853667625574
0.1568869964174174,337.0246966300654,331.4992521629543,342.55014109717655
0.1572475319069069,336.44412293703226,330.5147796080432,342.3734662660213
0.15760806739639638,335.9408216193321,329.5054411779493,342.3762020607149
0.15796860288588588,335.7658787113536,329.4229133964616,342.1088440262456
0.15832913837537535,335.5476614095999,329.18953224700925,341.9057905721906
0.15868967386486485,335.4254895731077,328.9990965406947,341.8518826055207
0.15905020935435435,335.14283186174555,328.5934301241548,341.6922335993363
0.15941074484384382,334.81689779423607,328.12908512226863,341.5047104662035
0.15977128033333332,334.4440284107296,327.616976914152,341.2710799073071
0.16013181582282282,334.1697804981797,327.1716389321888,341.1679220641706
0.1604923513123123,333.78502053800196,326.3834626199172,341.1865784560867
0.1608528868018018,333.31547015291983,325.32737388388506,341.3035664219546
0.1612134222912913,336.84352477513164,333.7567574996033,339.93029205066
0.16157395778078076,336.52760818825686,333.248650572192,339.80656580432174
0.16193449327027026,335.8125164088254,331.82765672348415,339.7973760941666
0.16229502875975974,335.3470149709333,330.9982827238565,339.69574721801007
0.16265556424924923,335.3978826188526,331.44219246230625,339.3535727753989
0.16301609973873873,335.3778396731244,331.72441355787436,339.03126578837447
0.1633766352282282,334.96085795821296,331.2932548280351,338.6284610883908
0.1637371707177177,334.29871137540425,330.838838691139,337.7585840596695
0.1640977062072072,333.82308870553305,330.54669048076914,337.09948693029696
0.16445824169669668,333.6629750353757,330.0929448362215,337.23300523452997
0.16481877718618618,333.48556062911325,329.6230902051555,337.348031053071
0.16517931267567565,333.01944884581826,328.7458187979375,337.29307889369903
0.16553984816516515,332.5459101870192,327.8419766290387,337.24984374499974
0.16590038365465465,331.9556803982272,326.64537310892837,337.265987687526
0.16626091914414412,331.5398358268299,325.89853273360535,337.1811389200545
0.16662145463363362,331.13702346927096,325.44325545465927,336.83079148388265
0.16698199012312312,330.7016646165316,324.95736105155464,336.4459681815086
0.1673425256126126,330.16815161957436,324.1882410114908,336.14806222765793
0.1677030611021021,329.59319708184967,323.41890360014816,335.7674905635512
0.1680635965915916,331.53532959281796,326.15588678625494,336.914772399381
0.16842413208108106,330.70792573439024,325.7920187180734,335.6238327507071
0.16878466757057056,330.2772099898879,325.68365847332086,334.870761506455
0.16914520306006003,330.3329367271106,325.5557202251673,335.11015322905394
0.16950573854954953,330.1985373154029,324.88188003133024,335.5151945994756
0.16986627403903903,329.95479166095566,324.214637161279,335.69494616063236
0.1702268095285285,333.7482349264358,331.5999801123307,335.89648974054097
0.170587345018018,333.6844235829582,331.57625148932914,335.7925956765872
0.1709478805075075,333.35194942882526,331.1508123938263,335.55308646382423
0.17112814825225223,333.14019269380555,330.8725978331591,335.407787554452