File: RHTT AVG/RHTT_L_LUB_Ex_avg_true_stress_strain.csv
True Strain,True Stress (MPa),Lower Bound (MPa),Upper Bound (MPa)
-0.00038621357086070874,2.084236550762542,2.084236550762542,2.084236550762542
-2.310195153269507e-05,0.6346996259825907,-0.6484998438677285,1.91789909583291
0.0003398778656046868,27.873249510899274,11.43652558444593,44.309973437352625
0.0007027259761999017,58.369473087456996,42.35456949982616,74.38437667508782
0.0010654424757968906,85.98444112255915,70.33400263894461,101.6348796061737
0.001428027459836443,116.18014229613209,100.76600533567576,131.59427925658844
0.0017904810236549036,138.52737449749776,124.96801840628831,152.08673058870724
0.0021528032624849908,161.9436152304174,152.49486701428586,171.39236344654896
0.00251499427145661,190.84185974293047,178.5678667837378,203.11585270212314
0.0028770541455956735,214.56505971455306,203.41958359261912,225.710535836487
0.003238982979824916,242.7065067445064,229.23457349558535,256.17843999342745
0.0036007808689647084,265.4335327462539,248.97546535210185,281.89160014040596
0.003962447907731655,286.32661399463194,277.92354751058747,294.7296804786764
0.004323984190740516,295.2566280537408,287.2432463138876,303.270009793594
0.004685389812502803,304.1326488824937,300.71324062784043,307.5520571371469
0.005046664867427596,308.8459338122219,305.7306901839143,311.96117744052947
0.005407809449822352,312.6467878493616,310.3934431103933,314.90013258832994
0.005768823653891724,315.03162805301105,312.95406509675445,317.10919100926765
0.006129707573738375,316.9856892486068,314.8801706794154,319.09120781779814
0.006490461303363788,318.6309880343726,316.47887349609664,320.78310257264854
0.006851084936667085,320.00077867309227,317.9438563021475,322.057701044037
0.00721157856744584,321.11711066925795,319.16722096614563,323.06700037237033
0.007571942289396881,322.01522029662686,320.0873021917555,323.9431384014983
0.007932176196114901,322.8603184120519,320.9079408602465,324.8126959638574
0.008292280381094357,323.4879314175607,321.60025956979786,325.3756032653235
0.008652254937728083,324.119875580732,322.09685036441397,326.14290079705006
0.00901209995930809,324.69521246918873,322.73092413122424,326.65950080715317
0.009371815539026376,325.1129645331194,323.15031546090063,327.0756136053381
0.009731401769973742,325.6900935504313,323.78676116574354,327.593425935119
0.010090858745140608,326.07367606234516,324.15445712454897,327.99289500014135
0.01045018655741781,326.44684449521924,324.5581314495003,328.3355575409382
0.010809385299595424,327.00105073061377,325.0748480969042,328.92725336432335
0.011168455064363574,327.2928764169258,325.35108185700824,329.2346709768434
0.01152739594431323,327.56459075251297,325.6826865291972,329.4464949758287
0.011886208031935035,327.9728759525471,326.1413044871798,329.8044474179144
0.01224489141962011,328.3198102509362,326.46614398004823,330.1734765218242
0.012603446199660851,328.74213740959874,326.79172239260413,330.6925524265933
0.012961872464249536,329.15200770143355,327.32965840122705,330.97435700164
0.013320170305480222,329.4001728203765,327.6046617293879,331.19568391136505
0.013678339815347357,329.65983163426085,327.7971809524748,331.52248231604693
0.01403638108574657,330.0406756519634,328.132909338676,331.9484419652508
0.01439429420847548,330.43565008004265,328.64147749305084,332.22982266703445
0.014752079275232515,330.7638584284233,329.004586960332,332.52312989651466
0.015109736377617713,331.1435819677257,329.3665761868252,332.9205877486262
0.015467265607133521,331.4297328191471,329.7975599962996,333.0619056419946
0.01582466705518362,331.72580444682853,330.05858874438655,333.39302014927046
0.01618194081307372,332.13756263671996,330.45730066449113,333.8178246089488
0.01653908697201236,332.47350931917197,330.8635327920855,334.08348584625844
0.01689610562310952,332.77573752161635,331.12655619359316,334.42491884963954
0.017252996857378498,333.04979045496935,331.3951798651158,334.70440104482293
0.01760976076573453,333.3105760600992,331.6408342092741,334.9803179109244
0.017966397438995578,333.6385000243581,332.0207180717462,335.25628197697
0.01832290696788313,334.0483964077603,332.4511453431987,335.64564747232197
0.01867928944302102,334.38703024885365,332.72361229628075,336.05044820142655
0.019035544954936232,334.6969146683698,332.9459345151268,336.44789482161275
0.01939167359405968,334.9826319508382,333.35063023657705,336.61463366509935
0.019747675450725054,335.34404904446825,333.7087162636115,336.97938182532505
0.020103550615169583,335.6439799552028,333.96676426117443,337.3211956492311
0.020459299177534866,335.99548887216037,334.3183469576684,337.6726307866524
0.02081492122786566,336.29131670086815,334.5857118087747,337.99692159296154
0.021170416856110708,336.58340977808285,334.9700593329262,338.1967602232395
0.0215257861521235,336.92097389464686,335.2910078622471,338.55093992704656
0.021881029205660894,337.25643160566506,335.6471173336521,338.86574587767797
0.022236146106385003,337.70554775945607,335.9932936789041,339.417801840008
0.0225911369438618,338.0044850585015,336.3335396801688,339.6754304368341
0.0229460018075619,338.27026554543863,336.7021965931311,339.8383344977462
0.023300740786861358,338.5281618037684,336.9598057017408,340.09651790579596
0.023655353971040495,338.9752489649329,337.30111436237235,340.6493835674935
0.024009841449284686,339.3490112452242,337.6963477205144,341.0016747699339
0.02436420331068515,339.56096441498397,337.9337189463535,341.1882098836144
0.024718439644237762,339.9010855729809,338.3048788098925,341.4972923360693
0.02507255053884387,340.20257426476553,338.6188075794916,341.7863409500394
0.02542653608331106,340.55812026305813,338.95985751493293,342.1563830111833
0.025780396366351765,341.0044029464221,339.4014755555282,342.60733033731594
0.026134131476585155,341.3252302406081,339.72746504850596,342.9229954327102
0.02648774150253573,341.6110712381743,339.9859971456386,343.23614533071003
0.02684122653263412,341.9655407820872,340.4362592301823,343.4948223339921
0.027194586655217862,342.23154944194715,340.7407156594888,343.72238322440546
0.027547821958530224,342.62160389180565,341.1511732394877,344.0920345441235
0.027900932530721,342.9307369997672,341.4539400699838,344.40753392955054
0.02825391845984729,343.27431820168886,341.815034556033,344.7336018473447
0.028606779833872328,343.6715566108192,342.20311060658764,345.1400026150507
0.028959516740666255,343.91617124824535,342.4185510674213,345.4137914290694
0.02931212926800692,344.2919302005652,342.8176331307209,345.7662272704095
0.02966461750357848,344.57367989248047,343.15200735422025,345.99535243074075
0.030016981534973262,344.87859263165836,343.315157826886,346.4420274364307
0.03036922144969039,345.1672844302582,343.67750817694423,346.6570606835721
0.030721337335136566,345.4683080475953,344.02528837682564,346.91132771836504
0.031073329278626823,345.8843162804001,344.44887221075857,347.3197603500417
0.03142519736738339,346.2067062230074,344.73062626448115,347.6827861815337
0.031776941688536446,346.4433916035201,344.96362579621933,347.9231574108209
0.032128562329124914,346.7548170986447,345.29400487943605,348.2156293178534
0.03248005937609529,347.1115716484985,345.6167457119636,348.6063975850334
0.03283143291630242,347.4000092702461,345.8824911641045,348.9175273763876
0.03318268303651025,347.72142647173996,346.2426625247922,349.2001904186877
0.03353380982339072,348.1009461995778,346.72871147819984,349.4731809209557
0.033884813363524474,348.3429556138241,346.9373780618463,349.74853316580186
0.034235693743401685,348.76695086925923,347.2446245217774,350.289277216741
0.03458645104942063,349.0085622259115,347.5807644256707,350.43636002615233
0.03493708536788959,349.2236468292851,347.86629925648595,350.58099440208423
0.03528759678502543,349.51689760547134,348.10230502479794,350.93149018614474
0.03563798538695438,349.8954946563497,348.37342970821175,351.4175596044877
0.03598825125971284,350.18189162180715,348.59684994808697,351.76693329552734
0.03633839448924616,350.50944365818236,348.99243995460245,352.0264473617622
0.03668841516140946,350.8174624738858,349.3710252946349,352.2638996531367
0.03703831336196837,351.0447970977503,349.6183335033481,352.47126069215244
0.037388089176597895,351.2924633486562,349.83899501868524,352.74593167862713
0.03773774269088317,351.6247319458575,350.07933076167586,353.1701331300391
0.038087273990320206,352.04404943710836,350.523373645872,353.56472522834474
0.038436683160314566,352.3361782571269,350.7763666980696,353.8959898161842
0.038785970286183157,352.57740009288625,350.98262666281545,354.1721735229571
0.039135135453152885,352.8688343025595,351.28906490693004,354.448603698189
0.03948417874636141,353.0909943742888,351.6006674536265,354.5813212949512
0.03983310025085791,353.3458884221861,351.8239217271394,354.8678551172328
0.04018190005160193,353.68847657979217,352.2404211699415,355.1365319896428
0.04053057823346415,353.9513766527586,352.4214760511877,355.4812772543295
0.04087913488122714,354.2530957570857,352.6578534770681,355.8483380371033
0.041227570079584185,354.536669079429,352.99480809578796,356.07853006307
0.04157588391314011,354.75348726354736,353.30449225465776,356.20248227243695
0.04192407646641198,355.0994976967673,353.64803040934504,356.55096498418953
0.04227214782382797,355.3362706069541,353.6924423284748,356.98009888543345
0.04262009806972811,355.5916693377085,354.0075673996867,357.1757712757303
0.04296792728836509,355.9277414590475,354.42194506710763,357.4335378509874
0.043315635563902846,356.2244959392598,354.75328382954535,357.69570804897415
0.04366322298041841,356.46277369922234,354.94946184057125,357.9760855578735
0.04401068962190051,356.73650029403615,355.18946365372796,358.2835369343444
0.04435803557225038,357.02107666527456,355.44753342296076,358.59461990758837
0.0447052609152825,357.2314459317514,355.67042308322266,358.7924687802802
0.045052365734723404,357.5317993525758,355.97379726374015,359.08980144141134
0.0453993501142125,357.7918073937006,356.2888994717538,359.29471531564735
0.045746214137302774,358.0824416040963,356.5108196521002,359.6540635560923
0.04609295788745969,358.4433137697829,356.83629539745743,360.0503321421084
0.046439581448061894,358.7131459828207,357.18333780251805,360.24295416312333
0.046786084902402,358.9226632302875,357.43300240185215,360.4123240587229
0.04713246833368523,359.2130972544016,357.7501416268659,360.6760528819372
0.047478731825031206,359.4984156123279,358.03570880427196,360.96112242038384
0.04782487545947262,359.72702099135284,358.21912151253696,361.23492047016873
0.04817089931995596,360.02940108867165,358.4897341750355,361.5690680023078
0.048516803489342265,360.3160176667911,358.7312672527487,361.9007680808335
0.048862588050406,360.54463521804985,358.9553302352678,362.13394020083183
0.049208253085835776,360.7950429830803,359.2499366671251,362.34014929903543
0.049553798678235145,361.0330536976852,359.48894548796807,362.5771619074024
0.04989922491012139,361.2079225685122,359.65097811600685,362.76486702101755
0.05024453186392634,361.4355503784962,359.85252315871463,363.0185775982777
0.0505897196219971,361.74921594240794,360.13519964266135,363.3632322421545
0.050934788266594644,361.92965770469374,360.3047151419455,363.55460026744197
0.051279737879895704,362.13568766631687,360.5791338594974,363.69224147313633
0.051624568543991355,362.38654331345595,360.82705566279526,363.94603096411663
0.05196928034088777,362.60137601339574,361.0103941245106,364.1923579022809
0.05231387335250699,362.8377136404866,361.2232091389942,364.45221814197896
0.05265834766068575,363.077571476821,361.4924586174399,364.66268433620206
0.05300270334717626,363.30938910229736,361.7621708901619,364.85660731443284
0.05334694049364692,363.59881412845147,362.05881643492904,365.13881182197395
0.0536910591816812,363.78709232013443,362.2535946774489,365.32058996282
0.05403505949277835,364.01499887952076,362.4415661368621,365.5884316221794
0.05437894150835421,364.3168026232044,362.71125798446917,365.92234726193965
0.05472270530974001,364.5281838673147,362.92878311195636,366.12758462267306
0.05506635097818312,364.7982034755341,363.18506721199714,366.41133973907097
0.05540987859484782,364.99166007593453,363.4374555687504,366.5458645831187
0.05575328824081393,365.22351793739807,363.6651757076767,366.7818601671194
0.056096579997078615,365.3784935469742,363.83467408168934,366.922313012259
0.056439753944555006,365.5514831364808,364.03621844359907,367.0667478293625
0.056782810164072973,365.7555961134434,364.1846246728523,367.3265675540345
0.05712574873637986,366.0652801323161,364.48731472208607,367.6432455425462
0.05746856974213931,366.3062562305367,364.7227190412265,367.8897934198468
0.057811273261932083,366.58643790928653,364.9206935810316,368.2521822375414
0.0581538593762567,366.7154736248562,364.95818683183643,368.4727604178759
0.058496328165528376,366.8878428257899,365.2088664094883,368.5668192420916
0.05883867971007972,367.13461834532296,365.51817103559614,368.75106565504973
0.059180914090161525,367.387210746314,365.6874290329157,369.0869924597123
0.05952303138594133,367.5385461666102,365.86360684210103,369.2134854911194
0.05986503167750531,367.73325357476693,366.01756259345245,369.4489445560814
0.060206915044856826,367.98150087416747,366.2502996931703,369.7127020551646
0.06054868156791724,368.18054262207755,366.58314215924815,369.77794308490695
0.06089033132652663,368.3088517496126,366.64405476504794,369.97364873417723
0.06123186440044262,368.4875992994847,366.71374861081676,370.26144998815266
0.06157328086934116,368.7034448973127,366.94521015342576,370.4616796411996
0.06191458081281725,368.910913195993,367.15722245413997,370.66460393784604
0.062255764310383765,369.1596526162772,367.3734233033669,370.94588192918746
0.06259683144147225,369.2745964991133,367.5006678717882,371.04852512643834
0.06293778228543363,369.4426592196075,367.6863588406979,371.19895959851704
0.06327861692153706,369.74411653841196,367.9794238323604,371.5088092444635
0.06361933542897066,369.8713244105744,368.0473559996378,371.6952928215111
0.06395993788684227,370.0245612927795,368.20311056057614,371.84601202498277
0.0643004243741781,370.21933710019033,368.3297620466695,372.1089121537112
0.06464079496992446,370.4594365828037,368.52845545541066,372.3904177101967
0.06498104975294652,370.6616097039246,368.669439518594,372.65377988925525
0.0653211888020289,370.868758658861,368.98226961200425,372.7552477057177
0.06566121219587653,371.17643784681457,369.1539220197196,373.19895367390956
0.06600112001311344,371.39692990988203,369.3932013039303,373.40065851583375
0.0663409123322835,371.60095827343434,369.6049187236246,373.596997823244
0.06668058923185119,371.7748301624245,369.7517647010475,373.7978956238016
0.0670201507902004,371.90750324124156,369.94042353796294,373.87458294452017
0.06735959708563527,372.02360846459624,370.0793561453175,373.967860783875
0.06769892819638076,372.2802471079564,370.36083817057647,374.19965604533644
0.06803814420058145,372.43974732187695,370.4851737929528,374.3943208508011
0.06837724517630324,372.61745453867536,370.64300014902403,374.5919089283267
0.06871623120153202,372.8430279020243,370.85365215964777,374.8324036444008
0.06905510235417439,372.9709189409573,370.9945384938343,374.9472993880803
0.06939385871205841,373.12746230456463,371.14979409934193,375.1051305097874
0.06973250035293245,373.2886913130642,371.2967440773675,375.2806385487609
0.0700710273544659,373.4151717845247,371.3841243172849,375.44621925176455
0.07040943979424995,373.64519616289164,371.6137292404224,375.6766630853609
0.07074773774979638,373.7560727814599,371.749426552885,375.76271901003486
0.07108592129853838,373.9197516363279,371.75593773347066,376.08356553918503
0.07142399051783122,374.0831524030929,371.98935258807523,376.1769522181106
0.07176194548495085,374.1806192218389,372.09819062772124,376.2630478159566
0.0720997862770958,374.39322061671237,372.1974556108229,376.58898562260185
0.07243751297138575,374.5845211241247,372.4021694355409,376.7668728127085
0.07277512564486224,374.82848181418456,372.6740324888261,376.98293113954304
0.07311262437448944,375.0771854164098,372.9109784050482,377.2433924277714
0.07345000923715303,375.1478973965038,372.9185342332364,377.37726055977123
0.07378728030966085,375.31324074972264,373.10468035622984,377.52180114321544
0.0741244376687437,375.6072067288796,373.34188601195535,377.8725274458039
0.07446148139105416,375.75942097147373,373.51947430468954,377.99936763825787
0.07479841155316735,375.7987452299534,373.51278279801426,378.08470766189254
0.0751352282315816,375.94374610921426,373.648719826277,378.23877239215153
0.0754719315027174,376.1281988900576,373.84990739567604,378.40649038443917
0.07580852144291801,376.2327772130343,373.9550697260488,378.51048470001984
0.0761449981284503,376.24390817497647,373.99367603551735,378.4941403144356
0.07648136163550354,376.3506285071718,374.0767212599143,378.62453575442925
0.07681761204019014,376.65065579321475,374.28787539841346,379.01343618801604
0.07715374941854637,376.8714618274341,374.5605971252837,379.18232652958443
0.07748977384653105,376.9277446966946,374.56656588056154,379.28892351282764
0.07782568540002725,377.1807471613732,374.73408729469855,379.6274070280478
0.07816148415484102,377.29298010882667,374.83293888554283,379.7530213321105
0.07849717018670199,377.6134862935175,375.32108875288424,379.90588383415076
0.07883274357126427,377.7179747407235,375.3090046418132,380.1269448396338
0.07916820438410513,377.96723717028567,375.49712117360866,380.4373531669626
0.07950355270072584,377.91410917439043,375.3910013397577,380.4372170090232
0.07983878859655238,378.1858071833566,375.67815346521246,380.69346090150066
0.08017391214693424,378.3864116899225,375.79797260176804,380.974850778077
0.0805089234271452,378.44837549846307,375.9430753091352,380.95367568779096
0.08084382251238403,378.6995257771925,376.2428754141742,381.15617614021085
0.08117860947777317,378.8666348940999,376.38402560343997,381.34924418475987
0.08151328439836039,378.99035364073643,376.50479933684267,381.47590794463025
0.08184784734911758,379.0034815095941,376.54044986086967,381.4665131583185
0.08218229840494143,379.2649743512071,376.88317587239897,381.64677283001527
0.08251663764065403,379.42351269622,376.9383337429922,381.90869164944775
0.08285086513100193,379.3897096535575,376.91515102684224,381.8642682802727
0.08318498095065668,379.4226637231083,376.96984547489376,381.8754819713228
0.08351898517421569,379.731302218217,377.19637529797274,382.2662291384613
0.08385287787620098,379.7747605922463,377.26849048312636,382.28103070136626
0.08418665913105998,379.8919958814037,377.4469348954129,382.3370568673945
0.08452032901316618,380.1364973372302,377.6083792922495,382.66461538221085
0.08485388759681786,380.12644713483985,377.66171706889355,382.59117720078615
0.0851873349562398,380.26432793273005,377.8262924199616,382.70236344549846
0.08552067116558189,380.5428031902098,377.93619124121255,383.14941513920706
0.08585389629891994,380.5005877526184,378.1012777590669,382.89989774616987
0.08618701043025635,380.7117074562132,378.28575457788594,383.1376603345405
0.08652001363351894,380.8161690763131,378.27141234759443,383.3609258050318
0.08685290598256173,380.9776557545542,378.50454712371123,383.45076438539706
0.08718568755116561,381.1762570004693,378.66252532455394,383.68998867638464
0.08751835841303722,381.2803960426167,378.85950606693854,383.7012860182948
0.08785091864180969,381.3978705094805,378.9616407920015,383.8341002269596
0.08818336831104329,381.4897219091797,379.00742958933864,383.9720142290208
0.08851570749422413,381.5679161105207,379.08290686582546,384.0529253552159
0.08884793626476593,381.721788755456,379.2164453949448,384.2271321159671
0.08918005469600865,381.8654636878096,379.3251755965001,384.4057517791191
0.08951206286121914,382.07351755996285,379.56360782658544,384.58342729334026
0.08984396083359199,382.22091308525347,379.74600369929084,384.6958224712161
0.09017574868624827,382.32499926519296,379.78910353980837,384.8608949905776
0.09050742649223632,382.4784768543964,379.8357621951842,385.1211915136086
0.09083899432453241,382.6124863261987,379.8852706195805,385.33970203281683
0.09117045225603965,382.75645761764406,380.0604168353837,385.4524983999044
0.09150180035958866,382.85014064337867,380.2452664181461,385.4550148686113
0.09183303870793832,382.9781685112463,380.40827049847627,385.5480665240163
0.09216416737377463,383.15871381996504,380.60660684227565,385.71082079765443
0.09249518642971137,383.2742349461306,380.7462728988003,385.8021969934609
0.09282609594829087,383.46313728011364,380.9427456103855,385.98352894984185
0.09315689600198265,383.6956903254931,381.15593759615194,386.2354430548342
0.09348758666318517,383.7496642068374,381.2354905134394,386.2638379002354
0.09381816800422443,383.7414899648186,381.1288523297957,386.3541275998415
0.09414864009735478,383.891064663681,381.1240410044025,386.6580883229595
0.09447900301475952,384.01996693151267,381.2400833986472,386.79985046437815
0.09480925682854988,384.10604328546964,381.3967146892157,386.8153718817236
0.0951394016107656,384.160501506578,381.430541716427,386.8904612967289
0.09546943743337576,384.2721598985689,381.61510705929504,386.92921273784265
0.09579936436827756,384.3754689121096,381.74480639836395,387.0061314258553
0.0961291824872971,384.5273554549313,381.9084158735318,387.14629503633074
0.09645889186219,384.69713769752053,382.0656892779213,387.3285861171197
0.09678849256464035,384.8055838122857,382.13218518836493,387.4789824362065
0.09711798466626137,384.9046763626802,382.2849188981788,387.5244338271816
0.09744736823859612,385.00620427173675,382.3672585410312,387.6451500024423
0.0977766433531162,385.067422690387,382.3981608712456,387.7366845095284
0.09810581008122339,385.21379173286203,382.47672174888174,387.95086171684227
0.09843486849424844,385.27442312820153,382.52748668896504,388.021359567438
0.09876381866345167,385.3344552912771,382.6103553086219,388.0585552739323
0.0990926606600237,385.4905436874957,382.7137766297517,388.2673107452396
0.09942139455508438,385.6125131989922,382.8276669873368,388.39735941064754
0.0997500204196834,385.72650564497667,382.93147356752286,388.5215377224304
0.10007853832480103,385.82094294998296,383.01575370318136,388.6261321967845
0.10040694834134704,385.95426285236596,383.1301468189074,388.77837888582457
0.10073525054016134,386.10200750790744,383.25433975482815,388.9496752609867
0.10106344499201468,386.15784955718783,383.3248312623179,388.99086785205776
0.10139153176760739,386.2478463123125,383.44158497866766,389.0541076459574
0.10171951093757099,386.34453325824495,383.5505931128579,389.1384734036321
0.10204738257246697,386.53110548661476,383.6410234748492,389.42118749838033
0.1023751467427874,386.6996599714364,383.7284265531473,389.6708933897255
0.10270280351895568,386.8580056970492,383.89614828827337,389.81986310582505
0.1030303529713254,387.0562562822909,384.09642933962726,390.0160832249545
0.10335779517018104,387.0673316275085,384.1627466450629,389.9719166099542
0.10368513018573866,387.0968990285558,384.1821465168507,390.01165154026097
0.10401235808814481,387.25042260408117,384.11967310695195,390.3811721012103
0.10433947894747718,387.2732604539136,384.24108090178845,390.30544000603874
0.1046664928337453,387.34632028807255,384.45088689320625,390.24175368293885
0.10499339981688925,387.23418863434875,384.47185388542243,389.9965233832751
0.10532019996678137,387.3839904727357,384.6231099886866,390.1448709567848
0.10564689335322487,387.66959498487904,384.7893710212364,390.5498189485217
0.10597348004595461,387.8766783664836,384.97408661316626,390.77927011980097
0.10629996011463773,387.86390376588554,385.12401454912487,390.60379298264627
0.10662633362887255,388.05384677074903,385.20686915415297,390.9008243873451
0.10695260065818932,388.1786789997204,385.20786316747126,391.14949483196943
0.10727876127205076,388.22672451443185,385.1631856408736,391.29026338799014
0.10760481553985111,388.2943610236651,385.15679461126405,391.43192743606613
0.10793076353091677,388.3769909114439,385.1609216638603,391.5930601590275
0.10825660531450691,388.5773050412099,385.45121149230494,391.7033985901149
0.10858234095981227,388.5516242946679,385.5777351241598,391.525513465176
0.10890797053595677,388.4752418301226,385.59836437175824,391.3521192884871
0.10923349411199626,388.62806579208484,385.53097588190343,391.7251557022663
0.10955891175691912,389.0458161381987,385.86605715283713,392.2255751235602
0.10988422353964705,389.0059793033466,385.8697559083867,392.14220269830645
0.11020942952903388,388.8357534017312,385.95140063323197,391.7201061702305
0.11053452979386631,389.05625960885476,386.09810243704675,392.0144167806627
0.11085952440286456,389.3913889754545,386.1920992143745,392.5906787365345
0.11118441342468126,389.4075759547518,386.36891425333187,392.44623765617166
0.11150919692790216,389.1847166655913,386.2656494914626,392.10378383971994
0.11183387498104683,389.4279286165235,386.35820026867356,392.49765696437345
0.11215844765256748,389.73639246028176,386.47162772721026,393.0011571933533
0.1124829150108497,389.8447964432799,386.63056549637474,393.05902739018507
0.11280727712421315,389.9499556540794,386.7755869240138,393.12432438414504
0.11313153406091021,389.75124885154645,386.6348007215003,392.8676969815926
0.11345568588912772,390.08621307596775,386.8790265961834,393.29339955575216
0.1137797326769856,390.1136920461951,386.7094668877118,393.5179172046784
0.11410367449253757,389.77972008633327,386.733511896714,392.82592827595255
0.11442751140377186,389.87879169192473,386.8454838142719,392.9120995695776
0.11475124347861004,390.1731059124847,386.8806474762586,393.46556434871076
0.11507487078490777,390.1140487584482,386.93898270118484,393.2891148157115
0.11539839339045543,390.0406359107531,387.011449466075,393.0698223554312
0.11572181136297703,390.24623365543493,387.2665128377369,393.225954473133
0.11604512477013088,390.2515651072334,387.2805876110945,393.2225426033723
0.11636833367951031,390.3019197058417,387.3537817801226,393.2500576315609
0.11669143815864251,390.3714200961218,387.43806508594855,393.30477510629515
0.11701443827498925,390.4908393852569,387.49723402064484,393.4844447498689
0.11733733409594756,390.765645539185,387.52047933148555,394.01081174688443
0.11766012568884837,390.9350914200167,387.54897489405437,394.321207945979
0.11798281312095825,390.63607088862665,387.50683167814645,393.7653100991068
0.11830539645947807,390.7631779171509,387.69186104208933,393.83449479221247
0.11862787577154373,391.2015050467414,387.851815729235,394.55119436424775
0.1189502511242267,391.54439681230133,387.93136941805136,395.15742420655124
0.1192725225845329,391.49573404072,388.08610962317397,394.905358458266
0.11959469021940426,391.1521707973388,387.97103527630975,394.3333063183678
0.1199167540957174,391.35053426122334,388.13222011254845,394.56884840989824
0.1202387142802846,391.83203122586224,388.3520316566855,395.31203079503905
0.12056057083985337,392.0133034133164,388.5916220555668,395.43498477106607
0.12088232384110743,391.602742481543,388.43375847445446,394.7717264886315
0.12120397335066535,391.70191438484056,388.3694175719419,395.03441119773925
0.12152551943508222,392.1324356647832,388.46729892755303,395.7975724020134
0.12184696216084838,392.1176655185179,388.6360474716924,395.59928356534346
0.12216830159439003,392.0483055124926,388.70173161851574,395.39487940646944
0.12248953780206998,391.9522845421009,388.6967385325554,395.2078305516464
0.1228106708501865,392.3137214188354,388.8848619015012,395.74258093616965
0.12313170080497403,392.57875893651294,389.01253391395403,396.14498395907185
0.12345262773260379,392.46581281482565,388.9800947768507,395.95153085280054
0.12377345169918277,392.3082468586053,388.94646557287865,395.670028144332
0.12409417277075434,392.4348391948665,388.9502296625036,395.9194487272294
0.12441479101329889,392.6713786272315,388.94092585360363,396.4018314008594
0.12473530649273265,392.6633709147238,389.15659348609006,396.17014834335765
0.12505571927490922,392.5978548542461,389.2217366665642,395.97397304192805
0.12537602942561837,392.72358019351924,389.2856678896567,396.1614924973818
0.12569623701058666,392.6926740142225,388.9824403493584,396.40290767908664
0.1260163420954781,392.7707895821215,389.0242802414627,396.5172989227803
0.12633634474589306,392.6667811220194,389.1343345917818,396.19922765225704
0.12665624502736905,392.6407779498403,389.22962073982836,396.0519351598522
0.12697604300538115,392.94063088202574,389.23089663711016,396.6503651269413
0.12729573874534117,393.0766207123156,389.2759043238801,396.8773371007511
0.12761533231259817,393.00000592854013,389.384779633187,396.6152322238933
0.12793482377243912,392.9771826176036,389.4501259226337,396.50423931257353
0.1282542131900877,393.3060615893104,389.61657713468975,396.995546043931
0.1285735006307059,393.31884565816944,389.4220589247351,397.21563239160383
0.1288926861593927,393.1514684265518,389.36613019087656,396.936806662227
0.12921176984118476,392.977246922814,389.34789792562225,396.6065959200058
0.12953075174105713,393.32213559222015,389.52033448047496,397.1239367039653
0.12984963192392207,393.71373920819696,389.60913664870804,397.81834176768587
0.1301684104546298,393.76674156001025,389.7030999947566,397.83038312526384
0.13048708739796908,393.6648535208296,389.77536445753776,397.5543425841214
0.1308056628186662,393.40014707881244,389.4990950732382,397.3011990843866
0.13112413678138563,393.663847491736,389.52689106740814,397.8008039160639
0.1314425093507306,393.8114850266583,389.6093914550332,398.0135785982834
0.13176078059124194,393.72599009466865,389.7588414987054,397.6931386906318
0.13207895056739963,393.3515568594914,389.6249014901397,397.07821222884303
0.1323970193436215,393.40073527614146,389.61115593669047,397.1903146155924
0.132714986984264,393.60001616295426,389.5143285365808,397.68570378932776
0.13303285355362274,393.58550830368745,389.61591546740544,397.5551011399695
0.1333506191159315,393.7787774308314,389.94561618956106,397.6119386721017
0.13366828373536274,393.9266580898161,390.0706274356657,397.78268874396656
0.13398584747602854,394.11386911320756,390.08201780830376,398.14572041811135
0.1343033104019792,394.1574086924349,390.1750115458912,398.1398058389786
0.13462067257720411,394.0457699797071,390.1977378379569,397.8938021214573
0.13493793406563226,393.87898954139416,390.0629661196753,397.695012963113
0.1352550949311311,393.96959085869156,389.88173149395163,398.0574502234315
0.13557215523750815,394.19520273437973,389.99802104131106,398.3923844274484
0.13588911504850953,394.0011119343827,389.83890770139715,398.16331616736824
0.13620597442782093,393.9722281667065,389.7724876374076,398.1719686960053
0.13652273343906796,393.99852692146357,389.63053427107417,398.3665195718529
0.1368393921458153,394.0896181745505,389.4693624019022,398.7098739471988
0.13715595061156727,394.03645471225957,389.3527401807242,398.72016924379494
0.1374724088997684,393.9101953321954,389.2709860172951,398.5494046470957
0.13778876707380244,393.91535885587575,389.17267452991143,398.65804318184007
0.1381050251969931,394.0120777552578,388.9733447554511,399.05081075506456
0.13842118333260453,394.1145801533959,388.9607713313226,399.2683889754692
0.13873724154384012,393.9858242755935,388.8809042203628,399.0907443308241
0.13905319989384415,393.8802667980943,388.85075789676733,398.9097756994212
0.13936905844570047,394.01431583964705,388.63927807788275,399.3893536014113
0.13968481726243334,393.8462386559931,388.3990623013077,399.2934150106785
0.14000047640700725,393.73788888899446,388.3346236147242,399.14115416326473
0.14031603594232753,393.52039882926096,388.27518045292834,398.7656172055935
0.14063149593123928,393.5052654048623,388.1165191559764,398.89401165374824
0.14094685643652888,393.4189100322944,387.8733458186895,398.9644742458992
0.1412621175209228,393.2710594888733,387.68289921583374,398.85921976191287
0.14157727924708816,393.0286200286534,387.5524547375615,398.5047853197453
0.14189234167763343,392.88485186526526,387.3162069456667,398.45349678486383
0.14220730487510733,392.8711095621618,387.0831302081182,398.6590889162054
0.14252216890199956,392.90734718145865,386.8742170899531,398.94047727296413
0.1428369338207413,392.7451933870528,386.76444101122036,398.7259457628852
0.1431515996937043,392.61177717359334,386.55755095994107,398.6660033872456
0.1434661665832014,392.60448441059214,386.28201429824793,398.92695452293634
0.14378063455148726,392.5913138903581,386.00220263761145,399.18042514310474
0.14409500366075703,392.3120522050348,385.6955619648955,398.928542445174
0.144409273973148,391.94956386077774,385.41845173055003,398.4806759910054
0.14472344555073832,392.3243453097251,385.3502165693201,399.2984740501301
0.14503751845554766,392.3159283959167,385.054721197914,399.5771355939195
0.14535149274953782,392.04743655166186,384.70790811502485,399.38696498829887
0.14566536849461173,391.71490189849106,384.41740431427286,399.01239948270927
0.14597914575261398,391.46471742954986,384.23803333398587,398.6914015251139
0.14629282458533158,391.536579004863,384.00764510470697,399.065512905019
0.14660640505449288,391.4434295645595,383.79931040223425,399.08754872688473
0.14691988722176808,391.292408387509,383.6229960702058,398.96182070481217
0.14723327114877002,390.9621182332837,383.3247705461556,398.59946592041183
0.1475465568970529,390.8369792634669,383.0005514189954,398.67340710793843
0.14785974452811385,390.98438280969145,382.7611937544836,399.2075718648993
0.14817283410339158,390.87604297366033,382.5454564844588,399.20662946286194
0.14848582568426721,390.5074500643517,382.2059218569072,398.80897827179615
0.14879871933206476,390.1264085721255,381.86187481756343,398.39094232668765
0.14911151510805012,389.97405359586617,381.54793596765,398.4001712240823
0.1494242130734318,390.0556474344994,381.30950309073046,398.8017917782683
0.14973681328936136,393.44820044552995,387.48605777409136,399.4103431169686
0.15004931581693254,393.3178957208966,387.41675398320314,399.21903745859004
0.15036172071718176,392.87258733226423,387.20259188763424,398.5425827768943
0.1506740280510889,392.70257102983146,386.8944663183292,398.5106757413338
0.15098623787957588,392.5850849436185,386.5060314064298,398.6641384808071
0.1512983502635084,395.70336594765894,393.0542935411388,398.35243835417907
0.15161036526369462,395.7386372526587,393.8030361753643,397.67423832995314
0.15192228294088575,395.0447815103121,392.3398779112578,397.7496851093664
0.15223410335577678,395.32957178816434,392.6129962412492,398.04614733507947
0.15254582656900534,395.5162363404061,392.5399022373787,398.4925704434335
0.15285745264115236,395.1804622862491,392.221712845952,398.1392117265462
0.15316898163274278,394.63928864453754,391.7060465972014,397.5725306918736
0.15348041360424441,394.32740502384667,391.3345554505366,397.3202545971567
0.15379174861606854,394.0705837531086,390.9374334141536,397.2037340920636
0.15410298672857062,394.1442709752616,390.84908057443033,397.4394613760928
0.15441412800204904,394.21222346839687,391.11931648332694,397.30513045346686
0.15472517249674672,394.14799611299713,391.3831033418908,396.91288888410355
0.1550361202728497,393.6019892630063,391.7244533340843,395.47952519192836
0.15534697139048798,393.7095082148878,391.0534061405483,396.3656102892273
0.15565772590973606,393.73864583795387,390.88934850135723,396.5879431745505
0.15596838389061185,393.8128372077668,391.1755672683274,396.45010714720615
0.1562789453930774,392.57671422205857,389.194228963755,395.9591994803622
0.15658941047703942,391.87975807149775,388.36742001259466,395.3920961304008
0.1568997792023483,392.35689390105046,389.1390729020983,395.5747149000026
0.15721005162879872,392.69774659830887,389.91691797398636,395.4785752226314
0.15752022781613031,391.3749735483503,387.4555329594629,395.29441413723765
0.1578303078240263,391.41161385329883,388.50856876396193,394.31465894263573
0.15814029171211524,390.9312896199411,388.6827525402497,393.1798266996325