File: RHTT AVG/RHTT_L_DRY_Ex_avg_true_stress_strain.csv
True Strain,True Stress (MPa),Lower Bound (MPa),Upper Bound (MPa)
-0.00023534769209566,2.2648377462688334,2.2648377462688334,2.2648377462688334
-7.048100224597744e-05,-0.33883152466557553,-0.37328971273919226,-0.30437333659195875
9.43585110587286e-05,5.888923860740477,-2.265080481686206,14.04292820316716
0.0002591708567764074,11.585260990218325,-3.00783483211194,26.17835681254859
0.00042395604386080184,29.383594463063304,4.888799550523254,53.878389375603355
0.0005887140812611182,50.736043533131266,36.59653714403007,64.87554992223247
0.0007534449779221401,60.829032529426755,52.94801787823781,68.7100471806157
0.0009181487427844533,70.73121212928761,63.20949619570688,78.25292806286835
0.0010828253847835613,90.63283228628045,79.68524579669727,101.58041877586362
0.001247474912851219,100.93819362312463,91.31800092065698,110.55838632559228
0.0014120973359145487,115.35613221783645,108.34641970041623,122.36584473525664
0.0015766926628962648,133.97521342644333,128.36549898526292,139.58492786762375
0.0017412609027148975,145.02840213958308,140.02046736713817,150.036336912028
0.0019058020642839105,155.22637766366032,143.8150594905605,166.63769583676017
0.0020703161565130326,167.5209908968942,157.04941549280792,177.9925663009805
0.002234803188307374,188.9477838333625,184.50799509003818,193.38757257668684
0.0023992631685676533,196.76453438451227,191.84982244943401,201.6792463195905
0.002563696106190417,206.3486220111643,198.88077637404902,213.8164676482796
0.0027281020100671616,218.75261295710897,207.40862144070624,230.09660447351166
0.002892480889085662,233.91798656359825,225.33268088037522,242.50329224682127
0.0030568327521290897,243.2121971255997,236.5960533035099,249.82834094768947
0.0032211576080762375,254.64433909941843,247.2495176704446,262.0391605283923
0.003385455465801743,268.55081239039873,259.2102634076162,277.89136137318127
0.0035497263341752057,275.3793509175725,267.3831786091972,283.37552322594775
0.0037139702220625194,284.2332910689808,275.6126013650467,292.8539807729149
0.003878187138324989,293.92659846037816,284.8460361508315,303.0071607699248
0.0040423770918195535,301.77227728591726,297.1457474862433,306.3988070855913
0.004206540091399012,307.84150252279835,304.79120380832063,310.89180123727607
0.004370676145911142,315.4863329426322,311.36772353989124,319.60494234537316
0.004534785264200025,320.77858966746703,318.7059116038687,322.8512677310654
0.004698867455105172,324.81868882727974,321.56134235152496,328.07603530303453
0.004862922727461741,328.1002020262192,324.4236870287406,331.77671702369787
0.005026951090100763,330.5606517984966,327.0051541341734,334.11614946281986
0.005190952551848263,333.0127775002274,329.71587510989735,336.3096798905574
0.005354927121526586,334.99786046764467,332.4608074924613,337.53491344282804
0.0055188748079535175,336.30004443021755,333.36630838571534,339.2337804747197
0.005682795619942505,337.7195565590825,334.52768347683013,340.9114296413348
0.005846689566302887,338.5849479844561,335.39327823589656,341.77661773301566
0.006010556655839005,339.52305252483023,336.19280691246786,342.85329813719267
0.006174396897351537,340.25458304477877,336.93887346485917,343.57029262469837
0.006338210299636616,340.87381389224805,337.76858432358165,343.9790434609144
0.006501996871486052,341.48429775918805,338.47621807166826,344.4923774467078
0.006665756621687556,342.1377297978781,339.3675322859369,344.9079273098193
0.006829489559023861,342.5013308348054,339.8425118541082,345.1601498155026
0.00699319569227405,343.25162815312086,340.1673740685578,346.3358822376839
0.007156875030212672,343.8078293902858,340.9270087880289,346.6886499925427
0.00732052758160997,344.36470050547706,341.2012878483087,347.52811316264535
0.0074841533552321,344.64737892414973,341.52900788641267,347.7657499618868
0.007647752359840257,345.130992631988,341.96684384886936,348.2951414151067
0.007811324604191998,345.55071807555584,342.3872452447565,348.71419090635516
0.00797487009704036,345.94688919128794,342.6880011069501,349.20577727562574
0.008138388847134088,346.2965037800057,343.0470412187207,349.54596634129075
0.008301880863217858,346.6250083689964,343.3819935268884,349.8680232111044
0.00846534615403139,346.92267564826466,343.75702360642583,350.0883276901035
0.00862878472831079,347.34112626905954,344.16585147384774,350.51640106427135
0.008792196594787654,347.6300656110282,344.35669562756266,350.90343559449377
0.008955581762189298,347.95027398226193,344.58336730906916,351.3171806554547
0.009118940239238984,348.2800496358364,344.9536708643022,351.6064284073707
0.009282272034655037,348.7234620258342,345.4251482166569,352.02177583501145
0.009445577157152172,349.00803642995186,345.84743226765823,352.1686405922454
0.009608855615440616,349.28928375071405,346.08306480327224,352.4955026981559
0.00977210741822633,349.5554511937413,346.2830047820696,352.827897605413
0.00993533257421123,349.9414355885391,346.5705408881829,353.3123302888953
0.010098531092092314,350.2316082727015,346.8390178694885,353.6241986759145
0.01026170298056298,350.49301361875825,347.10633142481913,353.8796958126973
0.010424848248312153,350.75717968955126,347.3600537136119,354.15430566549065
0.010587966904024507,350.91906524495727,347.51151614240433,354.3266143475102
0.010751058956380682,351.18421668768565,347.8148460908944,354.5535872844769
0.010914124414056418,351.5570814204782,348.2255476928705,354.8886151480859
0.01107716328572387,351.7732387936451,348.5840378343717,354.9624397529185
0.011240175580050726,351.8691719874244,348.8015726814147,354.9367712934341
0.011403161305700444,352.46635206766945,348.88203579218185,356.050668343157
0.01156612047133246,352.7799863814698,349.0666259597516,356.49334680318805
0.011729053085601323,352.73059544903106,349.6136234317091,355.84756746635304
0.011891959157158006,353.15513698052825,350.028608689222,356.28166527183447
0.012054838694649043,353.33401502176235,350.16110084662137,356.5069291969033
0.012217691706716736,353.5984832403362,350.3321671973777,356.86479928329464
0.012380518201999388,353.9610353666374,350.58317947566854,357.33889125760635
0.012543318189130426,354.18251253065046,350.76828001149875,357.59674504980217
0.012706091676739719,354.3522544030981,350.9080942728114,357.7964145333848
0.012868838673452699,354.60929957818774,351.1383771416098,358.08022201476575
0.013031559187890592,354.8716208164064,351.4135643063464,358.32967732646637
0.013194253228670634,355.1867713164201,351.7245901601212,358.64895247271903
0.013356920804405198,355.4148099145761,352.07972227154727,358.7498975576049
0.013519561923703115,355.8094019906323,352.486685130836,359.1321188504285
0.01368217659516879,355.95627439418274,352.7118265368574,359.20072225150807
0.013844764827402439,356.23482626815036,352.865891727156,359.6037608091447
0.014007326629000299,356.4340229748664,352.98765109674645,359.8803948529864
0.014169862008553757,356.69109053692705,353.13679726333373,360.2453838105204
0.014332370974650671,356.91420045078394,353.3430914527068,360.48530944886113
0.014494853535874494,357.1316574277672,353.54264705649166,360.72066779904276
0.014657309700804495,357.33377572447074,353.7925583638761,360.87499308506546
0.01481973947801598,357.56461075879463,354.06962082558334,361.05960069200586
0.014982142876079423,357.77557632808765,354.27923648979646,361.27191616637884
0.015144519903561778,358.169011664693,354.84391215580695,361.4941111735791
0.015306870569025606,358.4297275725142,355.051967155235,361.80748798979334
0.015469194881029302,358.6730840621983,355.233859876645,362.1123082477516
0.01563149284812731,358.85867317768515,355.40588322826386,362.3114631271065
0.015793764478869255,359.0539487423609,355.5708120507144,362.53708543400745
0.015956009781801252,359.2195419391188,355.6968726567928,362.74221122144485
0.01611822876546505,359.38953217617956,355.7911755051867,362.98788884717237
0.016280421438398227,359.6465405208748,356.05010065514404,363.2429803866056
0.016442587809134435,359.9053081966078,356.3133963996083,363.49721999360725
0.01660472788620252,360.16730685013243,356.5456683111866,363.78894538907826
0.01676684167812783,360.3772044033219,356.73165991606385,364.02274889058
0.016928929193431353,360.61252522783457,357.1055103027533,364.1195401529158
0.017090990440629932,360.80068632021033,357.31896212932764,364.282410511093
0.01725302542823649,360.9782745526979,357.4337680293801,364.5227810760157
0.017415034164759157,361.20095438099867,357.6585752287633,364.74333353323397
0.017577016658702586,361.44490325693477,357.84501459741807,365.0447919164515
0.017738972918567075,361.59383895576457,358.0566144891218,365.13106342240735
0.017900902952848796,361.81503553239713,358.240671931596,365.38939913319825
0.018062806770040008,362.13190714944403,358.48695692098676,365.77685737790136
0.018224684378628196,362.3756018962798,358.72854878620836,366.0226550063513
0.01838653578709738,362.5835620625003,358.96093238190264,366.2061917430979
0.018548361003927233,362.78523380333655,359.17435913052697,366.39610847614614
0.018710160037593324,363.1361936536305,359.61664218880424,366.6557451184568
0.01887193289656732,363.3336353512259,359.7581630243473,366.90910767810453
0.01903367958931613,363.51627214153893,359.85522374981775,367.1773205332601
0.019195400124303194,363.69025841937787,359.95001352829934,367.43050331045634
0.019357094509987648,363.8326995005154,360.11254484588613,367.5528541551447
0.019518762754824507,364.0706834766847,360.35077066033654,367.7905962930329
0.01968040486726492,364.3024345804596,360.5565012626495,368.0483678982697
0.019842020855755274,364.5134690530899,360.7767928403996,368.2501452657803
0.02000361072873852,364.8051277842811,361.14032102008133,368.46993454848086
0.020165174494653295,365.0268182147664,361.36713134954,368.6865050799928
0.02032671216193415,365.2913010822404,361.5655466444433,369.0170555200375
0.020488223739011765,365.53058753073407,361.7696977794816,369.29147728198654
0.020649709234312086,365.6963606399381,361.93970237299266,369.45301890688364
0.020811168656257626,365.90602110223335,362.1664594559457,369.64558274852095
0.020972602013266606,366.17239791716156,362.37174644508934,369.97304938923384
0.021134009313753165,366.33039807752357,362.52744045198483,370.13335570306236
0.021295390566127587,366.49295019689424,362.68018714594854,370.30571324783995
0.02145674577879544,366.6976206749102,362.8986046545509,370.4966366952694
0.02161807496015887,367.01466605712966,363.24948353285606,370.77984858140326
0.021779378118615737,367.292430234867,363.4716536923831,371.1132067773509
0.021940655262559842,367.41797067093563,363.6038164975212,371.23212484435004
0.022101906400381142,367.4064047444227,363.69982601452125,371.11298347432415
0.022263131540464887,367.6362736221034,363.83876439576585,371.4337828484409
0.022424330691192915,367.89137870561285,363.97452091782316,371.8082364934026
0.022585503860942803,368.072569216676,364.1083882974586,372.0367501358935
0.022746651058088076,368.2841802181701,364.3377321482144,372.23062828812584
0.022907772290998427,368.55774310501533,364.59601130397834,372.5194749060523
0.02306886756803885,368.8282446075955,364.84940395289914,372.8070852622919
0.023229936897570955,369.06870150031887,365.0344392926922,373.10296370794555
0.023390980287952088,369.19934712559916,365.2468062417858,373.1518880094126
0.023551997747535563,369.35915388515104,365.437089492469,373.2812182778331
0.023712989284670874,369.5915730428651,365.6152340938404,373.5679119918898
0.023873954907702836,369.7876625164544,365.8706505519554,373.7046744809535
0.024034894624972884,369.88961697705827,366.01031099405594,373.7689229600606
0.0241958084448182,370.05076450982705,366.1538829679034,373.94764605175067
0.02435669637557196,370.2470614008472,366.2907303765511,374.20339242514336
0.024517558425563517,370.43024148416066,366.4548216472852,374.4056613210361
0.02467839460311757,370.57932266689664,366.63604046993566,374.5226048638577
0.02483920491655544,370.75078246126543,366.77218791543055,374.7293770071003
0.024999989374194228,371.01676028702644,366.93498160402936,375.0985389700235
0.025160747984347014,371.25562365301823,367.0982085302179,375.4130387758186
0.025321480755323096,371.39462436189973,367.24353054885404,375.54571817494536
0.025482187695427105,371.4980325116913,367.45198850322595,375.5440765201567
0.02564286881296033,371.6380671077833,367.6370986567152,375.63903555885145
0.02580352411621983,371.81950725339397,367.79351295387323,375.84550155291464
0.02596415361349868,372.0288664119317,368.10108515725625,375.9566476666072
0.026124757313086167,372.2096990596679,368.4018064634066,376.01759165592915
0.02628533522326693,372.2943244820189,368.431161143197,376.1574878208408
0.02644588735232228,372.46554311693313,368.47286548298536,376.4582207508809
0.026606413708529317,372.5771225511653,368.56865999027536,376.5855851120552
0.026766914300161156,372.7499614359481,368.7364745577725,376.7634483141237
0.026927389135487145,372.945856729551,368.88172069840556,377.0099927606964
0.027087838222771998,373.10820519638236,369.00262893977197,377.2137814529927
0.027248261570277113,373.2397784567662,369.13054575574205,377.3490111577904
0.027408659186259687,373.44910336628584,369.3559760751778,377.5422306573938
0.02756903107897294,373.49055600284635,369.63010881137245,377.35100319432024
0.027729377256666347,373.62339642748015,369.761102083563,377.4856907713973
0.027889697727584768,373.964858803675,369.8526632590956,378.07705434825436
0.02804999249996974,374.06832049051985,370.0034996707421,378.1331413102976
0.02821026158205862,374.22606993778754,370.18870635864886,378.26343351692617
0.028370504982084814,374.4818356337975,370.3958665636809,378.5678047039141
0.02853072270827798,374.4823805018344,370.47602942126474,378.4887315824041
0.028690914768863172,374.66489787940935,370.58178811751236,378.7480076413063
0.028851081172062146,374.82175862477106,370.6777673674419,378.9657498821003
0.029011221926092488,375.06355724507546,370.86517446520537,379.26194002494555
0.029171337039167834,375.32827632499175,371.13328695756155,379.52326569242194
0.029331426519498095,375.5940399717659,371.38536557909924,379.8027143644325
0.02949149037528859,375.73947465460907,371.49478180000176,379.9841675092164
0.029651528614741355,375.6815807125278,371.54264529932385,379.82051612573173
0.029811541246054257,375.7084720465072,371.63720869596597,379.77973539704846
0.02997152827742124,375.9425680312361,371.87272511600776,380.01241094646434
0.030131489717032528,376.19731129271213,372.104676840615,380.2899457448092
0.030291425573073766,376.560457921993,372.2936983831848,380.82721746080125
0.030451335853727324,376.296099223869,372.34868404971047,380.2435143980276
0.03061122056717143,376.29553346056593,372.4308750655274,380.1601918556045
0.030771079721580386,376.5764216295755,372.57540699212797,380.5774362670231
0.030930913325124796,376.88150985108626,372.80645655373365,380.9565631484388
0.031090721385970695,377.02782429346195,373.0197117168488,381.03593687007503
0.031250503912280854,377.3065496223195,373.15953289812916,381.45356634650983
0.03141026091221391,377.53312010834975,373.2901386762625,381.7761015404371
0.0315699923939246,377.7332075994824,373.45554867800655,382.01086652095825
0.03172969836556396,377.76841813187866,373.54510061538156,381.99173564837577
0.03188937883527849,377.67597879569473,373.6197117817087,381.73224580968076
0.032049033811211415,378.0801230203065,373.8232997934642,382.3369462471487
0.03220866330150186,378.2907011078901,373.9302432962693,382.6511589195108
0.03236826731428503,378.4196214718889,374.10542619994175,382.73381674383603
0.032527845857692486,378.172563596538,374.26693551419044,382.0781916788855
0.032687398939851224,378.4580558630642,374.3843679130383,382.5317438130901
0.03284692656888501,378.5155960234581,374.59841410474843,382.4327779421678
0.03300642875291349,378.9002384944999,374.89718312843854,382.9032938605612
0.03316590550005245,379.2163814192654,375.0726432593855,383.3601195791454
0.033325356818414,379.2672940666351,375.0880332467328,383.44655488653746
0.0334847827161057,379.38953090997643,375.12496539385165,383.6540964261012
0.03364418320123192,379.34298792924284,375.1395269492671,383.5464489092186
0.03380355828189291,379.34178004357426,375.15862132559204,383.52493876155654
0.03396290796618506,379.4970169810979,375.3738706559303,383.6201633062654
0.0341222322622011,379.76428074837077,375.69403000564824,383.83453149109323
0.034281531178029255,379.983752760264,375.9160470907925,384.0514584297354
0.034440804721754516,380.136842766616,376.05636243298204,384.2173231002499
0.03460005290145781,380.2465419894114,375.9770925603683,384.5159914184545
0.0347592757252162,380.2494861531472,376.15030750241505,384.3486648038793
0.034918473201103105,380.53456979137815,376.36400336328956,384.70513621946674
0.03507764533718745,380.7741339649783,376.5199937031499,385.0282742268068
0.03523679214153494,380.8920134758593,376.70660258496235,385.0774243667562
0.035395913622207224,380.97747611660776,376.8122274249367,385.1427248082788
0.0355550097872621,381.1885502527432,376.91880943332734,385.4582910721591
0.03571408064475374,381.22811685774303,377.046691987195,385.40954172829106
0.03587312620273182,381.24979581954364,377.14465655613856,385.35493508294866
0.03603214646924284,381.39265142488466,377.27798696532267,385.5073158844467
0.03619114145232921,381.61365032223864,377.5445456347443,385.68275500973306
0.03635011116002955,381.7831253447069,377.66842171852517,385.8978289708886
0.03650905560037883,381.8387825108749,377.7283124403076,385.9492525814422
0.03666797478140754,381.9442446254924,377.8135993171982,386.07488993378655
0.036826868711143025,382.01191113440717,377.8273890128827,386.1964332559316
0.03698573739760855,382.17394820798114,377.9360198554701,386.4118765604922
0.03714458084882357,382.32887554905034,378.0532819344519,386.60446916364873
0.03730339907280394,382.4707060300235,378.2574058107397,386.6840062493073
0.037462192077561046,382.5840462707625,378.4669851259836,386.7011074155413
0.0376209598711031,382.68783531557114,378.64985207052223,386.72581856062
0.0377797024614343,382.8083199849671,378.8230648108115,386.7935751591227
0.037938419856555015,382.9501538046079,378.99089149718293,386.90941611203283
0.03809711206446202,382.99099073918103,379.02495614809544,386.95702533026656
0.03825577909314766,383.12436434749907,379.1119847684818,387.1367439265163
0.038414420950601096,383.2650175294537,379.158287523361,387.3717475355464
0.03857303764480749,383.33988429100896,379.1625352495672,387.51723333245064
0.038731629183748194,383.4496107435218,379.31137278760366,387.58784869944
0.03889019557540098,383.62387859730484,379.5503169877434,387.69744020686625
0.03904873682773919,383.75025211000064,379.7214983857525,387.77900583424884
0.039207252948733014,383.8156353351172,379.7559526776628,387.8753179925716
0.039365743946348626,383.8053286827883,379.694621701246,387.91603566433054
0.03952420982854843,383.90761234579287,379.77770709765946,388.0375175939263
0.03968265060329125,383.93007009268945,379.91275351428845,387.94738667109044
0.039841066278531484,383.7225857672217,380.1034459717491,387.34172556269425
0.0399994568622204,384.15127242455276,380.26688281696426,388.0356620321412
0.040157822362305265,384.4788709600412,380.41150607297584,388.5462358471066
0.04031616278672959,384.49336371684586,380.56940413201363,388.41732330167804
0.040474478143433294,384.65486758219913,380.72612468160054,388.58361048279767
0.040632768440351914,384.79998663519456,380.77990148432536,388.82007178606375
0.04079103368541785,384.8530145337577,380.8490215958832,388.8570074716322
0.04094927388655952,384.9502912496326,380.955846710951,388.9447357883142
0.041107489051701585,385.0328016542975,381.05331881401094,389.01228449458404
0.04126567918876515,385.12405859026376,381.18189723996517,389.06621994056235
0.041423844305666924,385.27191277127235,381.31055949144275,389.233266051102
0.04158198441032051,385.4590436119825,381.46501422455617,389.45307299940885
0.04174009951063554,385.6065272744197,381.5878227266167,389.62523182222264
0.04189818961451787,385.6509251492169,381.58456961831973,389.717280680114
0.04205625472986986,385.81841920516365,381.8008964884248,389.8359419219025
0.04221429486458946,385.86696140521843,381.8309222136407,389.90300059679623
0.042372310026571526,385.9090229137594,381.8595041660649,389.9585416614539
0.04253030022370694,385.99947661524226,382.00400196371953,389.99495126676504
0.04268826546388287,386.1202506678871,382.16228000660897,390.0782213291653
0.04284620575498295,386.21053052200614,382.2672958775793,390.15376516643295
0.043004121104886425,386.2761694193305,382.3377910716571,390.2145477670038
0.04316201152146947,386.3545711081052,382.4154470239849,390.29369519222547
0.043319877012604306,386.45369793833277,382.52620854216036,390.38118733450517
0.04347771758615942,386.57245501904725,382.6721579074468,390.4727521306477
0.0436355332499998,386.6659721112539,382.8453912389158,390.48655298359205
0.043793324011986066,386.77163019048317,382.9313915036096,390.6118688773568
0.04395108987997575,386.8188313365231,382.9894395627829,390.64822311026325
0.04410883086182247,386.87841262559135,383.0584664053204,390.69835884586234
0.04426654696537611,386.93101755613765,383.1364374929499,390.72559761932547
0.04442423819848306,387.0272248594233,383.22872315578275,390.8257265630639
0.044581904568985364,387.10810645052686,383.3130688857249,390.90314401532885
0.044739546084721984,387.2075784333638,383.423261343718,390.99189552300953
0.04489716275352798,387.2991980354739,383.5287425572898,391.0696535136581
0.0450547545832347,387.36860956798057,383.6007939473515,391.1364251886096
0.04521232158166999,387.4222078317936,383.659749116904,391.1846665466833
0.04536986375665737,387.5212057467287,383.8165487417334,391.225862751724
0.04552738111601732,387.6113971723895,383.9326520301404,391.29014231463856
0.04568487366756637,387.7192641302463,383.9512045619734,391.4873236985193
0.0458423414191174,387.81906470855904,384.01629161474335,391.62183780237467
0.04599978437847978,387.88022065219496,384.0890050427526,391.6714362616373
0.046157202553458565,387.8493898263394,384.204204354733,391.4945752979458
0.046314595951855775,387.9376599990427,384.28955824304944,391.585761755036
0.04647196458146951,388.0281526968093,384.37220086921053,391.6841045244081
0.04662930845009422,388.1088846410214,384.4623835552052,391.75538572683763
0.04678662756552086,388.1924206929588,384.54833797561633,391.8365034103013
0.04694392193553608,388.2599373808167,384.6178132871956,391.9020614744379
0.0471011915679235,388.299121458101,384.6530354494041,391.9452074667979
0.04725843647046285,388.3461597521563,384.7024324744493,391.98988702986327
0.04741565665093041,388.38155475912265,384.75816820397034,392.00494131427496
0.04757285211709815,388.42196900545304,384.8150993690189,392.0288386418872
0.04773002287673501,388.5595773409699,384.8862518825746,392.2329027993652
0.04788716893760605,388.5814544919902,385.0096034126482,392.1533055713322
0.04804429030747269,388.5639299146698,385.0083586683507,392.119501160989
0.04820138699409289,388.7183539949669,385.16440254032676,392.2723054496071
0.04835845900522032,388.76855121108275,385.3020422479623,392.23506017420317
0.04851550634860563,388.78130155373776,385.37838415244295,392.18421895503263
0.04867252903199561,388.751940898407,385.3441291404898,392.1597526563242
0.048829527063133406,388.73594322151786,385.3254225917124,392.14646385132335
0.04898650044975872,388.76713432222516,385.4049913114971,392.1292773329532
0.049143449199606976,388.81774491217186,385.52401659644505,392.1114732278986
0.04930037332041061,388.7457689159183,385.58909171482406,391.9024461170126
0.049457272819898174,388.7402649446599,385.60165828220653,391.8788716071133
0.049614147705794615,388.9166319143111,385.5577891152542,392.27547471336794
0.04977099798582143,388.96407124168803,385.5967491735994,392.3313933097767
0.04992782366769587,389.3101965672624,385.45195352658413,393.1684396079406
0.05008462475913217,389.23831461578084,385.5855786984462,392.8910505331155
0.05024140126784075,389.1921390273745,385.70094723238265,392.6833308223663
0.05039815320152838,389.2639728763498,385.73973845775436,392.7882072949452
0.050554880567898426,389.32356030639215,385.76247905096835,392.8846415618159
0.05071158337465001,389.3763916372947,385.78379838470516,392.96898488988427
0.05086826162947925,389.42823259663646,385.8029372091967,393.05352798407614
0.05102491534007846,389.47972678953215,385.8206326751362,393.1388209039281
0.05118154451413631,389.4920377363258,385.9559700365727,393.02810543607893
0.05133814915933809,389.3789460732767,386.0791009918501,392.67879115470333
0.05149472928336484,389.44643000773044,386.062705461155,392.8301545543059
0.05165128489389463,389.50582286900044,386.02418985295685,392.9874558850441
0.0518078159986017,389.56430047800495,385.9795118085509,393.14908914745894
0.0519643226051567,389.6250927945954,385.93937523395283,393.31081035523795
0.0521208047212269,389.3532398869072,386.1076826376665,392.5987971361478
0.0522772623544753,389.3044416978549,386.05031269716557,392.5585706985442
0.05243369551256198,389.27907449339733,385.9949554937256,392.56319349306904
0.05259010420314319,389.2664498059419,385.937306711803,392.59559290008076
0.05274648843387159,389.38225947739915,386.05647321308794,392.7080457417103
0.05290284821239648,389.5194975427044,386.1836339805761,392.85536110483275
0.05305918354636291,389.5821682187365,386.2299752427072,392.93436119476587
0.05321549444341299,389.64772745817584,386.2799964054914,393.01545851086024
0.05337178091118505,389.6692653437475,386.2746329610765,393.0638977264185
0.05352804295731383,389.65942154538374,386.26035943865736,393.05848365211006
0.053684280589430686,389.6471794049819,386.2456585417246,393.04870026823914
0.053840493815162795,389.6344558398587,386.2280897162298,393.0408219634876
0.053996682642134364,389.6303115843306,386.2020564765887,393.0585666920725
0.05415284707796584,389.6289147282893,386.15776227776513,393.1000671788135
0.054308987130274086,389.5622280661849,386.1236030395569,393.0008530928129
0.05446510280667262,389.55631781374484,386.0369894945851,393.07564613290464
0.05462119411477074,389.46711848593765,385.985905621189,392.94833135068626
0.05477726106217484,389.37309680589277,385.9270019470296,392.8191916647559
0.05493330365648754,389.31161017509885,385.91330357745863,392.70991677273906
0.05508932190530788,389.2371575820628,385.87644268125774,392.5978724828679
0.05524531581623157,389.1621122441367,385.7892985291521,392.5349259591213
0.05540128539685014,389.1447802425237,385.6669830116758,392.6225774733716
0.055557230654752175,389.13139357530565,385.5505867173469,392.71220043326434
0.05571315159752254,389.1234278091276,385.44278545307594,392.80407016517927
0.05586904823274251,389.05932314676915,385.388772547355,392.72987374618333
0.05602492056799006,388.9304950255122,385.3856893836567,392.47530066736766
0.05618076861083896,388.97696548454036,385.2451451859039,392.70878578317684
0.05633659236886009,388.92598406434297,385.18047591960834,392.67149220907754
0.05649239184962059,388.8713161522796,385.18565606486294,392.5569762396962
0.05664816706068405,388.83341234596,385.22435277817397,392.44247191374615
0.05680391800961071,388.773634947416,385.21847961570387,392.3287902791281
0.0569596447039567,388.720393386815,385.2207889921796,392.21999778145033
0.057115347151275225,388.69571462629295,385.2119117623056,392.1795174902803
0.05727102535911574,388.6706542734303,385.18137021078326,392.15993833607735
0.0574266793350242,388.6435781992326,385.1494873582401,392.1376690402251
0.057582309086543215,388.61769118486393,385.1162490111032,392.1191333586247
0.057737914621211285,388.60054213703756,385.0858378350424,392.11524643903266
0.05789349594656399,388.56992922152017,384.9606486577186,392.1792097853217
0.05804905307013319,388.5090883678587,384.84863521938115,392.16954151633615
0.058204585999447236,388.4936511535555,384.6580446163425,392.3292576907685
0.05836009474203118,388.3893792171338,384.39673335323175,392.38202508103586
0.05851557930540592,388.10626374224364,383.85852687045036,392.3540006140369
0.05867103969708949,387.82664955077433,383.2964606533598,392.3568384481889
0.0588264759245962,387.74758026233826,383.19507350970315,392.30008701497337
0.05898188799543686,387.71793991291713,383.2254519384155,392.2104278874188
0.059137275917118995,387.6783776318841,383.23534326700855,392.12141199675966
0.05929263969714598,387.68964834156696,383.30914026577,392.07015641736393
0.059447979343018355,387.77321093528633,383.47786787192723,392.0685539986454
0.059603294862232925,387.85717272271205,383.643675409672,392.07067003575213
0.05975858626228302,387.8219712080442,383.65533231763817,391.9886100984503
0.059913853550658674,387.65116443164237,383.4351934935139,391.86713536977084
0.060069096734845825,387.41813386436695,383.0945932392743,391.7416744894597
0.06022431582232754,387.2084848358221,382.7593984629523,391.657571208692
0.0603795108205832,387.1951712134308,382.68528420363805,391.70505822322355
0.060534681737088696,387.2998015617584,382.76555302309237,391.8340501004244
0.06068982857931665,387.3022733560275,382.68778421329654,391.91676249875854
0.06084495135473558,387.2047546828075,382.47353860893776,391.9359707566772
0.06100005007081116,386.94124102047783,381.83453668783545,392.04794535312016
0.06115512473500538,386.46444427824395,380.3323909237022,392.5964976327857
0.061310175354776765,386.0910370966114,379.57898259301857,392.60309160020415
0.06146520193758056,385.7677205877712,379.02729821409883,392.5081429614435
0.061620204490867934,385.62443969782674,379.01359216913335,392.2352872265202
0.06177518302208722,385.4810958567673,378.99627164027135,391.96592007326325
0.06193013753868307,385.4019974126376,379.0061472048485,391.7978476204267
0.06208506804809667,385.4968117814314,379.26927468710244,391.7243488757604
0.06223997455776599,385.6511975510844,379.67239484305475,391.6300002591141
0.06239485707512488,385.7816454304485,380.0404557508601,391.52283511003697
0.06254971560760436,385.7108525698868,379.95461086910507,391.4670942706686
0.06270455016263184,385.63273132544566,379.7861583211002,391.47930432979115
0.06285936074763122,385.55456739727794,379.61511857247797,391.4940162220779
0.06301414737002321,385.44096120889805,379.4023732398041,391.479549177992
0.06316891003722441,385.240880615624,379.1075613810143,391.37419985023377
0.06332364875664863,385.0496849912286,378.812347411534,391.28702257092317
0.063478363535706,384.8462489996049,378.49462583389607,391.1978721653137
0.06363305438180325,384.8747247858099,378.38406400927977,391.36538556234
0.06378772130234386,384.5190652059278,377.6088096233151,391.42932078854045
0.06394236430472727,384.0773579308864,376.73169860528594,391.4230172564869
0.06409698339635006,383.6354053924425,375.84811369988046,391.4226970850046
0.06425157858460523,383.34048514658934,375.3246967613708,391.3562735318079
0.06440614987688233,383.1981821691863,375.20567197035245,391.19069236802005
0.06456069728056767,383.1599617509915,375.2235287910984,391.09639471088457
0.06471522080304355,383.1190694528944,375.2600950687461,390.97804383704266
0.06486972045168947,383.09597450588933,375.3095732118574,390.88237579992125
0.06502419623388125,383.07274661551116,375.35903473795736,390.78645849306497
0.06517864815699136,383.002468265368,375.39065866669165,390.6142778640443
0.06533307622838902,382.7949336246827,375.4818446709181,390.1080225784473
0.06548748045543942,382.7771659723731,375.58959748816267,389.9647344565835
0.06564186084550497,386.1544550882381,381.6179596369968,390.69095053947933
0.06579621740594448,385.9499381344609,381.2087034485064,390.6911728204155
0.0659505501441133,385.72567005801926,380.7455812447275,390.705758871311
0.06610485906736363,385.50132493495147,380.2684862976967,390.7341635722062
0.06625914418304364,385.2768922111006,379.7792989285276,390.7744854936736
0.0664134054984987,385.0386257642258,379.26410064727435,390.8131508811772
0.06656764302107059,385.0972436583775,379.4045781886136,390.78990912814146
0.06672185675809768,385.21972098384583,379.67951371776047,390.75992824993114
0.06687604671691517,385.5012547340425,380.3196846997317,390.6828247683533
0.06703021290485425,385.85255454115435,381.0809905221557,390.62411856015297
0.0671843553292433,385.6234472682277,380.6695102755547,390.57738426090066
0.06733847399740715,385.2141808647532,380.161089164978,390.2672725645283
0.06749256891666724,384.8150171376686,379.6317765545235,389.9982577208136
0.06764664009434179,384.47853542523774,379.13312652633317,389.8239443241423
0.06780068753774507,384.34025286748795,379.0374094825521,389.6430962524238
0.06795471125418856,384.20190946104645,378.9403917351581,389.46342718693484
0.06810871125098017,384.1103829725484,378.8983049660687,389.3224609790281
0.06826268753542442,384.0258310498461,378.835203422951,389.2164586767411
0.06841664011482267,383.92736784524334,378.7513584462291,389.1033772442576
0.06857056899647229,383.7941429253356,378.62143450437105,388.9668513463002
0.06872447418766792,383.67667714189383,378.5107093652128,388.84264491857493
0.06887835569570057,383.5605682710408,378.4005031833183,388.72063335876334
0.06903221352785795,383.4444054983627,378.2890143377191,388.59979665900636
0.06918604769142456,383.228221262745,377.99206564776085,388.4643768777292
0.06933985819368096,382.85122455043097,377.3537700671516,388.34867903371037
0.06949364504190494,382.47409374235394,376.70702238606896,388.24116509863893
0.06964740824337076,382.08930922698084,376.04519512199994,388.13342333196175
0.06980114780534928,381.6643921341639,375.33783293397784,387.99095133435
0.06995486373510826,381.2908881491735,374.74318593083194,387.83859036751505
0.07010855603991145,381.2257147188922,374.87361321192236,387.5778162258621
0.0702622247270199,381.17176513275825,375.0460142286972,387.2975160368194
0.07041586980369109,381.1836132382731,375.3802937775135,386.98693269903265
0.07056949127717917,381.1954469878159,375.7000653079553,386.69082866767644
0.07072308915473512,381.25783772574295,376.0666675270662,386.4490079244196
0.070876663443606,381.0289332884094,375.7383149645064,386.31955161231247
0.07095344174454844,380.8250681144175,375.39012828265,386.26000794618494