File: RHTT AVG/RHTT_S_LUB_Ex_avg_true_stress_strain.csv
True Strain,True Stress (MPa),Lower Bound (MPa),Upper Bound (MPa)
-0.00030652397367354837,12.384453286304751,12.384453286304751,12.384453286304751
5.4057028381986114e-05,1.276573027757858,-0.5980155882491005,3.1511616437648162
0.0004145080586425406,34.32590479207296,19.36635820668535,49.285451377460575
0.0007748292107709581,59.7515077370092,55.176204988075185,64.32681048594321
0.0011350205783296483,86.5065064083691,78.96509916045535,94.04791365628284
0.001495082254779291,118.64740179291302,111.83706971370161,125.45773387212444
0.0018550143334798693,139.7713293770678,137.771502028019,141.77115672611657
0.0022148169076903704,169.9014683105661,158.50641014034645,181.2965264807857
0.0025744900705698195,195.18189502271056,189.84502567712127,200.51876436829986
0.0029340339151760915,221.78127147171347,215.35394334850557,228.2085995949214
0.003293448534466723,242.63404214081504,236.2386289787681,249.029455302862
0.0036527340212997197,264.61646874578145,257.2133036698004,272.01963382176257
0.004011890468432372,284.0436476069737,280.2787216596107,287.8085735543367
0.0043709179685222825,296.6651912095099,294.59961984076614,298.7307625782537
0.004729816614127071,305.21296789789056,303.1082251351465,307.31771066063465
0.0050885864977053994,310.50085087971337,308.3305042570873,312.67119750233945
0.005447227711615787,313.5708820684958,311.26120079706106,315.8805633399305
0.005805740348117419,316.04410023391694,313.83020531066654,318.2579951571674
0.00616412449937095,317.98288930447967,315.6836449629185,320.2821336460408
0.00652238025743732,319.366384101233,317.1540098599954,321.57875834247056
0.0068805077142785635,320.56800831977245,318.31211244212284,322.82390419742205
0.007238506961758606,321.6083642803907,319.4862823471631,323.7304462136182
0.007596378091642089,322.45637927431545,320.2365030450753,324.67625550355564
0.007954121195595385,323.08799970326544,320.9064718302808,325.26952757625014
0.008311736365186307,323.7754206732147,321.5800858402854,325.970755506144
0.008669223691885122,324.38569146120017,322.2928235014454,326.478559420955
0.009026583267063378,324.81399675192995,322.61688023303196,327.01111327082793
0.009383815181994696,325.1713805987836,323.04506213820446,327.29769905936274
0.009740919527855574,325.77191262568243,323.6129135008026,327.9309117505622
0.01009789639572421,326.19457446416214,324.0516217602621,328.3375271680622
0.010454745876581519,326.47620187805364,324.31575442288334,328.636649333224
0.010811468061310824,326.88850636259133,324.76717854688405,329.00983417829866
0.011168063040698891,327.2250336928317,325.06253451785915,329.3875328678042
0.011524530905434734,327.5635816306378,325.54687359831075,329.58028966296496
0.01188087174611042,327.878050594557,325.8451499570354,329.9109512320786
0.01223708565322186,328.2016416903633,325.74374587672145,330.65953750400513
0.01259317271716764,328.578298137395,326.4450844993929,330.711511775397
0.012949133028249807,328.80570413995855,326.7092458945754,330.9021623853416
0.013304966676674669,329.0647936334792,326.80185019248194,331.32773707447654
0.013660673752551618,329.42675734046486,327.1448936590336,331.7086210218961
0.014016254345894137,329.8194060041321,327.655418026072,331.9833939821922
0.014371708546619505,330.05194739506544,327.89630257176736,332.2075922183636
0.014727036444549807,330.2588607032611,328.09882091972787,332.41890048679437
0.015082238129410761,330.6761023679535,328.50178816820704,332.8504165677
0.0154373136908325,330.9873015127903,328.8211466292227,333.1534563963579
0.015792263218350373,331.3306228313992,329.20823751073925,333.45300815205906
0.016147086801403768,331.60482831854034,329.52034254058714,333.6893140964936
0.0165017845293369,331.93153343722344,329.70214868329265,334.1609181911542
0.016856356491399598,332.19626636841156,329.91976073135504,334.472772005468
0.01721080277674614,332.4070345124119,330.2274902161844,334.58657880863933
0.01756512347443625,332.6663816530408,330.50360814638253,334.8291551596991
0.017919318673434798,333.07343481152355,330.98370136572476,335.1631682573224
0.018273388462612818,333.4065592087101,331.25107273487646,335.56204568254384
0.01862733293074632,333.7653492627627,331.4283151698444,336.102383355681
0.018981152166517072,334.0986314735751,331.83640529756786,336.3608576495823
0.01933484625851341,334.25025420106664,332.06947740977995,336.4310309923534
0.01968841529522905,334.4905680547566,332.2602363330057,336.72089977650745
0.020041859365064082,334.93783827031706,332.7278857847957,337.1477907558384
0.020395178556324688,335.29459898953326,333.1046191076405,337.484578871426
0.020748372957224127,335.5829794510877,333.3710338962975,337.7949250058779
0.02110144265588158,335.91920079200236,333.69034090725376,338.1480606767509
0.021454387740322916,336.1230371611321,333.8995170781271,338.3465572441372
0.021807208298481484,336.3447068911141,334.10503378542023,338.5843799968079
0.02215990441819694,336.7445931538517,334.5176587221144,338.971527585589
0.02251247618721604,337.2120329308643,335.01035590282015,339.41370995890844
0.0228649236931934,337.39005300434445,335.2024889139816,339.5776170947073
0.023217247023690345,337.6257612699962,335.36938982669506,339.8821327132973
0.023569446266175895,338.0009206318252,335.7958928327,340.2059484309503
0.02392152150802647,338.4156313080797,336.1765127967862,340.65474981937314
0.024273472836526876,338.8021636768467,336.4857163394669,341.1186110142266
0.024625300338869158,339.0510914423265,336.7670351717821,341.3351477128708
0.024977004102153345,339.3023243764115,337.1486174715819,341.4560312812411
0.025328584213388256,339.5884697560423,337.38426164733823,341.7926778647463
0.025680040759490323,339.88502298830576,337.66314735995667,342.1068986166548
0.026031373827284363,340.35632805892266,338.0231538135092,342.68950230433603
0.026382583503504368,340.696344873318,338.42024952443575,342.97244022220036
0.026733669874792317,340.98942988574686,338.7340775662572,343.2447822052365
0.027084633027699194,341.2045371322977,338.93247933014703,343.4765949344483
0.02743547304868466,341.53194757011994,339.3193472648099,343.74454787543004
0.027786190024118057,341.8764952082668,339.725678516026,344.0273119005076
0.028136784040277245,342.2132358193776,339.91109879214997,344.5153728466052
0.02848725518334936,342.4187934672148,340.02734201443815,344.8102449199915
0.028837603539431603,342.7146363159891,340.29738289531286,345.1318897366653
0.02918782919453007,343.05036914022344,340.686750242599,345.4139880378479
0.029537932234560742,343.4162032012624,341.1957176504117,345.6366887521131
0.029887912745349163,343.70310663165645,341.5715505722162,345.8346626910967
0.030237770812631463,344.02979355530556,341.69465602490027,346.3649310857109
0.030587506522053158,344.40905173587413,342.0876401505642,346.730463321184
0.030937119959169937,344.6502780920665,342.37619722734667,346.9243589567863
0.03128661120944844,344.852592175582,342.53729439930225,347.16788995186175
0.03163598035826506,345.21824988025554,342.8376918773968,347.59880788311426
0.03198522749090677,345.41154073756513,343.0399160613972,347.78316541373306
0.03233435269257185,345.73608971599634,343.3672897479067,348.104889684086
0.032683356048368715,346.2269353463705,343.9372303733084,348.51664031943267
0.033032237643316927,346.40660725515073,343.99586703514,348.81734747516145
0.03338099756234689,346.7287109155468,344.3451188658936,349.1123029652
0.033729635890300806,346.95142817728276,344.5950731161352,349.30778323843026
0.034078152711931535,347.22939467335857,344.8018001349808,349.6569892117363
0.03442654811190335,347.54494355013804,345.0571577962394,350.03272930403665
0.03477482217479271,347.9138191741343,345.6146803601892,350.2129579880794
0.0351229749850871,348.2317593256735,345.71990736955865,350.7436112817884
0.035471006627186004,348.52173859272875,346.09446037493603,350.9490168105215
0.03581891718540059,348.8379721262924,346.48256753986504,351.1933767127198
0.03616670674395471,349.09843653922184,346.7866856805131,351.4101873979306
0.03651437538698373,349.33084587525065,347.02527255109595,351.6364191994054
0.03686192319853529,349.5888959002767,347.1658824053875,352.01190939516596
0.03720935026257007,349.9456302145753,347.3964002812843,352.4948601478663
0.03755665666296063,350.2027065956712,347.7125015181052,352.6929116732372
0.03790384248349217,350.52359966554206,348.0186921738956,353.0285071571886
0.03825090780786329,350.7364042861008,348.3368155524572,353.1359930197445
0.03859785271968484,351.01166838982505,348.6347382913551,353.388598488295
0.03894467730248089,351.3954898497504,348.9485212813072,353.84245841819364
0.03929138163968842,351.75045931490814,349.25310509968904,354.2478135301272
0.03963796581465829,351.9009774865188,349.49603686283206,354.3059181102056
0.03998442991065409,352.10241790260477,349.6665975712384,354.5382382339711
0.040330774010852895,352.42628373378784,349.90199600735446,354.95057146022117
0.040676998198346026,352.6937394927322,350.1287099056234,355.25876907984104
0.041023102556137905,352.995510108101,350.551173110533,355.43984710566895
0.041369087167146774,353.25353778815014,350.8922426103725,355.61483296592775
0.04171495211420549,353.5626524883543,351.1560142075952,355.9692907691134
0.04206069748006036,353.89333788669484,351.36431817455303,356.42235759883664
0.0424063233473721,354.1801837761795,351.6305705299896,356.7297970223694
0.04275182979871553,354.4696889114174,351.92448019260314,357.01489763023164
0.04309721691658055,354.6288143244616,352.069306763979,357.1883218849442
0.04344248478337098,354.8559922808846,352.4446583538088,357.26732620796037
0.043787633481405325,355.170866137016,352.7333942686483,357.6083380053837
0.0441326630929175,355.52462530413146,352.95967770415126,358.0895729041117
0.044477573700055714,355.81481565864595,353.24171953559414,358.38791178169777
0.044822365384883184,355.9320849337383,353.3935143211592,358.47065554631735
0.04516703822937892,356.3064298071929,353.7559700205816,358.8568895938043
0.045511592315436555,356.60360226241806,354.06288389575343,359.14432062908264
0.045856027724865314,356.6691819676574,354.2686122435357,359.06975169177906
0.046200344539389704,356.9030918857459,354.5531571124479,359.25302665904394
0.04654454284065049,357.4957621732136,354.8061092277819,360.1854151186453
0.0468886227102035,357.57458167158285,354.9955319714681,360.15363137169754
0.04723258422952043,357.70590133718355,355.161533013711,360.25026966065616
0.04757642747998958,357.9590917038657,355.39894198331086,360.5192414244205
0.04792015254291465,358.27229545424376,355.75122385883924,360.79336704964834
0.048263759499515786,358.5739975376615,356.0678483882567,361.08014668706636
0.0486072484309292,358.8003619039395,356.28515568976275,361.3155681181163
0.04895061941820816,359.0845095431219,356.47250819516546,361.69651089107833
0.04929387254232186,359.3021878423533,356.69082204192694,361.9135536427797
0.049637007884156106,359.62822712750386,357.16989659901185,362.08655765599593
0.04998002552451413,359.7134060788837,357.22322440639675,362.2035877513706
0.0503229255441154,359.97061107681566,357.4202190993121,362.52100305431924
0.05066570802359638,360.2171879614423,357.5511357242072,362.8832401986773
0.05100837304351126,360.52774328556205,357.774812049226,363.2806745218981
0.05135092068433083,360.74180685164515,358.1583638332685,363.32524987002176
0.051693351026443415,360.9212141072036,358.40354332499305,363.43888488941406
0.05203566415015458,361.16024168479595,358.63205229382527,363.68843107576663
0.052377860135688084,361.49307944509764,358.87403702380806,364.1121218663872
0.05271993906318472,361.6371292462722,359.08244165744196,364.1918168351024
0.053061901012703076,361.8826947518106,359.3059871870225,364.4594023165988
0.05340374606422025,362.2344623387152,359.6908278804022,364.77809679702824
0.053745474297630734,362.49829310135743,359.997703482342,364.9988827203728
0.05408708579274734,362.7251177968221,360.29398454692836,365.15625104671585
0.05442858062930091,362.63654598856243,359.8261079659893,365.4469840111356
0.054769958886941264,362.8083380004959,359.7521914280531,365.8644845729387
0.05511122064523604,363.3405484003196,360.7587494199634,365.9223473806759
0.05545236598367145,363.6455680301526,361.1939604505318,366.0971756097735
0.05579339498165301,363.8252259841356,361.18670933525084,366.4637426330204
0.056134307718504396,363.99942031608265,361.21618601406163,366.7826546181036
0.056475104273468184,364.28056866938044,361.7075881560354,366.8535491827255
0.05681578472570659,364.4717546503987,361.89984133431113,367.0436679664862
0.057156349154300325,364.56016277261267,361.848130908861,367.27219463636436
0.05749679763824954,364.8797865144328,362.2593131418017,367.50025988706386
0.057837130256473517,365.1068448417171,362.4622274292767,367.75146225415745
0.05817734708781161,365.36424879293406,362.6368828195296,368.09161476633847
0.05851744821102211,365.5522407614345,362.8921117018311,368.21236982103795
0.05885743370478299,365.5668347670605,362.96871070256657,368.16495883155443
0.05919730364769261,365.97530660334957,363.28667687528605,368.6639363314131
0.05953705811826859,366.2781445429983,363.55323346821797,369.00305561777867
0.059876697194948585,366.3869503372931,363.7595988964115,369.0143017781747
0.06021622095609092,366.5305871714069,363.8946197264255,369.1665546163883
0.06055562947997357,366.71045672320895,364.0188015733915,369.40211187302646
0.06089492284479499,366.93418551527196,364.3382798841442,369.53009114639974
0.06123410112867388,367.1893176781355,364.6218887383483,369.7567466179228
0.06157316440965012,367.4413119779463,364.78431003193094,370.0983139239617
0.06191211276568358,367.6425613055422,364.9778494172908,370.30727319379355
0.06225094627465489,367.82171718775635,365.22202218484773,370.42141219066497
0.06258966501436619,368.0661056660311,365.42021516830584,370.7119961637563
0.06292826906253993,368.22509941367446,365.5442057638189,370.90599306352993
0.06326675849681965,368.43098663939406,365.74230422460977,371.11966905417836
0.06360513339477071,368.62411658052383,365.9026857567559,371.3455474042917
0.0639433938338791,368.8635789321873,366.1245824693461,371.60257539502845
0.06428153989155247,369.0644396341545,366.3028311403045,371.8260481280045
0.0646195716451197,369.18607130784443,366.48437338050394,371.88776923518486
0.06495748917183193,369.4230807948529,366.756332338425,372.0898292512809
0.06529529254886139,369.61569110510766,366.91230205316566,372.31908015704965
0.06563298185330214,369.75971659423885,366.9784569784112,372.54097621006656
0.06597055716217076,369.9858502775193,367.4021067997646,372.56959375527407
0.06630801855240527,370.07190397653534,367.39284680435617,372.75096114871445
0.066645366100866,370.35877280605735,367.73788887329414,372.9796567388205
0.06698259988433532,370.5429344576307,367.7545369095995,373.33133200566186
0.06731971997951859,370.6992836527889,367.9052671591349,373.49330014644295
0.067656726463043,370.9559557344843,368.18319111875894,373.72872035020964
0.06799361941145823,371.2116630661335,368.4393683915677,373.9839577406993
0.06833039890123735,371.3543583265856,368.71782301595044,373.9908936372207
0.06866706500877545,371.5095060196267,368.92271117865937,374.09630086059406
0.06900361781039059,371.801908010697,369.26635073081627,374.33746529057777
0.06934005738232435,371.8665615689529,369.1773650158313,374.55575812207445
0.0696763838007408,371.9167506509204,369.18196858635105,374.65153271548974
0.07001259714172739,372.0838218489216,369.30955244163454,374.85809125620864
0.07034869748129463,372.2029142699518,369.39364519586707,375.0121833440366
0.07068468489537706,372.39816036425617,369.5613215202354,375.23499920827686
0.07102055945983206,372.9348727602847,370.11398099837726,375.7557645221922
0.07135632125044061,372.6051688115892,369.79055260424906,375.4197850189293
0.071691970342908,372.8649059299088,370.06014367063347,375.66966818918405
0.07202750681286271,373.3502731009338,370.6535276038696,376.0470185979981
0.07236293073585731,373.50582136311453,370.82473919552444,376.1869035307046
0.07269824218736815,373.5934569575446,370.8469040011757,376.34000991391355
0.07303344124279633,373.7994472047706,371.07534226007556,376.5235521494657
0.0733685279774665,373.95942469685684,371.258600621427,376.66024877228665
0.07370350246662764,374.13017505167926,371.402206581945,376.8581435214136
0.07403836478545377,374.28746167946406,371.5541948732509,377.0207284856773
0.07437311500904274,374.4649645103116,371.6903675927061,377.23956142791707
0.07470775321241706,374.6901909037096,371.9015471389098,377.4788346685095
0.07504227947052454,374.86646486770303,372.0545157025209,377.67841403288514
0.07537669385823721,375.0247386677889,372.3101162171481,377.73936111842966
0.07571099645035217,375.1695972515008,372.552094469806,377.78710003319566
0.07604518732159139,375.35475887977617,372.70026644135953,378.00925131819275
0.0763792665466025,375.4672379169907,372.81269595955644,378.12177987442493
0.07671323419995775,375.6106395915371,372.9504236544686,378.2708555286056
0.07704709035615473,375.79519105412885,373.06254133376234,378.5278407744954
0.077380835089617,376.09909937054687,373.2307462893662,378.96745245172747
0.07771446847469307,376.1481424754646,373.32912392053805,378.9671610303912
0.07804799058565723,376.2871603660094,373.46951566541895,379.10480506659985
0.07838140149670927,376.2969105044733,373.5117392787115,379.08208173023513
0.07871470128197544,376.5506050906038,373.8749121704279,379.2262980107798
0.07904789001550724,376.6868830959115,373.94572165301315,379.4280445388099
0.0793809677712822,376.83483060410026,374.1063874535283,379.5632737546722
0.07971393462320454,377.07332027249925,374.2629985975182,379.8836419474803
0.08004679064510412,377.19046539051624,374.3636929467212,380.01723783431123
0.08037953591073703,377.3775954543131,374.56295300330913,380.1922379053171
0.08071217049378644,377.55626353319724,374.75508756129534,380.35743950509914
0.08104469446786136,377.7112232701266,374.90130913743815,380.5211374028151
0.0813771079064976,377.8840838647851,375.09808431153834,380.6700834180319
0.08170941088315749,378.0381736092408,375.24239126731953,380.83395595116207
0.08204160347123073,378.12728337589033,375.30698998217713,380.9475767696035
0.08237368574403328,378.276942740317,375.4645547268418,381.0893307537922
0.08270565777480815,378.47297297715687,375.74217473467166,381.20377121964214
0.08303751963672595,378.59526875853965,375.84670161866916,381.3438358984102
0.08336927140288396,378.6885916030545,375.96214905972226,381.4150341463867
0.08370091314630683,378.8377404598134,376.07657512875267,381.5989057908741
0.08403244493994644,378.9769640351245,376.1484742114482,381.8054538588008
0.08436386685668275,379.13436527623526,376.28592632937676,381.98280422309375
0.08469517896932265,379.2943856610743,376.43819574550724,382.1505755766413
0.08502638135060069,379.4926920350097,376.5908182952273,382.3945657747922
0.08535747407317977,379.65419354534407,376.7107412197474,382.59764587094077
0.08568845720965008,379.80023259662204,376.9644478062086,382.6360173870354
0.08601933083252972,379.91105371629794,377.1219930380217,382.70011439457414
0.08635009501426544,380.0211624682968,377.23473635459806,382.80758858199556
0.08668074982723149,380.0965414577193,377.32793755796433,382.86514535747426
0.08701129534373042,380.3048225220103,377.53890561120676,383.07073943281375
0.08734173163599367,380.37680872640635,377.66375911204506,383.0898583407676
0.08767205877618048,380.5173006015234,377.78026177254054,383.25433943050626
0.08800227683637885,380.7223996679033,377.89499906030204,383.54980027550454
0.08833238588860513,380.80111847642013,377.92692041864956,383.6753165341907
0.08866238600480504,380.958353577439,378.1188245359312,383.7978826189468
0.08899227725685245,381.078534940288,378.22718529247527,383.9298845881007
0.08932205971655013,381.2975806204785,378.3978883923967,384.19727284856043
0.08965173345563046,381.43919391514584,378.59501978953705,384.2833680407547
0.08998129854575429,381.5853727466393,378.7202558696329,384.45048962364564
0.0903107550585118,381.66552478659275,378.7603920701143,384.57065750307123
0.09064010306542229,381.8105881562945,378.9483948580766,384.6727814545124
0.090969342637935,381.95235487721055,379.086222768625,384.8184869857961
0.09129847384742802,382.0960305973511,379.1990283733348,384.99303282136736
0.09162749676520898,382.20444813078495,379.2996940038217,385.1092022577483
0.09195641146251576,382.3487917725015,379.45373560801045,385.24384793699255
0.09228521801051535,382.51040664618785,379.6908661979808,385.3299470943948
0.09261391648030459,382.6656028082744,379.9283947965865,385.4028108199624
0.09294250694291081,382.6841748314631,379.8540953825581,385.51425428036816
0.09327098946929076,382.7915377961411,379.9242587972242,385.658816795058
0.09359936413033149,382.89232431473613,379.96781297891494,385.81683565055727
0.09392763099685,383.0564021343619,380.2903897278562,385.8224145408676
0.09425579013959426,383.08762993233137,380.32590314649093,385.8493567181718
0.09458384162924192,383.41129162377763,380.5054200282007,386.31716321935454
0.09491178553640117,383.5951260136279,380.6375568399731,386.5526951872827
0.09523962193161128,383.7096380868963,380.6884363403666,386.730839833426
0.09556735088534166,383.72039420066193,380.84214666759925,386.59864173372466
0.09589497246799256,383.78849173723876,380.9931981159268,386.58378535855064
0.09622248674989492,383.8600204512456,381.12026438550646,386.5997765169847
0.09654989380131118,383.97260737337007,381.1886040016598,386.75661074508037
0.09687719369243422,384.13591708875634,381.3468302574286,386.925003920084
0.09720438649338796,384.30590446208697,381.485946359378,387.12586256479597
0.09753147227422818,384.4582876452808,381.6171418138744,387.2994334766872
0.09785845110494126,384.56012849331574,381.7121987057356,387.40805828089594
0.09818532305544503,384.63181146540614,381.81261439066986,387.4510085401424
0.09851208819558935,384.803184299137,381.9553292727287,387.65103932554536
0.09883874659515499,385.02162935696794,382.07416993175303,387.9690887821829
0.09916529832385461,385.0982687217332,382.1543815270553,388.042155916411
0.09949174345133238,385.2313957191063,382.3039135752579,388.1588778629546
0.09981808204716489,385.3226030165493,382.42131682823293,388.2238892048656
0.10014431418086003,385.3992556753228,382.51577067976217,388.2827406708834
0.10047043992185768,385.5060998556958,382.62290873420676,388.3892909771849
0.10079645933953044,385.5913058949194,382.6868193472027,388.49579244263606
0.10112237250318241,385.7237659092961,382.8720839094723,388.5754479091199
0.10144817948205023,385.83153250607114,382.9797603892923,388.68330462284996
0.10177388034530264,385.93188198474377,383.0332112020715,388.83055276741607
0.10209947516204143,386.19671287747167,383.5246086552947,388.86881709964865
0.10242496400130031,386.1260129894472,383.23027366364516,389.0217523152493
0.10275034693204561,386.20042923242306,383.3314683229208,389.06939014192534
0.10307562402317698,386.38483300879847,383.48858921950415,389.28107679809284
0.1034007953435262,386.5028299872296,383.603553532255,389.4021064422042
0.10372586096185797,386.47081806086635,383.3266344970503,389.61500162468246
0.10405082094687056,386.66878064660114,383.65965054374834,389.6779107494539
0.10437567536719465,386.78385905905776,383.7923339122775,389.775384205838
0.10470042429139431,386.9160472622244,383.95374446147423,389.8783500629746
0.10502506778796657,387.02292428338677,384.1082686602602,389.9375799065134
0.10534960592534241,387.2551296450967,384.51554022676584,389.9947190634276
0.10567403877188562,387.3294512038088,384.68809597113784,389.97080643647973
0.10599836639589343,387.4157881386262,384.7593933731941,390.0721829040583
0.10632258886559727,387.6120111331673,384.79608225214326,390.42794001419134
0.10664670624916162,387.77533745876855,384.8730600495113,390.6776148680258
0.1069707186146847,387.8529118069986,384.9098412343082,390.795982379689
0.10729462603019914,387.8618486820539,384.80660132273744,390.9170960413704
0.10761842856367092,387.9548965855223,384.92208303697277,390.98771013407185
0.10794212628300016,388.0331514848533,385.0224956841471,391.0438072855595
0.10826571925602096,388.13540921964415,385.1522404010914,391.11857803819686
0.10858920755050208,388.1762191928545,385.1872205174695,391.16521786823955
0.10891259123414601,388.1995288350182,385.2140678888408,391.18498978119567
0.10923587037458955,388.31098642217216,385.356336130889,391.26563671345525
0.10955904503940453,388.38660757277825,385.4588397099822,391.3143754355743
0.10988211529609666,388.5006203060982,385.57476694359013,391.42647366860626
0.11020508121210632,388.6208665575528,385.6869710820523,391.55476203305335
0.11052794285480909,388.73942323852094,385.8007028119441,391.67814366509776
0.11085070029151474,388.86173044600883,385.903399180138,391.82006171187965
0.11117335358946809,388.9338072998073,385.9872367506607,391.88037784895386
0.1114959028158487,389.04897946118047,386.108319357148,391.98963956521294
0.11181834803777173,389.1318110207974,386.1783478643367,392.0852741772581
0.11214068932228682,389.1976201572615,386.23502787784383,392.1602124366791
0.11246292673637885,389.35908921315104,386.41838251917403,392.299795907128
0.11278506034696852,389.47211234139905,386.52278321158525,392.42144147121286
0.11310709022091127,389.56583677161524,386.6495179689584,392.4821555742721
0.11342901642499821,389.66577752191824,386.75237425565854,392.57918078817795
0.11375083902595573,389.74033139371636,386.8068097735322,392.67385301390044
0.11407255809044646,389.82844077453973,386.87250710566565,392.7843744434138
0.11439417368506806,389.9338805945539,386.9734699248098,392.89429126429803
0.11471568587635399,390.05265856302196,387.0956303715834,393.0096867544605
0.11503709473077416,390.11763618890546,387.1422750111323,393.0929973666786
0.11535840031473377,390.17171631442307,387.1819509705899,393.16148165825626
0.11567960269457406,390.21943459198303,387.2372518723698,393.2016173115962
0.11600070193657298,390.36365375478323,387.3448592080372,393.3824483015292
0.11632169810694402,390.4121059281627,387.4035706240632,393.4206412322622
0.11664259127183715,390.4805003852153,387.50119405135877,393.4598067190719
0.11696338149733848,390.5663928221095,387.574198311512,393.55858733270696
0.11728406884947111,390.62760220085516,387.6187612775587,393.6364431241516
0.11760465339419407,390.7052406836949,387.6833300118506,393.72715135553915
0.11792513519740298,390.794779995757,387.705575006222,393.883984985292
0.11824551432493072,390.88334030896067,387.75837044517874,394.0083101727426
0.1185657908425463,390.9349755867576,387.8249005671701,394.0450506063451
0.11888596481595576,390.9537528864873,387.83010938195406,394.07739639102044
0.11920603631080187,390.9976602307893,387.7671910240103,394.2281294375682
0.11952600539266497,391.1720769459005,388.09747038329334,394.2466835085078
0.11984587212706188,391.29533999380243,388.29272378243877,394.2979562051661
0.12016563657944655,391.3804138989307,388.3644433559708,394.39638444189063
0.12048529881521079,391.4798649515641,388.4386391689837,394.5210907341444
0.12080485889968309,391.5565789245011,388.4988047034726,394.6143531455295
0.12112431689812936,391.5922682044144,388.5490016325679,394.63553477626084
0.12144367287575354,391.61377181891396,388.6079492671364,394.6195943706916
0.12176292689769658,391.714706987377,388.66309391974465,394.76632005500926
0.12208207902903702,391.7756307807703,388.70303483507564,394.848226726465
0.12240112933479169,391.77755970870805,388.6905841505122,394.86453526690383
0.12272007787991467,391.8372722268695,388.7732906006701,394.9012538530689
0.12303892472929806,391.9107086138307,388.82243415900666,394.99898306865475
0.12335766994777171,391.914516039047,388.75404000795766,395.0749920701363
0.12367631360010414,391.8703693498255,388.60699860615733,395.13374009349377
0.12399485575100132,392.10647640799175,388.9948132389761,395.2181395770074
0.12431329646510764,392.0238421422561,388.7929117577025,395.2547725268097
0.12463163580700554,391.91856228652995,388.49847331840886,395.338651254651
0.12494987384121639,392.28979210993094,389.0918583494211,395.48772587044084
0.12526801063219944,392.4477468142442,389.29855757791336,395.59693605057504
0.12558604624435235,392.39740392906384,389.18866753048565,395.60614032764204
0.12590398074201203,392.4531457901627,389.25420675423055,395.6520848260948
0.1262218141894534,392.5153950301056,389.34045379253917,395.69033626767197
0.12653954665089015,392.61673440889325,389.43772594672674,395.79574287105976
0.12685717819047534,392.6857220170459,389.5171039331814,395.85434010091046
0.12717470887230034,392.7094373016902,389.539243663083,395.87963094029726
0.12749213876039553,392.6575846082752,389.4438435709577,395.8713256455927
0.12780946791873082,392.6366924074704,389.3490333583075,395.92435145663325
0.12812669641121474,392.69092943820755,389.3888100247583,395.99304885165674
0.1284438243016952,392.71351754552785,389.41664921273957,396.0103858783161
0.1287608516539592,392.75787087933674,389.4328360975088,396.08290566116466
0.1290777785317336,392.81355708487945,389.4439078139639,396.183206355795
0.12939460499868422,392.8698520777549,389.4944027923146,396.24530136319515
0.12971133111841648,392.9336863242999,389.52478986565364,396.3425827829462
0.13002795695447525,392.96506398823215,389.53660540907737,396.393522567387
0.13034448257034562,392.9733267787954,389.55101400738505,396.3956395502058
0.13066090802945182,392.9749863294228,389.56565854378584,396.3843141150597
0.13097723339515793,392.97701555327217,389.5649489013467,396.3890822051976
0.13129345873076848,393.0034502482238,389.53560399019267,396.471296506255
0.13160958409952736,393.0244560198029,389.51587805956694,396.5330339800389
0.13192560956461852,393.0006112037242,389.45428530365234,396.54693710379604
0.13224153518916662,393.0128859829771,389.48266559322,396.54310637273414
0.1325573610362359,392.9221135985944,389.38154797777753,396.46267921941137
0.13287308716883087,392.7095184850956,389.13131421145806,396.28772275873314
0.133188713649897,392.4524901825606,389.1748033281101,395.7301770370111
0.1335042405423196,393.078459078157,389.33329420373343,396.8236239525806
0.13381966790892458,393.04353375371045,389.41797101299704,396.6690964944239
0.1341349958124783,393.0806519498018,389.4798545436553,396.68144935594836
0.13445022431568834,393.09707269370426,389.48284469801706,396.71130068939146
0.13476535348120242,393.16579950364064,389.4741683780385,396.85743062924274
0.13508038337160896,393.1916907874123,389.4267612181799,396.95662035664475
0.135395314049438,393.1720736034107,389.33064300307854,397.01350420374285
0.13571014557715977,392.9532545804705,389.2336999907154,396.6728091702256
0.1360248780171858,392.93585480087324,389.06746973956643,396.8042398621801
0.1363395114318685,392.8650291643239,388.81337184537966,396.9166864832681
0.13665404588350205,392.61733706139404,388.6018082818584,396.63286584092964
0.1369684814343212,392.7492747520851,388.53133695788046,396.9672125462898
0.13728281814650212,392.81536137974643,388.6035496775818,397.0271730819111
0.13759705608216288,392.8290270815812,388.6409214655337,397.0171326976287
0.13791119530336246,392.74504507100926,388.6319115292614,396.85817861275706
0.13822523587210134,392.76974817211584,388.6223005505134,396.9171957937183
0.13853917785032221,392.7951299718403,388.5619220563775,397.0283378873031
0.13885302129990887,392.7434545367679,388.4296364031964,397.05727267033933
0.139166766282687,392.6237912973463,388.20429786584117,397.04328472885146
0.13948041286042404,392.4908701725702,387.9714402165684,397.0103001285721
0.13979396109482978,392.34400320167776,387.5890476612,397.09895874215556
0.14010741104755545,392.25119241042256,387.4331552647778,397.06922955606734
0.14042076278019433,392.2337902779352,387.534092784093,396.93348777177744
0.14073401635428243,392.23448922727437,387.64033526924436,396.8286431853044
0.1410471718312973,392.26391906404245,387.70658060859944,396.8212575194854
0.14136022927265898,392.19428236506815,387.6199024617059,396.7686622684303
0.14167318873972967,391.7031448113165,387.0050166172732,396.4012730053598
0.1419860502938145,391.5539758509594,386.81971173806477,396.288239963854
0.14229881399616057,391.44821186064985,386.47301206034535,396.42341166095434
0.1426114799079575,391.1855250215009,385.92720876936596,396.4438412736358
0.14292404809033804,390.8945149408415,385.0038717082057,396.78515817347727
0.1432365186043772,390.94723601483554,385.10699358502825,396.78747844464283
0.14354889151109262,391.0242985079212,385.3003005885767,396.7482964272656
0.14386116687144543,391.08144438310416,385.3991992061463,396.76368956006206
0.14417334474633908,390.9716082939976,385.07872564473985,396.86449094325525
0.14448542519661997,390.7414586133442,384.87941106339144,396.60350616329697
0.1447974082830782,390.50118921976946,384.676943239776,396.3254351997629
0.14510929406644626,390.39361254657274,384.55904072781937,396.22818436532606
0.14542108260740025,390.28905378124074,384.3769649504231,396.20114261205845
0.14573277396655912,389.89948900284764,383.5071741494202,396.29180385627507
0.14604436820448588,389.3491308934645,382.4874129601633,396.2108488267658
0.14635586538168632,388.8878052743126,381.43815695860286,396.3374535900223
0.14666726555860987,388.806345468138,381.4613907842988,396.1513001519771
0.14697856879564938,388.67463352445407,381.30982724987103,396.03943979903704
0.14728977515314182,388.6540511194268,381.20785587257274,396.1002463662808
0.14760088469136728,388.4473694329674,380.85628397786707,396.03845488806775
0.14791189747054967,388.19030885792034,380.4363869865385,395.9442307293022
0.14822281355085723,387.8785790297495,379.9607607746622,395.79639728483687
0.14853363299240158,387.68099424246736,379.56222756012914,395.7997609248056
0.14884435585523825,387.3549633169743,378.7655119652419,395.9444146687067
0.14915498219936743,386.9302257427168,377.65722112875704,396.2032303566765
0.1494655120847328,391.14722218079197,387.56282658895896,394.73161777262504
0.14977594557122223,390.90170574573335,387.09295397024545,394.71045752122126
0.1500862827186684,390.19214608730283,385.56200016806275,394.8222920065429
0.15039652358684774,389.77216841014047,384.7176585379559,394.8266782823251
0.15070666823548126,389.9522144642255,385.35310929327096,394.5513196351801
0.15101671672423422,390.0498270354412,385.8008336441994,394.29882042668294
0.15132666911271694,389.6856358645863,385.41883207564746,393.95243965352506
0.15163652546048387,389.03583655059185,385.0094541019615,393.06221899922224
0.15194628582703412,388.6026918411161,384.7886441830471,392.41673949918516
0.15225595027181152,388.5366012289824,384.37945014047114,392.69375231749365
0.15256551885420513,388.45024294125346,383.9511648651012,392.94932101740574
0.1528749916335484,388.0273725138029,383.04782719198306,393.00691783562274
0.15318436866911966,387.595509667325,382.1128876623774,393.07813167227266
0.1534936500201428,387.027255132635,380.83596582671737,393.21854443855256
0.15380283574578624,386.6619536642973,380.08272233362254,393.2411849949721
0.1541119259051635,386.31155600277253,379.6690840792198,392.9540279263253
0.15442092055733392,385.92288671122964,379.2193879051015,392.62638551735785
0.15472981976130148,385.41932398844193,378.43872003626404,392.3999279406199
0.15503862357601556,384.8669851509042,377.65724375217866,392.0767265496298
0.15534733206037146,387.25434948136564,380.9708181690729,393.5378807936584
0.15565594527320942,386.40712109853956,380.6632567096082,392.15098548747085
0.1559644632733154,386.0229390841667,380.6540665019076,391.39181166642584
0.15627288611942075,386.2071683872437,380.6219086300173,391.7924281444701
0.15658121387020313,386.1690842510313,379.95122304740704,392.3869454546555
0.1568894465842853,386.0029827217296,379.2877695647844,392.7181958786748
0.15719758432023584,390.5611321437408,388.0471867665762,393.0750775209053
0.15750562713656985,390.60676347584274,388.1389639019204,393.074563049765
0.1578135750917477,390.3377586467288,387.7603419008902,392.9151753925674
0.15796751351465715,390.14985697789496,387.49421280775977,392.80550114803015