File: RHTT AVG/RHTT_S_DRY_Ex_avg_eng_stress_strain.csv
Engineering Strain,Engineering Stress (MPa),Lower Bound (MPa),Upper Bound (MPa)
-0.000630475,-0.3554029166666666,-0.3554029166666666,-0.3554029166666666
-0.00047381318818818824,7.232201070458819,7.232201070458819,7.232201070458819
-0.0003171513763763764,3.8829955052506944,-0.27145472576105645,8.037445736262445
-0.00016048956456456457,6.41864456222626,-2.0587381481951317,14.89602727264765
-3.827752752752793e-06,0.3645774168847097,-0.37999147510168585,1.109146308871105
0.000152834059059059,15.638760836794754,-3.573533947124263,34.85105562071377
0.0003094958708708709,46.225419807442215,22.23001477476641,70.22082484011801
0.00046615768268268266,60.47053086820987,34.543579291550245,86.3974824448695
0.0006228194944944944,78.89943802219253,65.17388081243962,92.62499523194543
0.0007794813063063062,89.66826810219086,73.55864677442284,105.77788942995889
0.000936143118118118,98.41049758457561,82.93932493438598,113.88167023476524
0.0010928049299299297,108.95267575469427,94.64814022740731,123.25721128198123
0.0012494667417417417,121.82859653827487,113.23614158836436,130.42105148818536
0.0014061285535535532,130.55224812937854,121.06631953808932,140.03817672066776
0.0015627903653653652,141.3514051476707,129.61974762488495,153.08306267045646
0.0017194521771771768,153.48736553478744,140.28167141649408,166.6930596530808
0.0018761139889889888,165.02269261409094,156.26058493728354,173.78480029089835
0.002032775800800801,181.48553284577144,170.57572592168177,192.39533976986112
0.0021894376126126124,186.37277548143555,174.5496500387697,198.1959009241014
0.0023460994244244244,200.78394971470544,188.64748393042342,212.92041549898747
0.002502761236236236,211.56267906215356,201.59682946498438,221.52852865932275
0.002659423048048048,228.0519987301705,213.69709005818484,242.40690740215618
0.0028160848598598595,234.15673474810342,225.84195433444444,242.4715151617624
0.0029727466716716715,249.70614871005927,231.62008847220054,267.792208947918
0.0031294084834834835,261.6373595005469,247.01700013322707,276.2577188678667
0.0032860702952952955,268.4246443491733,257.58754912685004,279.2617395714966
0.0034427321071071066,278.365360168971,264.6441861852616,292.0865341526804
0.0035993939189189186,285.6583278191421,272.8063380634126,298.5103175748715
0.0037560557307307306,294.48207284947796,283.7584765074513,305.2056691915046
0.003912717542542543,299.66671712564477,291.0741771254385,308.25925712585104
0.004069379354354354,307.443533428249,299.43290277313645,315.45416408336155
0.004226041166166166,312.1199680240642,301.4027314834943,322.8372045646341
0.004382702977977978,317.8724983015778,309.54726759284824,326.1977290103074
0.00453936478978979,321.79686438697047,314.44456630005476,329.1491624738862
0.004696026601601602,325.01581057362125,318.43770815434357,331.59391299289894
0.004852688413413413,329.10052250791585,321.88450316083885,336.31654185499286
0.005009350225225225,330.971334779775,325.29155531845043,336.6511142410996
0.005166012037037037,333.7685623249581,327.2637335220397,340.27339112787655
0.005322673848848849,335.09531708134506,329.34855261126046,340.84208155142966
0.00547933566066066,336.6644259638573,330.45495484441,342.8738970833046
0.005635997472472472,337.9089242313388,332.15140992515074,343.66643853752686
0.005792659284284284,338.82063419431057,333.70038893425146,343.9408794543697
0.005949321096096096,340.2825091948733,334.0316983155483,346.5333200741983
0.006105982907907908,340.7868565845147,335.75088796404367,345.8228252049857
0.006262644719719719,342.22723866180627,335.9934579763254,348.46101934728716
0.006419306531531531,342.81125935273053,337.1715604802335,348.45095822522757
0.006575968343343343,343.7394950409819,337.7483645973788,349.73062548458506
0.006732630155155155,344.42079817344757,337.8656672678899,350.97592907900525
0.006889291966966967,344.82562869019534,338.7300902787321,350.92116710165857
0.007045953778778778,345.17857147573505,339.7310109190404,350.6261320324297
0.007202615590590591,345.8851141611204,340.2196575433289,351.5505707789119
0.007359277402402402,346.51352603962295,340.3923470036752,352.6347050755707
0.007515939214214213,346.94706594635534,340.8918819350662,353.0022499576445
0.007672601026026026,347.6264942269889,341.13056718027116,354.1224212737066
0.007829262837837837,348.2735893736684,341.5444502471641,355.00272850017274
0.007985924649649648,348.5225418194719,342.03540401229424,355.00967962664953
0.008142586461461461,348.7740148638739,342.5376854596481,355.0103442680997
0.008299248273273272,349.07166879137424,343.14170635428087,355.0016312284676
0.008455910085085085,349.2196812008063,343.6468093993381,354.7925530022745
0.008612571896896896,350.46388399472505,343.7898020013016,357.1379659881485
0.008769233708708708,350.7114973239135,344.33057776056944,357.0924168872575
0.00892589552052052,350.56756184566785,344.9377024150602,356.1974212762755
0.009082557332332332,350.8387331556323,345.2036825663571,356.47378374490756
0.009239219144144144,351.4917167005963,345.2703959311233,357.71303747006937
0.009395880955955956,351.9907429443318,345.5274215343669,358.45406435429675
0.009552542767767767,351.95653140904903,345.99496989681836,357.9180929212797
0.00970920457957958,353.06085310876085,345.4786308155131,360.6430754020086
0.00986586639139139,353.3172723216391,346.24514186161383,360.3894027816644
0.010022528203203204,353.6991803501558,347.1868910006684,360.2114696996432
0.010179190015015015,353.6065160824178,347.81592086375997,359.3971113010756
0.010335851826826826,353.8367746899945,347.80528066145786,359.86826871853117
0.010492513638638639,354.4617633826791,347.9560040153177,360.96752275004053
0.01064917545045045,355.1631761072268,348.06117474666985,362.2651774677837
0.010805837262262263,355.3539673022537,348.5485287208023,362.15940588370506
0.010962499074074074,355.5750604251709,349.081385948932,362.06873490140975
0.011119160885885885,356.29318468542925,348.86802966922573,363.7183397016328
0.011275822697697698,356.40221550751585,349.13000585479153,363.67442516024016
0.011432484509509509,356.4580340326264,349.3991068201079,363.51696124514496
0.01158914632132132,356.50918145062235,350.10144575917997,362.91691714206473
0.011745808133133133,357.1107011640941,350.41814324315976,363.80325908502846
0.011902469944944944,357.5178466103334,350.4627695447114,364.57292367595534
0.012059131756756757,357.9128609188544,350.4729452430765,365.3527765946323
0.012215793568568568,358.19221104409394,351.043157421935,365.34126466625287
0.01237245538038038,358.33390079473656,351.6390550977925,365.02874649168064
0.012529117192192192,358.4448113575769,352.14924402426743,364.74037869088636
0.012685779004004003,358.94703364893945,352.1990689033111,365.6949983945678
0.012842440815815816,359.58548346034064,351.87862306417003,367.29234385651125
0.012999102627627627,359.46979749609017,352.28654482168156,366.6530501704988
0.013155764439439438,359.6886778151178,352.3712390645978,367.0061165656378
0.013312426251251251,360.22231709690385,352.49537412150966,367.94926007229805
0.013469088063063062,360.2314869923164,353.2977605404133,367.16521344421943
0.013625749874874875,360.8970821494536,353.31954722589114,368.474617073016
0.013782411686686686,361.35304982864847,353.22287526374225,369.4832243935547
0.013939073498498497,361.9852623531871,353.3894397415424,370.58108496483186
0.01409573531031031,362.0898769324672,353.90787585193516,370.2718780129992
0.014252397122122121,362.1273313785512,354.3536864773168,369.90097627978565
0.014409058933933934,361.95358531300536,354.8512444448334,369.0559261811773
0.014565720745745745,362.27013180824014,355.0958410158916,369.44442260058867
0.014722382557557557,362.90159590167184,354.8721104127965,370.9310813905472
0.01487904436936937,363.1026371828216,355.0481088983439,371.15716546729925
0.015035706181181182,363.271003001203,355.25278785823576,371.2892181441702
0.015192367992992993,363.41093736875445,355.72884000341924,371.09303473408966
0.015349029804804805,363.61967260554394,356.1921161019451,371.0472291091428
0.015505691616616616,364.5735719654343,355.5955412659515,373.55160266491714
0.01566235342842843,364.5824847012308,356.0782935667419,373.0866758357197
0.015819015240240243,364.5071881676,356.8716899686196,372.14268636658045
0.015975677052052054,364.6614011584969,357.295319093746,372.0274832232478
0.016132338863863865,365.15353051477985,357.2357171664289,373.0713438631308
0.016289000675675677,365.36333091188027,357.13017263039194,373.5964891933686
0.016445662487487488,365.60065233107434,357.07574616363905,374.12555849850963
0.0166023242992993,366.0547799903535,357.35930915044503,374.75025083026196
0.016758986111111113,365.6429640536615,358.29953401986495,372.98639408745805
0.016915647922922925,366.7754810359361,357.7844951131431,375.76646695872904
0.017072309734734736,366.9998957818273,358.1738398557305,375.82595170792416
0.017228971546546547,366.79559358073504,358.56663082635475,375.02455633511534
0.017385633358358358,367.0656855411852,358.43575438394856,375.6956166984218
0.017542295170170173,367.5607315852679,358.3450364875089,376.7764266830269
0.017698956981981984,367.8937179587518,358.7824853918065,377.00495052569704
0.017855618793793795,367.9931164953391,359.087954192283,376.8982787983952
0.018012280605605606,367.69416406532736,359.8040862259924,375.5842419046623
0.018168942417417417,368.1768341220529,359.5222212394013,376.83144700470456
0.01832560422922923,368.65684361729683,359.2346168223153,378.0790704122784
0.018482266041041043,369.10334461985383,359.5050543324574,378.70163490725025
0.018638927852852854,368.9135194991976,360.39110719627934,377.4359318021159
0.018795589664664665,369.0175908204834,360.6837051488266,377.3514764921402
0.018952251476476476,369.58664384868655,360.48832151844,378.6849661789331
0.01910891328828829,369.9704397112826,360.3595583445185,379.5813210780467
0.019265575100100102,369.50601959867953,360.85680955913836,378.1552296382207
0.019422236911911913,369.83158530228786,360.8278864520645,378.83528415251124
0.019578898723723724,370.22986062141337,360.98821713001723,379.4715041128095
0.019735560535535535,370.57285802147754,361.0549271194897,380.09078892346537
0.01989222234734735,370.83646259681956,360.9895884041091,380.68333678953
0.02004888415915916,370.9452878903571,361.0482132920742,380.84236248864005
0.020205545970970972,370.8349712207514,361.3978237415187,380.2721186999841
0.020362207782782783,370.7547735766723,361.86614563792307,379.6434015154215
0.020518869594594594,371.538710751203,362.0879950562832,380.98942644612276
0.02067553140640641,371.81553202908,362.0233917400216,381.6076723181383
0.02083219321821822,372.0756675757555,362.30333111214264,381.8480040393684
0.02098885503003003,371.9954527965877,362.5721580518922,381.4187475412832
0.021145516841841842,372.40256530422084,362.3693916439801,382.43573896446156
0.021302178653653654,372.87004916026615,362.28869363479043,383.45140468574186
0.021458840465465468,372.92332387345897,362.66547897730914,383.1811687696088
0.02161550227727728,372.9399411314895,362.98026684063996,382.899615422339
0.02177216408908909,372.89710085820036,363.20110031942085,382.5931013969799
0.0219288259009009,372.83608153353237,363.3913430927658,382.28081997429894
0.022085487712712713,373.39034562137476,362.9496485998793,383.8310426428702
0.022242149524524527,372.71534919100577,364.1842371216553,381.2464612603562
0.02239881133633634,373.42913910764497,364.1504205409742,382.70785767431573
0.02255547314814815,373.9846733938438,363.88210671797646,384.0872400697112
0.02271213495995996,373.9707280606244,364.20508516624506,383.7363709550038
0.022868796771771772,373.98987696683855,364.4026601024983,383.5770938311788
0.023025458583583583,374.23278967226395,364.18232370327524,384.28325564125265
0.023182120395395397,374.48623114680925,363.9753574113029,384.99710488231557
0.02333878220720721,374.4772249209517,364.4370178686357,384.5174319732677
0.02349544401901902,374.7875067843376,364.85633090497714,384.7186826636981
0.02365210583083083,375.3781509186369,364.9440144112307,385.8122874260431
0.023808767642642642,375.67236480307065,364.54231717824786,386.80241242789344
0.023965429454454457,375.6631805070318,364.521311736759,386.80504927730465
0.024122091266266268,375.5169895420481,364.82947808775185,386.2045009963444
0.02427875307807808,375.4969333170474,365.3447759315792,385.64909070251565
0.02443541488988989,375.1972977608131,366.15855672519854,384.2360387964277
0.0245920767017017,375.6161675911574,365.99582097935416,385.2365142029607
0.024748738513513516,376.04087152504536,365.65288246505315,386.42886058503757
0.024905400325325327,376.36498322266624,365.4563620677536,387.27360437757886
0.025062062137137138,376.06582897894475,365.910980283391,386.2206776744985
0.02521872394894895,375.7470108083527,366.3323392943218,385.16168232238357
0.02537538576076076,376.2039310490667,366.0715982245108,386.33626387362256
0.025532047572572575,376.5310659830826,366.2458460512419,386.8162859149233
0.025688709384384386,376.80059445747673,366.32369348609717,387.2774954288563
0.025845371196196197,376.9778184198617,366.25018227180465,387.70545456791876
0.026002033008008008,376.71657179920714,366.8020879590674,386.63105563934687
0.02615869481981982,376.97453435483186,366.88512887847077,387.06393983119295
0.026315356631631634,377.2504628508124,366.98189165967375,387.5190340419511
0.026472018443443445,377.4934037664028,367.06376461761295,387.9230429151927
0.026628680255255256,377.72107615869044,367.1227345053885,388.31941781199237
0.026785342067067067,377.8805703525667,367.0723071006426,388.68883360449075
0.02694200387887888,377.73085394327376,367.39878986359633,388.0629180229512
0.027098665690690693,377.9973880883937,367.3516157458552,388.64316043093214
0.027255327502502504,378.2187826806073,367.21400870596534,389.2235566552493
0.027411989314314315,378.5147081586239,367.20823925852807,389.8211770587197
0.027568651126126126,378.6030895563546,367.550018380661,389.65616073204814
0.027725312937937938,378.55458505785293,367.89911770378643,389.21005241191943
0.027881974749749752,378.30647782490917,368.4653903084393,388.14756534137905
0.028038636561561563,378.49860030618703,368.4053252370326,388.59187537534143
0.028195298373373374,378.7224703363571,368.3987111291563,389.0462295435579
0.028351960185185186,379.05067249926486,368.43645985944306,389.66488513908666
0.028508621996996997,379.27507315523496,368.38056274938197,390.16958356108796
0.02866528380880881,379.2851028434137,368.5258234155554,390.044382271272
0.028821945620620622,379.4261666278412,368.62712147274567,390.22521178293675
0.028978607432432434,379.6693861210075,368.65606712255146,390.68270511946355
0.029135269244244245,379.8329410216857,368.5511322547317,391.1147497886397
0.029291931056056056,379.9820449545267,368.42336678409566,391.54072312495776
0.02944859286786787,379.86760633354027,368.53722572690725,391.1979869401733
0.02960525467967968,379.82303103763223,369.01798827873296,390.6280737965315
0.029761916491491493,379.8056556417831,369.57925003681675,390.0320612467495
0.029918578303303304,380.13485292775124,369.65676592191625,390.61293993358623
0.030075240115115115,380.31384468135036,369.47969545673794,391.1479939059628
0.030231901926926926,380.41998250797735,369.3494207570985,391.4905442588562
0.03038856373873874,380.6514920555785,369.73146328090866,391.57152083024835
0.030545225550550552,380.4321969501959,370.1712383892508,390.69315551114096
0.030701887362362366,380.5508166221898,370.1803236950815,390.92130954929814
0.030858549174174174,380.68975577529966,370.15618444918056,391.22332710141876
0.03101521098598599,381.14584032282517,369.99324986825445,392.2984307773959
0.031171872797797796,381.5396172412855,369.75090223492145,393.32833224764954
0.03132853460960961,381.3052365048151,369.9652298994607,392.64524311016953
0.031485196421421426,381.00300263163285,370.0644682198695,391.9415370433962
0.03164185823323323,380.77884659102244,370.29729371766507,391.2603994643798
0.03179852004504505,380.53197706539464,370.71599408938806,390.3479600414012
0.031955181856856855,381.0539310350904,370.3602503908325,391.74761167934827
0.03211184366866867,381.3713824536864,370.27555286587614,392.4672120414967
0.032268505480480485,381.6011043227771,370.28099952117185,392.9212091243823
0.03242516729229229,381.42192809851474,370.37974696718214,392.46410922984734
0.03258182910410411,381.1913045924088,370.8484645784717,391.53414460634593
0.032738490915915915,381.4768741916289,370.8348997756248,392.11884860763297
0.03289515272772773,381.77475166300223,370.5365196111833,393.0129837148212
0.03305181453953954,382.0277964824906,370.71699141640755,393.33860154857365
0.03320847635135135,382.14604664045964,371.1993756269642,393.0927176539551
0.033365138163163166,382.08960892241555,371.3951879266087,392.7840299182224
0.033521799974974974,382.06102135154055,371.438676215494,392.6833664875871
0.03367846178678679,382.3177879210756,371.2503355015279,393.3852403406233
0.033835123598598596,382.57867627159703,371.0681720188809,394.0891805243132
0.03399178541041041,382.5455484519884,371.1792014395913,393.9118954643855
0.034148447222222225,382.49208433334087,371.31797016258054,393.6661985041012
0.03430510903403403,382.3957921762632,371.4636382278605,393.32794612466597
0.03446177084584585,382.2806722277089,371.58765140562906,392.9736930497888
0.034618432657657655,382.3764751690342,371.58282605011334,393.1701242879551
0.03477509446946947,382.517277189736,371.6561845198184,393.37836985965356
0.034931756281281284,382.78407479393775,371.6243852628529,393.9437643250226
0.03508841809309309,382.8462527281505,371.3142946823978,394.37821077390316
0.03524507990490491,382.7932820956625,371.71074401339814,393.87582017792687
0.035401741716716714,382.79261308224216,372.0626298154642,393.5225963490201
0.03555840352852853,382.9827640718815,371.95194736934286,394.0135807744201
0.03571506534034034,383.18697509195715,371.8458302509829,394.5281199329314
0.03587172715215215,383.3890516724425,371.7368568915857,395.0412464532993
0.036028388963963966,383.3172604897233,371.85111551674277,394.78340546270385
0.03618505077577577,383.18514811327043,371.96405522179816,394.4062410047427
0.03634171258758759,383.09046449606655,372.10667741928006,394.07425157285303
0.0364983743993994,383.14591212289196,372.37683671057414,393.9149875352098
0.03665503621121121,383.38934769838477,372.3251014984203,394.45359389834925
0.036811698023023025,383.5178729080256,372.1756709667093,394.8600748493419
0.03696835983483483,383.64642653373966,372.2354274483172,395.05742561916213
0.03712502164664665,383.3321459586373,372.56529030471415,394.0990016125604
0.03728168345845846,383.43941193938525,372.6578416659047,394.2209822128658
0.03743834527027027,383.53695393327905,372.73299148241995,394.34091638413815
0.037595007082082084,383.8061820899763,372.5723638503549,395.04000032959766
0.03775166889389389,383.90314708960204,372.43982005699746,395.3664741222066
0.037908330705705706,383.7717248165848,372.49673828107365,395.046711352096
0.03806499251751752,383.6697689579142,372.5457774612368,394.79376045459156
0.03822165432932933,383.610368728189,372.5775520018457,394.6431854545323
0.03837831614114114,383.55889003143045,372.6192404833229,394.498539579538
0.03853497795295295,383.74653994316816,372.4230297574573,395.070050128879
0.038691639764764765,383.8090545998483,372.4408668165075,395.17724238318914
0.03884830157657658,383.8896407496966,372.5548380546617,395.2244434447315
0.03900496338838839,383.85965952516517,372.8042248311406,394.91509421918977
0.0391616252002002,383.8630072003733,372.8152114458731,394.91080295487353
0.03931828701201201,384.2227843870147,372.6928002559476,395.75276851808184
0.039474948823823824,384.49961596088707,372.71238599521797,396.28684592655617
0.03963161063563564,384.3786446046746,373.05066844295214,395.70662076639707
0.03978827244744745,384.2108433546275,373.3102703801107,395.11141632914433
0.03994493425925926,384.1117285984589,373.5146465432255,394.7088106536923
0.04010159607107107,384.0998251616258,373.63722927805424,394.56242104519737
0.040258257882882884,384.2278296142919,373.6284828504634,394.82717637812044
0.0404149196946947,384.3581736904429,373.4643133622094,395.25203401867645
0.040571581506506506,384.3843755998622,373.34619047402293,395.4225607257015
0.04072824331831832,384.33160355950474,373.32767001888965,395.33553710011984
0.04088490513013013,384.3336817355585,373.4046155436543,395.2627479274627
0.04104156694194194,384.2487660682723,373.62607826784927,394.8714538686953
0.04119822875375376,384.63613661824274,373.69074996514615,395.58152327133934
0.041354890565565565,384.88662511100733,373.6148511745225,396.15839904749214
0.04151155237737738,384.82305841773587,373.8220558303726,395.8240610050991
0.04166821418918919,384.67071750047154,373.8565875460785,395.48484745486456
0.041824876001001,384.6469083110994,373.7720050376073,395.52181158459155
0.041981537812812816,384.66970277209725,373.76321235420806,395.57619318998644
0.042138199624624624,384.8490919586528,373.95474731282457,395.7434366044811
0.04229486143643644,384.9414343859032,373.89188917192905,395.9909795998774
0.042451523248248246,385.05485841647396,373.86514692518597,396.24456990776196
0.04260818506006006,385.20471906728045,373.9080759892613,396.5013621452996
0.042764846871871875,385.24348018298525,374.19769794217365,396.28926242379686
0.04292150868368368,385.13569227962205,374.32129520331415,395.95008935592995
0.0430781704954955,385.0794199738317,374.47045894955926,395.68838099810415
0.043234832307307305,385.2065385061449,374.4396985442994,395.9733784679904
0.04339149411911912,385.43054787465564,374.31545824477934,396.54563750453195
0.043548155930930935,385.5381236594757,374.70869299265826,396.3675543262931
0.04370481774274274,385.4544799296196,374.83085828291996,396.0781015763192
0.04386147955455456,385.36007010280883,374.85170654281296,395.8684336628047
0.044018141366366365,385.3368001958398,374.8195716239499,395.85402876772974
0.04417480317817818,385.4049780619256,374.7431463820562,396.066809741795
0.044331464989989994,385.50917278566124,374.6241033317278,396.3942422395947
0.0444881268018018,385.60099194299033,374.49397718798076,396.7080066979999
0.044644788613613616,385.5103801866561,374.56581928832645,396.45494108498576
0.044801450425425424,385.4397277617762,374.656926278237,396.22252924531546
0.04495811223723724,385.32884177704693,374.79447762900816,395.8632059250857
0.04511477404904905,385.5574452862766,374.77805539219054,396.3368351803627
0.04527143586086086,385.5477341137165,374.67695067218074,396.41851755525227
0.045428097672672675,385.53445391287033,374.5716242307396,396.4972835950011
0.04558475948448448,385.5319351338755,374.4994533128249,396.56441695492606
0.0457414212962963,385.51030214918245,374.60534468704986,396.41525961131504
0.04589808310810811,385.4211946268835,374.7531329239901,396.0892563297769
0.04605474491991992,385.4132425885799,375.03911232064615,395.7873728565137
0.046211406731731734,385.51778824206855,375.23992518126573,395.79565130287136
0.04636806854354354,385.48181892385867,375.0832060737964,395.8804317739209
0.046524730355355357,385.5560317566823,374.9539084699522,396.15815504341236
0.046681392167167164,385.8223720087849,375.12636902813074,396.51837498943905
0.04683805397897898,386.11549978024874,375.3608907728896,396.8701087876079
0.04699471579079079,385.7588493623777,375.4828602603543,396.0348384644011
0.0471513776026026,385.71383218051716,375.5575327126962,395.87013164833814
0.047308039414414416,385.86229941914706,375.41661721613804,396.3079816221561
0.04746470122622622,385.82426910677174,375.3554874114538,396.2930508020897
0.04762136303803804,385.7437147974001,375.2467889269926,396.2406406678076
0.04777802484984985,385.6620126884101,375.1455127020611,396.178512674759
0.04793468666166166,385.6212220487026,375.12588397896695,396.1165601184382
0.048091348473473475,385.5247648047845,375.21716308191213,395.8323665276569
0.04824801028528528,385.34143972542256,375.2393049767086,395.44357447413654
0.0484046720970971,385.3041858811173,375.34636218021166,395.2620095820229
0.04856133390890891,385.43321535794075,375.44310696395775,395.42332375192376
0.04871799572072072,385.47818216235487,375.44209371503115,395.5142706096786
0.048874657532532534,385.71774386427626,375.28452955008476,396.15095817846776
0.04903131934434434,385.3630353230886,375.56044039812195,395.1656302480552
0.049187981156156156,385.48996252106735,375.46048885383345,395.51943618830126
0.04934464296796797,385.53362747929424,375.48507979282067,395.5821751657678
0.04950130477977978,385.5806798038116,375.55455012649014,395.6068094811331
0.04965796659159159,385.5726486301658,375.5804066563649,395.5648906039667
0.0498146284034034,385.5546602945936,375.59809263325906,395.5112279559281
0.049971290215215215,385.53592251800745,375.6142447516652,395.4576002843497
0.05012795202702703,385.4192612692354,375.53380162201995,395.30472091645083
0.05028461383883884,385.3478641867444,375.6250657394435,395.0706626340453
0.05044127565065065,385.3412743138319,375.76254671402535,394.92000191363843
0.05059793746246246,385.46021086729104,375.80980533209345,395.11061640248863
0.050754599274274274,385.62520067716815,375.8223730277416,395.4280283265947
0.05091126108608609,385.34765493849244,376.03994367252244,394.65536620446244
0.0510679228978979,385.34359968936684,376.0135395447491,394.6736598339846
0.05122458470970971,385.15226643256403,375.8650096790142,394.4395231861139
0.05138124652152152,385.1763505402547,375.70199169783166,394.65070938267775
0.051537908333333333,385.2035235192101,375.4723375426953,394.93470949572486
0.05169457014514515,385.10896830225937,375.4543382861628,394.76359831835595
0.051851231956956956,384.9758518836858,375.5010342044259,394.4506695629457
0.05200789376876877,384.9071130736362,375.5139101300588,394.3003160172136
0.05216455558058058,385.03924591819276,375.60536256666944,394.4731292697161
0.05232121739239239,385.0600247205877,375.55927232319067,394.56077711798474
0.05247787920420421,384.9347339787725,375.39434565504837,394.47512230249663
0.052634541016016015,384.9645357535217,375.1783111804501,394.7507603265933
0.05279120282782783,384.95254743512726,375.07927107206694,394.82582379818757
0.05294786463963964,384.77808318381824,375.05865346646345,394.497512901173
0.05310452645145145,384.5702063652001,375.07194394879957,394.0684687816006
0.053261188263263266,386.988301912117,377.8571614182119,396.1194424060221
0.053417850075075074,386.96947046428494,377.86809445656604,396.07084647200384
0.05357451188688689,386.95997235553955,377.86751239834933,396.05243231272976
0.053731173698698696,387.1385607766192,377.91828444444315,396.3588371087953
0.05388783551051051,387.1684458966427,377.82994462550914,396.5069471677763
0.054044497322322325,387.21726082222244,377.781232224028,396.6532894204169
0.05420115913413413,382.5321396392697,377.2029604673429,387.8613188111965
0.05435782094594595,382.48382713847946,377.24683218750016,387.72082208945875
0.054514482757757755,382.4038885996904,377.22789724331903,387.57987995606175
0.05467114456956957,382.3280824015056,377.2071447031964,387.4490200998148
0.054827806381381385,382.23665224696856,377.0920247380791,387.38127975585803
0.05498446819319319,382.1344768155111,376.95696648936945,387.31198714165276
0.05514113000500501,382.0840101859999,376.9140892967773,387.25393107522245
0.055297791816816814,382.0590738392801,376.9360784028147,387.18206927574545
0.05545445362862863,382.03570323956865,376.9664737203642,387.1049327587731
0.055611115440440444,382.0377253220128,377.0324850274806,387.042965616545
0.05576777725225225,382.16831743407664,377.0510498144327,387.2855850537206
0.055924439064064066,382.30999116524714,377.03325558265226,387.586726747842
0.056081100875875874,382.2419026317811,376.9762589166804,387.5075463468818
0.05623776268768769,382.0875807778477,376.76956438895945,387.4055971667359
0.0563944244994995,381.96318342060493,376.61836380240294,387.30800303880693
0.05655108631131131,381.8554355744247,376.4945652869279,387.21630586192146
0.056707748123123125,381.83754119917506,376.55539711521357,387.11968528313656
0.05686440993493493,381.9242837096615,376.5645338578018,387.2840335615212
0.05702107174674675,382.01842591253325,376.4844558440026,387.5523959810639
0.05717773355855856,381.9452625028409,376.44628484082745,387.4442401648543
0.05733439537037037,381.8577923679755,376.3850078611673,387.3305768747837
0.057491057182182184,381.7717467161474,376.32226924784055,387.22122418445423
0.05764771899399399,381.67905629999103,376.24997510651235,387.1081374934697
0.057804380805805806,381.58455162996785,376.1763836338947,386.992719626041
0.05796104261761762,381.49641554123883,376.1122157233938,386.8806153590839
0.05811770442942943,381.41713630865905,376.0655572032248,386.7687154140933
0.05827436624124124,381.36537224047396,376.0668017223047,386.6639427586432
0.05843102805305305,381.32373354805804,376.08974428151885,386.55772281459724
0.058587689864864866,381.231512374078,376.0223885126684,386.44063623548766
0.05874435167667668,381.136627744589,375.94771378992476,386.3255416992533
0.05890101348848849,381.04346685826386,375.87217524077323,386.2147584757545
0.0590576753003003,381.01008554691936,375.9102997565641,386.1098713372746
0.05921433711211211,380.93240680955404,375.87606598995797,385.9887476291501
0.059370998923923925,380.85066444852424,375.8368627005801,385.86446619646836
0.05952766073573574,380.7396608256997,375.7583595353825,385.72096211601684
0.05968432254754755,380.63450834996405,375.6911960110233,385.5778206889048
0.05984098435935936,380.53611194688114,375.6335387620642,385.4386851316981
0.05999764617117117,380.4474819621928,375.5797554550358,385.3152084693498
0.060154307982982984,380.36046984044987,375.5273312332311,385.1936084476686
0.06031096979479479,380.2734702818421,375.47461942377197,385.0723211399122
0.060467631606606606,380.1487920920984,375.3690338464452,384.92855033775163
0.06062429341841842,380.0246630334987,375.2656199407657,384.7837061262317
0.06078095523023023,379.9009036039959,375.1660728597418,384.63573434825
0.06093761704204204,379.7771441744931,375.0663094197513,384.48797892923494
0.06109427885385385,379.6586861904562,374.9733592200756,384.34401316083677
0.061250940665665665,379.56607623321923,374.9175139771884,384.2146384892501
0.06140760247747748,379.42093694955656,374.7698488710768,384.0720250280363
0.06156426428928929,379.24778447412496,374.61720735629433,383.8783615919556
0.0617209261011011,379.11019737007365,374.5358578820882,383.6845368580591
0.06187758791291292,375.90752881891325,374.5950043374715,377.220053300355
0.06203424972472473,375.85984390701026,374.5387859839505,377.18090183007