File: RHTT AVG/RHTT_S_DRY_Ex_avg_true_stress_strain.csv
True Strain,True Stress (MPa),Lower Bound (MPa),Upper Bound (MPa)
-0.0006306738329400226,-0.3551788440127812,-0.3551788440127812,-0.3551788440127812
-0.0004739254731262845,7.228774358212007,7.228774358212007,7.228774358212007
-0.0003172016795101898,3.881764007881741,-0.2713686335211575,8.034896649284638
-0.0001605024443928407,6.417614436755374,-2.0584077422061755,14.89363661571692
-3.827760078625078e-06,0.3645760213724986,-0.379990020588271,1.109142063333268
0.00015282238112411962,15.641150972092095,-3.5740801048225874,34.85638204900678
0.0003094479869035528,46.23972638400189,22.2368948725486,70.24255789545518
0.0004660490649442221,60.49871967074999,34.55968204642436,86.43775729507563
0.0006226256229268433,78.9485781302974,65.21447237594145,92.68268388465334
0.0007791776685291908,89.73816284094538,73.61598436450069,105.86034131739007
0.000935705209424768,98.50262389463998,83.01696801264467,113.98827977663531
0.0010922082532836973,109.07173977588805,94.75157218165651,123.39190737011958
0.0012486868077725003,121.98081731784251,113.37762638124218,130.58400825444284
0.0014051408805541008,130.73582137320386,121.23655434686547,140.2350883995423
0.0015615704792878258,141.57230776176635,129.82231611763422,153.3222994058985
0.0017179756116294089,153.75127971962544,140.52287904182924,166.97968039742165
0.0018743562852307702,165.33229399620487,156.55374760661198,174.11084038579773
0.0020307125077409054,181.85445224513575,170.92246812953937,192.78643636073213
0.002187044286804558,186.78082704604162,174.93181560783293,198.62983848425029
0.0023433516300631085,201.25500882356476,189.0900696838917,213.41994796323786
0.002499634545154355,212.0921699343446,202.1013781951175,222.08296167357176
0.002655893039712514,228.65848547174696,214.2654010247864,243.05156991870754
0.0028121271213682256,234.8161399836618,226.47794444276684,243.15433552455673
0.0029683367977483307,250.448461832533,232.30863631929856,268.5882873457675
0.0031245220764767627,262.4561296729641,247.7900172290086,277.12224211691955
0.003280682965173217,269.30670659949436,258.4339999204737,280.17941327851497
0.003436819471454043,279.32369753193115,265.55528522200086,293.09210984186143
0.003592931602932023,286.6865246671828,273.7882755376806,299.58477379668506
0.003749019367216373,295.5881639268017,284.82428915928057,306.3520386943229
0.003905082771912748,300.83922834665844,292.2130681644584,309.4653885288585
0.004061121824623021,308.6946377958116,300.6514088456958,316.7378667459275
0.00421713653294617,313.43899985771634,302.67647183433843,324.2015278810942
0.004373126904476954,319.2656390465014,310.9039213243523,327.6273567686505
0.0045290929468068,323.25761774263344,315.87194489265795,330.64329059260893
0.004685034667523581,326.54209346601607,319.9331001027894,333.1510868292428
0.0048409520742116255,330.69754480033833,323.4465083597848,337.9485812408919
0.00499684517445171,332.6292861101972,326.9210546443488,338.3375175760456
0.005152713975820848,335.4928147355134,328.95438190870016,342.03124756232654
0.0053085584858931735,336.87892016244564,331.1015675394006,342.6562727854906
0.005464378712238616,338.5091233587169,332.26562846273094,344.75261825470284
0.005620174662423787,339.8133780742325,334.02341443196707,345.603341716498
0.005775946344011764,340.7833066866833,335.63340159038074,345.93321178298595
0.005931693764562091,342.3069591054589,336.0189601451018,348.59495806581594
0.006087416931630777,342.86769530605943,337.8009771472671,347.9344134648518
0.006243115852770305,344.37048627095595,338.09766563178124,350.64330691013066
0.00639879053552941,345.01186990897605,339.3359680806709,350.68777173728114
0.0065544409874539605,345.99991507872824,339.96938715098713,352.03044300646934
0.006710067216085645,346.73965602529273,340.1403918477293,353.3389202028562
0.006865669228962849,347.201233123935,341.0637007686594,353.3387654792107
0.007021247033620441,347.61068373577797,342.12473991919376,353.09662755236224
0.0071768006375897715,348.3763916769305,342.67012895297586,354.08265440088513
0.007332330048398679,349.06361520143315,342.8973887109301,355.2298416919362
0.007487835273571268,349.5546990045581,343.4540045983092,355.655393410807
0.007643316320628797,350.29369362326867,343.74792592002734,356.83946132651005
0.007798773197088352,351.00031484435203,344.21849151895395,357.78213816975017
0.007954205910463738,351.3058165771466,344.7668729762489,357.8447601780442
0.008109614468265254,351.6139374354141,345.3268281798122,357.9010466910159
0.0082649988779997,351.9687012358397,345.9895245682297,357.9478779034497
0.008420359147170375,352.1726514249824,346.5526559206453,357.7926469293195
0.008575695283276867,353.4822793928953,346.7507163884577,360.2138423973329
0.00873100729381592,353.786968408278,347.35009307000655,360.2238437465495
0.008886295186280134,353.69669127558586,348.0165803079054,359.37680224326635
0.009041558968158836,354.0252460639212,348.33901480459826,359.71147732324414
0.009196798646937863,354.7392256985446,348.46042478311637,361.0180266139728
0.009352014230099572,355.2980060626353,348.77395605412227,361.8220560711483
0.009507205725122831,355.3186112277292,349.30010164419025,361.33712081126816
0.009662373139483028,356.48879316063477,348.832953519974,364.1446328012955
0.009817516480651852,356.8030533241352,349.66115016988886,363.9449564783816
0.009972635756098174,357.2441403606651,350.666581407505,363.82169931382515
0.010127730973286734,357.2059440001682,351.3564052124796,363.05548278785676
0.010282802139679014,357.4939791640726,351.4001445069626,363.58781382118264
0.010437849262733029,358.1809582693478,351.6069371330947,364.7549794056009
0.010592872349903321,358.9453710831319,351.76773926403706,366.12300290222674
0.010747871408640973,359.19386444342115,352.3148874001603,366.072841486682
0.010902846446393376,359.4730516958456,352.9081903191736,366.0379130725176
0.011057797470605125,360.2548659284912,352.74714941905984,367.7625824379225
0.01121272448871669,360.4209436986452,353.0667338992563,367.7751534980342
0.01136762750816531,360.53323498499464,353.3936066964652,367.67286327352406
0.01152250653638476,360.6408185193481,354.15882264138924,367.12281439730697
0.011677361580805366,361.3052549422562,354.5340875200627,368.07642236444974
0.011832192648854005,361.77319203439436,354.63414212603954,368.9122419427491
0.011986999747953883,362.22897926611256,354.69934466694133,369.75861386528385
0.012141782885525414,362.5678131520777,355.33142816665986,369.8041981374956
0.012296542068984912,362.76737099359707,355.98969361698903,369.5450483702051
0.01245127730574547,362.9358084060092,356.56136317178937,369.310253640229
0.012605988603216737,363.50055639195267,356.66698845683453,370.33412432707087
0.012760675968804924,364.2034387499066,356.3976034552224,372.00927404459077
0.012915339409912805,364.1425822852744,356.865953772151,371.41921079839784
0.013069978933939502,364.4206573319869,357.006952080965,371.8343625830087
0.01322459454828136,365.0177501273112,357.18794279340943,372.84755746121294
0.013379186260330642,365.083476613704,358.0563591896151,372.11059403779296
0.013533754077476395,365.8145755213942,358.1337910022952,373.4953600404932
0.013688298007104246,366.3333663256267,358.0911383477823,374.57559430347106
0.013842818056596392,367.0310015305015,358.31536111569295,375.74664194531
0.013997314233331618,367.1937999962501,358.8964675941782,375.49113239832195
0.014151786544685279,367.2885139141327,359.4040759386795,375.1729518895859
0.014306234998029101,367.1689958551291,359.9643169388188,374.3736747714394
0.01446065960073205,367.54685738268347,360.2680678741048,374.8256468912621
0.014615060360159018,368.2443720272844,360.09667338130146,376.39207067326737
0.014769437283671711,368.5052574320998,360.3308854639031,376.67962940029656
0.014923790378628423,368.7330390664721,360.5942643965177,376.8718137364265
0.015078119652384042,368.93201006193914,361.1332034464717,376.7308166774065
0.01523242511229005,369.20088179797983,361.6593195082304,376.7424440877293
0.015386706765694307,370.2265373438987,361.1092960690652,379.3437786187322
0.015540964619941932,370.29270443043606,361.65531764877585,378.9300912120962
0.015695198682373988,370.27333293240036,362.5170486710435,378.0296171937573
0.015849408960328357,370.4871139367539,363.0033537237976,377.97087414971014
0.016003595461139532,371.04431100638055,362.9987648100332,379.0898572027279
0.016157758192138615,371.314734455971,362.9474662536726,379.6820026582695
0.01631189716065331,371.6131972645165,362.94809336751405,380.2783011615189
0.01646601237400772,372.132140159062,363.2923042923342,380.9719760257897
0.016620103839523215,371.7707694098623,364.3042709341214,379.23726788560316
0.016774171564517135,372.9797259399007,363.83665166475777,382.1228002150435
0.016928215556303642,373.26543167523005,364.28869458862675,382.2421687618333
0.017082235822193526,373.1151044259362,364.7443651064031,381.4858437454693
0.017236232369494207,373.44735496843873,364.6673869921945,382.22732294468295
0.017390205205509712,374.0085904317004,364.6312308903382,383.38594997306257
0.017544154337540495,374.4050530468451,365.1325611666446,383.6775449270456
0.017698079772884276,374.56386130222,365.49969181578365,383.62803078865636
0.01785198151883477,374.3171745255156,366.2849783901385,382.3493706608927
0.018005859582682523,374.86621782064356,366.05435977488196,383.6780758664051
0.018159713971714734,375.4127030298243,365.81780823563986,385.0075978240087
0.018313544693215226,375.92521083175603,366.1495223897288,385.70089927378325
0.018467351754464467,375.7896719730852,367.10841104212057,384.47093290404985
0.018621135162739565,375.9534940365884,367.4629680695349,384.44402000364187
0.018774894925314055,376.59114286525374,367.3203868421903,385.8618988883172
0.018928631049458768,377.04017276295536,367.2456378975298,386.834707628381
0.01908234354244053,376.62476556919694,367.80892352408245,385.44060761431143
0.01923603241152304,377.0145419695369,367.83597114716093,386.19311279191277
0.019389697663966636,377.47855356701837,368.05596887366346,386.90113826037333
0.01954333930702832,377.8863210937869,368.1805484903098,387.5920936972639
0.01969695734796174,378.2132239652993,368.17047356172105,388.2559743688775
0.019850551794017,378.3823269966568,368.28682709623837,388.47782689707526
0.020004122652441496,378.327894279396,368.7000640829368,387.95572447585516
0.020157669930478652,378.304159312699,369.2345392849572,387.37377934044093
0.02031119363536876,379.1622651064507,369.5176314086113,388.80689880429014
0.020464693774348786,379.50301573893694,369.50841774579624,389.49761373207764
0.020618170354652358,379.8268197744912,369.8509041094749,389.8027354395075
0.02077162338350978,379.8032114271657,370.1821325151685,389.42429033916284
0.0209250528681478,380.2772100208063,370.03187971795586,390.52254032365676
0.021078458815790506,380.8129935620747,370.0062321107975,391.61975501335195
0.021231841233658004,380.9258259863106,370.44785963301484,391.4037923396064
0.02138520012896729,381.00122527830484,370.82626762514053,391.17618293146916
0.021538535508932043,381.0158777264307,371.10877427291297,390.9229811799484
0.021691847380762633,381.01193905505534,371.3600885893416,390.663789520769
0.021845135751666106,381.6368535116412,370.9655686043654,392.30813841891705
0.02199840062884619,381.00533971779754,372.2844773781901,389.726202057405
0.022151642019503093,381.7935079420076,372.306957108719,391.28005877529614
0.022304859930834364,382.4200746523976,372.08963980514534,392.75050949964987
0.022458054370033585,382.4644017074118,372.47696021364453,392.4518432011791
0.022611225344291257,382.5425754578931,372.73611047947537,392.3490404363109
0.022764372860794576,382.8496712714816,372.5677887145782,393.131553828385
0.022917496926727437,383.16761604367247,372.41307796776886,393.9221541195761
0.02307059754927043,383.2170673149412,372.94253405691586,393.4916005729665
0.023223674735600632,383.5933056690167,373.4287924027397,393.7578189352937
0.023376728492892487,384.25663467074605,373.57570886241336,394.9375604790788
0.02352975882831648,384.61666084642906,373.22162050385526,396.0117011890028
0.023682765749040022,384.6661099581091,373.2572215178315,396.0749983983867
0.023835749262227247,384.57524463581495,373.6299280548089,395.520561216821
0.02398870937503899,384.6135306426276,374.2148915347878,395.01216975046736
0.024141646094632808,384.3653993971642,375.1057929742621,393.6250058200663
0.02429455942816275,384.85334919495835,374.99641828138067,394.71028010853604
0.024447449382780238,385.3474087248124,374.70233003989324,395.9924874097316
0.024600315965632766,385.7385037982611,374.55819906648804,396.9188085300341
0.024753159183864764,385.49081415246906,375.08146400791406,395.900164297024
0.02490597904461739,385.22287094857126,375.570773432558,394.8749684645845
0.02505877555502853,385.75025092415143,375.360806245516,396.1396956027868
0.025211548722232788,386.14467507231416,375.59685241587937,396.692497728749
0.025364298553361295,386.4801154243581,375.73407638867576,397.2261544600404
0.025517025055542552,386.72095006965526,375.7160541832939,397.7258459560166
0.02566972823590116,386.5119685337937,376.33968795758534,396.68424911000216
0.025822408101558655,386.8356961538636,376.4823649987329,397.18902730899424
0.02597506465963333,387.1779433201797,376.63915101604886,397.71673562431045
0.026127697917240206,387.48641611318527,376.7806833644902,398.1921488618804
0.026280307881491046,387.7792899213911,376.8987284169675,398.6598514258148
0.02643289455949437,388.0022306899586,376.9044644096808,399.0999969702364
0.026585457958355214,387.90768007538566,377.29724948519674,398.51811066557457
0.026737998085176018,388.2406129401553,377.3063543718872,399.1748715084234
0.026890514947055324,388.52725947016506,377.22254677675323,399.83197216357695
0.02704300855108864,388.8905492939789,377.274147589211,400.50695099874673
0.02719547890436823,389.0406660476072,377.6828766087987,400.3984554864157
0.02734792601398312,389.05012939267317,378.0992358717152,400.0010229136312
0.027500349887019084,388.85440948729007,378.7389330171759,398.96988595740424
0.02765275053055844,389.1111849992319,378.73490825869766,399.4874617397662
0.02780512795168093,389.40066338819173,378.78582270980905,400.0155040665744
0.027957482157462403,389.79750207413167,378.88235570014854,400.7126484481148
0.02810981315497569,390.0876828487009,378.88258496384515,401.29278073355675
0.028262120951290385,390.15741796087343,379.0897207346373,401.22511518710957
0.02841440555347287,390.36196696942943,379.2516723221191,401.47226161673973
0.028566666968586278,390.67167621552085,379.33920656928035,402.0041458617613
0.028718905203690314,390.89947602618565,379.28896872324435,402.5099833291269
0.028871120265842105,391.1124528178739,379.2151986433754,403.00970699237234
0.029023312162094902,391.0541728161482,379.39012844399247,402.7182171883039
0.02917548089949896,391.0677886047092,379.9428598031079,402.1927174063105
0.029327626485101312,391.10939984799006,380.5786368134005,401.64016288257955
0.02947974892594577,391.5079472908849,380.71637081849696,402.29952376327276
0.029631848229072943,391.7518748792446,380.591886015259,402.91186374323024
0.029783924401520005,391.92080211020175,380.51555622219433,403.3260479982091
0.029935977450321567,392.2189441841554,380.96707141903767,403.47081694927317
0.030088007382508386,392.05258421273106,381.47820235817704,402.6269660672851
0.030240014205108228,392.2344449297793,381.5455582969307,402.9233315626279
0.03039199792514566,392.4372893239961,381.5786672691303,403.29591137886194
0.030543958549642033,392.9671589768685,381.468668576309,404.46564937742806
0.03069589608561551,393.4329216572513,381.27673032625944,405.58911298824324
0.030847810540081053,393.25097080348166,381.5556984087182,404.9462431982451
0.030999701920050214,392.99895700664115,381.71602069036095,404.2818933229213
0.031151570232531987,392.82739687306963,382.01418818962935,403.6406055565099
0.031303415484531534,392.6323307658892,382.5042140584583,402.76044747332014
0.03145523768305104,393.2305786985869,382.1951795446226,404.2659778525512
0.031607036835089516,393.61792066674326,382.165783533835,405.07005779965147
0.03175881294764276,393.91480164897405,382.2294139835386,405.6001893144095
0.031910566027703396,393.7895979260578,382.38937222426995,405.18982362784567
0.032062296082260654,393.61121453460913,382.9313858748868,404.29104319433145
0.032214003118301235,393.9658513719835,382.97547477323366,404.9562279707333
0.03236568714280799,394.333290426547,382.7253750149938,405.9412058381002
0.03251734816276084,394.65450836077883,382.9698606633587,406.33915605819897
0.032668986185136514,394.83653459308175,383.5263413141086,406.1467278720549
0.03282060121690856,394.83808151482094,383.78683968491396,405.8893233447279
0.03297219326504736,394.8683944875216,383.88996922255933,405.8468197524838
0.03312376233651993,395.19366293198436,383.7534757390478,406.63385012492085
0.033275308438290734,395.5232730694347,383.62330948264577,407.4232366562237
0.03342683157732045,395.54895464467614,383.79624520373335,407.3016640856189
0.03357833176056679,395.55359508811574,383.9979022693401,407.1092879068914
0.03372980899498432,395.51392152102574,384.20673883944625,406.8211042026053
0.03388126328752442,395.45474115281615,384.3932198975159,406.5162624081164
0.03403269464513536,395.613749424546,384.44644109047135,406.7810577586206
0.034184103074761975,395.81935164021326,384.5805634466576,407.05813983376885
0.03433548858334664,396.1553948029953,384.60587771703587,407.70491188895477
0.03448685117782791,396.2797221092498,384.34312589815573,408.2163183203439
0.03463819086514143,396.28486191018493,384.811718887662,407.7580049327079
0.03478950765221965,396.34413830164675,385.2342949386337,407.45398166465986
0.034940801545991926,396.6010197412207,385.177964807124,408.0240746753174
0.03509207255338443,396.8725229449338,385.12632837492987,408.6187175149377
0.03524332068132022,397.1418791271588,385.07169999439935,409.2120582599182
0.035394545936718966,397.1275638472481,385.24831214326383,409.0068155512324
0.03554574832649787,397.05072215427225,385.42359344676237,408.67785086178213
0.03569692785757036,397.012628051828,385.6296713419737,408.3955847616823
0.0358480845368469,397.13011507315264,385.9679859145007,408.2922442318046
0.035999218371234876,397.44249812126174,385.9726915761878,408.9123046663357
0.0361503293676385,397.63581703194797,385.87608937785177,409.39554468604416
0.036301417532958874,397.8292056791875,385.99636067350013,409.6620506848748
0.03645248287409375,397.56336017520715,386.3967847720658,408.7299355783485
0.03660352539793841,397.73467872080687,386.55115335720524,408.91820408440844
0.03675454511138436,397.89594283854086,386.6874979111595,409.1043877659223
0.036905542021320195,398.2353782237958,386.5792245078971,409.8915319396946
0.037056516134631394,398.3961315858526,386.50004482669067,410.2922183450145
0.037207467458200326,398.319870276431,386.6174678226293,410.0222727302327
0.037358395998906224,398.2741558424949,386.72672969273157,409.82158199225825
0.03750930176362502,398.27259163886436,386.8180824053279,409.7271008724008
0.03766018475923014,398.27923437180186,386.9197394948638,409.63872924873993
0.0378110449925913,398.5342043994001,386.7743429983328,410.29406580046737
0.03796188247057529,398.65925627888055,386.8512146690485,410.4672978887126
0.03811269720004579,398.80310128566447,387.0279607572218,410.57824181410706
0.03826348918786341,398.8320914912235,387.34543997171573,410.3187430107312
0.03841425844088561,398.8957064165761,387.4152610254498,410.37615180770246
0.03856500496596679,399.3297661000978,387.34644274372147,411.3130894564742
0.03871572876995802,399.67771862372297,387.42518835838445,411.9302488890615
0.0388664298597079,399.6121893843004,387.8352672820468,411.38911148655404
0.039017108242061324,399.497929067285,388.1636411254248,410.83221700914515
0.03916776392386027,399.4550463455348,388.4346645442651,410.47542814680446
0.03931839691194366,399.5028412012264,388.62067852367693,410.38500387877576
0.03946900721314729,399.69617266468447,388.67011466544767,410.7222306639213
0.039619594834303905,399.8919784141417,388.5578435955774,411.22611323270604
0.03977015978224292,399.9794576243396,388.49343587098343,411.4654793776958
0.03992070206379132,399.98475462419566,388.5326502008798,411.4368590475116
0.040071221685772374,400.0471278516304,388.6712278253093,411.42302787795154
0.04022171865500646,400.0189375232219,388.96027797033446,411.0775970761093
0.040372192978310906,400.48246416160123,389.08614696537205,411.87878135783035
0.04052264466249993,400.8035693726229,389.065652458515,412.54148628673084
0.040673073714384715,400.7976609632663,389.3399896807941,412.25533224573854
0.040823480140773125,400.69925934959025,389.4345239119878,411.96399478719263
0.04097386394847059,400.7347175553795,389.4049728009507,412.06446230980833
0.04112422514427887,400.8187284444675,389.4543667866946,412.1830901022404
0.04127456373499683,401.06593982096206,389.7125271056684,412.4193525362557
0.041424879727420275,401.2224790143981,389.7055948166632,412.73936321213296
0.04157517312834197,401.40102369039187,389.7362919015903,413.06575547919346
0.0417254439445516,401.6175930233076,389.83962048646276,413.3955655601524
0.041875692182835565,401.71835862139756,390.20020519447763,413.23651204831754
0.04202591784997787,401.66629724019833,390.3877299258709,412.9448645545258
0.04217612095275881,401.6679368817709,390.6019612257148,412.73391253782705
0.04232630149795584,401.8608786021364,390.62853612006086,413.0932210842119
0.04247645949234337,402.1549552260876,390.55756524990306,413.7523452022722
0.04262659494269274,402.32759798591707,391.0265655837779,413.62863038805625
0.04277670785577226,402.30069772306734,391.21277262853084,413.38862281760385
0.04292679823834719,402.26253293876493,391.2932570053305,413.2318088721994
0.04307686609717951,402.29860994052353,391.3184325145738,413.2787873664733
0.043226911439028834,402.4301671117012,391.2973511158547,413.5629831075477
0.043376934270651056,402.5993591823288,391.23173865298463,413.9669797116729
0.04352693459879926,402.75565776745066,391.15451273163075,414.35680280327057
0.043676912430223494,402.7214096184432,391.2882311123388,414.1545881245476
0.04382686777167077,402.70798661708494,391.4420999874337,413.97387324673616
0.04397680062988505,402.65249909390405,391.64452982014984,413.6604683676583
0.04412671101160707,402.95178231329555,391.68608267975117,414.21748194683994
0.04427659892357516,403.00203362994586,391.63911421307927,414.3649530468124
0.04442646437252399,403.0485507414047,391.5877005617053,414.50940092110415
0.04457630736518541,403.1063156705411,391.57092081916096,414.6417105219212
0.04472612790828825,403.1440912938507,391.7403255782245,414.5478570094769
0.04487592600855831,403.11128864949455,391.9535833639593,414.26899393502975
0.04502570167271837,403.1633511647562,392.3114429735667,414.0152593559457
0.04517545490748797,403.3331075568404,392.58028998580176,414.08592512787897
0.04532518571958429,403.35586632600996,392.4750898825583,414.2366427694617
0.045474894115720844,403.49392217104275,392.3985379572033,414.58930638488215
0.04562458010260833,403.83309746339364,392.6377901729784,415.0284047538089
0.045774243686954444,404.2003984010765,392.94206443650785,415.4587323656451
0.04592388487546389,403.88747685194517,393.1285705626029,414.6463831412874
0.04607350367483832,403.90077072820765,393.26558774913434,414.53595370728095
0.04622310009177642,404.1166882886047,393.1768413402253,415.05653523698413
0.04637267413297364,404.1373027657517,393.1716234750629,415.1029820564405
0.04652222580512305,404.1133562794085,393.11655249134293,415.11016006747406
0.046671755114914115,404.08818191428,393.0692243302499,415.1071394983102
0.046821262069033476,404.10585449769417,393.1074256861776,415.1042833092108
0.046970746674164794,404.0651706141653,393.2618624249125,414.86847880341816
0.047120208936988726,403.9333974726414,393.34385482266816,414.52294012261467
0.047269648864182945,403.9547086563318,393.51487976438307,414.3945375482804
0.04741906646242191,404.1503664285221,393.67512504503264,414.6256078120115
0.04756846173837772,404.25790659137164,393.73288003001846,414.78293315272487
0.04771783469871886,404.56956649986387,393.62643240910273,415.512700590625
0.04786718535011104,404.25789337152077,393.97466428438486,414.54112245865673
0.04801651369921695,404.451435533441,393.928632304457,414.97423876242493
0.048165819752696355,404.5576466794056,394.01325699499637,415.1020363638148
0.048315103517205985,404.6674265519748,394.14499037373463,415.189862730215
0.048464364999399406,404.719402334474,394.23096594256305,415.20783872638503
0.04861360420592783,404.7609224263692,394.30837204681194,415.2134728059264
0.048762821143438856,404.8016499905455,394.3841731851195,415.21912679597153
0.04891201581857733,404.7395395084318,394.35854201425565,415.120537002608
0.049061188237985096,404.72493273099616,394.5132271183399,414.9366383436524
0.04921033840830107,404.7783797510689,394.716488912018,414.84027059011976
0.04935946633616116,404.96370251102184,394.82500636006694,415.1023986619768
0.04950857202819812,405.1974532075994,394.89708696907144,415.4978194461273
0.04965765549104234,404.966190007977,395.1846114236313,414.7477685923227
0.049806716731320644,405.0222969275018,395.21576999078604,414.82882386421767
0.0499557557556571,404.88153133057557,395.1185387067327,414.6445239544185
0.050104772570672786,404.9671915616235,395.0060283518846,414.9283547713625
0.050253767182985846,405.05610740402017,394.82339645667315,415.2888183513672
0.050402739599211474,405.01701087768504,394.8632889129959,415.17073284237415
0.050551689825961664,404.93732407753384,394.97122542903674,414.9034227260309
0.05070061786984612,404.9253213212133,395.04359767679784,414.8070449656288
0.05084952373747095,405.12464706259715,395.1986493786426,415.0506447465517
0.05099840743543952,405.20683398311354,395.208990654141,415.2046773120861
0.051147268970352246,405.135292450013,395.0942447802753,415.1763401197507
0.051296108348806595,405.226967400352,394.92564938859715,415.5282854121069
0.0514449255773971,405.2746554458641,394.8801569477463,415.66915394398194
0.05159372066271534,405.1512610485351,394.9172082821313,415.38531381493885
0.051742493611349735,404.99262506156094,394.9899619174259,414.99528820569606
0.05189124442988642,407.5997587159388,397.98228282912953,417.2172346027481
0.052039973124907934,407.6405476211773,398.0529956744012,417.2280995679534
0.052188679702994116,407.6911639942508,398.1115799330031,417.2707480554986
0.052337364170721844,407.939970031172,398.2242774298418,417.6556626325022
0.052486026534665074,408.032115423981,398.1903825324339,417.8738483155281
0.05263466680139484,408.14422303788604,398.19822901738314,418.090217058389
0.05278328497747902,403.26582501377857,397.6477981534998,408.88385187405726
0.0529318810694832,403.27481452879306,397.7531479439736,408.79648111361246
0.05308045508396941,403.2504387912577,397.79228094333513,408.70859663918026
0.05322900702749698,403.2303962674846,397.82949104393936,408.63130149102983
0.05337753690662228,403.1938494082328,397.7671532583816,408.62054555808396
0.053526044727898806,403.14593780149613,397.6837448235068,408.60813077948546
0.0536745304978771,403.15255426449977,397.697558095409,408.6075504335906
0.05382299422310459,403.1860969661704,397.7798111945809,408.5923827377599
0.05397143591012641,403.2212844293478,397.87094355683774,408.57162530185786
0.05411985556548417,403.2832693674985,397.99968207713994,408.5668566578571
0.054268253195716744,403.4809950336083,398.07834877321187,408.88364129400463
0.05441662880736013,403.69046296975085,398.11862890961,409.2622970298918
0.0545649824069474,403.67844933226075,398.1175025207971,409.23939614372443
0.05471331400100871,403.575331471545,397.9582417390092,409.19242120408074
0.054861623596071336,403.50377732960675,397.8575396849826,409.1500149742309
0.055009911198659424,403.4497752700373,397.7857419442086,409.1138085958661
0.055158176815294835,403.4906883094505,397.90900572922567,409.07237088967537
0.05530642045249593,403.6421827426341,397.9776538780495,409.30671160721863
0.055454642116778356,403.80152598507107,397.95200301221837,409.65104895792376
0.05560284181465488,403.78402695618206,397.9706302145655,409.59742369779855
0.05575101955263536,403.7513780108578,397.9648147133595,409.5379413083562
0.05589917533722677,403.720208037147,397.95743434809674,409.4829817261973
0.05604730917493298,403.6819832834657,397.9399279429498,409.42403862398163
0.0561954210722556,403.64181036199915,397.92102656361925,409.36259416037905
0.056343511035692725,403.6083455408929,397.91207188794397,409.30461919384186
0.05649157907173976,403.5842247009651,397.9216241028505,409.2468252990797
0.05663962518688924,403.5891976141426,397.9818562570426,409.1965389712427
0.05678764938763081,403.6048713202996,398.06505468009783,409.1446879605013
0.05693565168045125,403.5669859877639,398.0526715930944,409.0813003824335
0.057083632071834214,403.5262518416797,398.0325185008426,409.0199851825168
0.05723159056826114,403.48731323938284,398.0114273045775,408.9631991741882
0.05737952717620994,403.5116554652889,398.1106881816258,408.9126227489521
0.05752744190215589,403.4890667633032,398.13331807386186,408.84481545274457
0.057675334752571354,403.4621488376733,398.1506726715472,408.77362500379934
0.05782320573392585,403.40420218397105,398.1263756804214,408.6820286875207
0.05797105485268603,403.3524211190505,398.1140705320191,408.5907717060819
0.05811888211531545,403.3077674700658,398.1118194799756,408.50371546015606
0.058266687528275435,403.27343537167343,398.11365673188203,408.4332140114649
0.05841447109802383,403.2407906877844,398.1169179722625,408.3646634033062
0.05856223283101581,403.20813206177206,398.1198578545511,408.296406268993
0.058709972733703694,403.1354892080199,398.06671030159987,408.2042681144399
0.05885769081253695,403.06338971147716,398.0158329938994,408.1109464290549
0.05900538707396218,402.99164341787446,397.9690251381311,408.01426169761777
0.05915306152442312,402.9198583475188,397.9219565485442,407.91776014649344
0.05930071417036047,402.8536598338637,397.8820861910332,407.82523347669417
0.05944834501821269,402.8148554472797,397.881564380324,407.7481465142353
0.059595954074414745,402.72026701738696,397.7835667710962,407.65696726367776
0.05974354134539898,402.5958953086174,397.6802401172927,407.5115504999421
0.059891106837594896,402.50922984612583,397.65255788864107,407.3659018036106
0.06003865055742913,399.1677799805314,397.77403965010143,400.56152031096144
0.06018617251132549,399.17602732543384,397.7730185652741,400.5790360855935