File: RHTT AVG/RHTT_L_LUB_Ex_avg_eng_stress_strain.csv
Engineering Strain,Engineering Stress (MPa),Lower Bound (MPa),Upper Bound (MPa)
-0.000386139,2.0850416666666667,2.0850416666666667,2.0850416666666667
-2.310168468468469e-05,0.6347142889519589,-0.6485148256527441,1.917943403556662
0.00033993563063063065,27.863777620082242,11.43263922302188,44.294916017142604
0.000702972945945946,58.32846975124344,42.32481629902581,74.33212320346107
0.0010660102612612614,85.89287843278055,70.25910571130932,101.52665115425178
0.0014290475765765768,116.01435226717658,100.62221140831294,131.40649312604023
0.001792084891891892,138.27956577681175,124.74446573389945,151.81466581972407
0.0021551222072072073,161.5953574869158,152.16692868706986,171.02378628676172
0.0025181595225225225,190.36249660936244,178.11933388696497,202.6056593317599
0.0028811968378378377,213.9486315937454,202.83517552629047,225.06208766120034
0.0032442341531531533,241.92165624492924,228.49328776764332,255.35002472221515
0.003607271468468469,264.47948345160364,248.08057138506314,280.87839551814415
0.003970308783783784,285.1943045422229,276.8244688901865,293.56414019425927
0.0043333460990991,293.9826992706537,286.00389246215957,301.96150607914785
0.004696383414414415,302.7110019535582,299.3075774851307,306.1144264219857
0.00505942072972973,307.29121825253117,304.1916566106476,310.3907798944147
0.005422458045045046,310.9606169502874,308.7194249807448,313.20180891982994
0.005785495360360361,313.2194980999792,311.1538857344795,315.2851104654789
0.006148532675675676,315.0486026209658,312.95595078993637,317.1412544519953
0.0065115699909909916,316.56962277862795,314.43143122431206,318.7078143329438
0.006874607306306307,317.81591903404035,315.77304064976204,319.85879741831866
0.007237644621621622,318.80967950705286,316.8738010045721,320.7455580095336
0.007600681936936938,319.58614763698716,317.6727724880489,321.4995227859254
0.007963719252252251,320.3094637687581,318.37251156054396,322.2464159769723
0.008326756567567567,320.8165699368545,318.94448647237454,322.6886534013344
0.008689793882882883,321.32760492505287,319.3220079332061,323.3332019168996
0.009052831198198198,321.78217277645405,319.8355072726945,323.7288382802136
0.009415868513513514,322.08029878892967,320.135957379765,324.02464019809435
0.00977890582882883,322.5360439502389,320.6511438263593,324.42094407411844
0.010141943144144143,322.7998582530054,320.8999084976052,324.6998080084056
0.010504980459459459,323.05317718156067,321.1840987680528,324.9222555950685
0.010868017774774775,323.4854055927515,321.579911898382,325.39089928712093
0.01123105509009009,323.65785719245685,321.7376288231406,325.5780855617731
0.011594092405405406,323.81030416421066,321.94996884054257,325.67063948787876
0.011957129720720721,324.0975989200855,322.2876690213034,325.9075288188676
0.012320167036036037,324.32408337000845,322.49297663989626,326.15519010012065
0.01268320435135135,324.62485404817807,322.69886672201926,326.55084137433687
0.013046241666666666,324.91311271231973,323.1142320440411,326.71199338059836
0.013409278981981982,325.0415993341552,323.26984617555746,326.8133524927529
0.013772316297297298,325.1813314830993,323.34398531390303,327.0186776522956
0.014135353612612613,325.4404596746116,323.559284438494,327.3216349107292
0.014498390927927929,325.7133308785282,323.94479915582065,327.4818626012358
0.014861428243243243,325.92021848833673,324.1867094405678,327.65372753610563
0.015224465558558558,326.1777007959874,324.42734327291214,327.92805831906264
0.015587502873873876,326.342862511875,324.73574070481374,327.9499843189363
0.015950540189189188,326.51767120971743,324.8766309853267,328.15871143410817
0.016313577504504503,326.80618461505094,325.15289373178376,328.4594754983181
0.01667661481981982,327.0199240080824,325.4363560341384,328.6034919820264
0.017039652135135135,327.20035725549087,325.578806586782,328.82190792419976
0.01740268945045045,327.3529684051317,325.72665995616615,328.9792768540973
0.017765726765765766,327.49243494304574,325.8518394632478,329.13303042284366
0.01812876408108108,327.69774491685814,326.1087691313915,329.28672070232477
0.018491801396396397,327.9833926495682,326.4151413760953,329.5516439230411
0.018854838711711713,328.1988930549404,326.5662581698019,329.8315279400789
0.019217876027027028,328.3860326047642,326.6680680807623,330.1039971287661
0.019580913342342344,328.54933587635907,326.9486765339718,330.1499952187463
0.01994395065765766,328.78674247564203,327.1833869385046,330.39009801277945
0.020306987972972975,328.96371769639757,327.3198833271354,330.6075520656597
0.020670025288288287,329.19110050014297,327.5479231039827,330.8342778963032
0.021033062603603603,329.3637875382168,327.6933177419262,331.0342573345074
0.02139609991891892,329.5326953028328,327.9531411560285,331.1122494496371
0.021759137234234234,329.74598573852444,328.1507310713513,331.3412404056976
0.02212217454954955,329.95706384541984,328.3825805673106,331.5315471235291
0.022485211864864865,330.27915107303124,328.6045507358498,331.9537514102127
0.02284824918018018,330.45418548588646,328.82056546485995,332.08780550691296
0.023211286495495496,330.59669103535424,329.0641933264224,332.12918874428607
0.023574323810810812,330.73139285422246,329.1991581492833,332.26362755916165
0.023937361126126128,331.05076719939973,329.4157701125473,332.68576428625215
0.024300398441441443,331.29832982743346,329.68487392404376,332.91178573082317
0.02466343575675676,331.38780263414395,329.7997246254575,332.9758806428304
0.025026473072072074,331.6022507733628,330.045016101848,333.15948544487765
0.025389510387387387,331.7788711689069,330.234319884512,333.3234224533018
0.025752547702702702,332.00806668799345,330.4499299310293,333.5662034449576
0.026115585018018018,332.3255273824091,330.76339596729593,333.8876587975223
0.026478622333333333,332.5205443292397,330.9639944339578,334.07709422452166
0.02684165964864865,332.68135162636696,331.09875700014993,334.263946252584
0.027204696963963965,332.9088562316844,331.4200764817233,334.3976359816455
0.02756773427927928,333.05011244050326,331.59927496018474,334.50094992082177
0.027930771594594596,333.3119441110885,331.881467766814,334.742420455363
0.02829380890990991,333.4948961360632,332.0587337114844,334.93105856064193
0.028656846225225227,333.71120744626694,332.29257726749466,335.1298376250392
0.029019883540540543,333.97951012214764,332.55247646835755,335.40654377593773
0.02938292085585586,334.0993563039733,332.6444845060432,335.5542281019034
0.029745958171171174,334.34647397114105,332.9147644721665,335.7781834701156
0.030108995486486486,334.502155987629,333.12203743270965,335.8822745425484
0.0304720328018018,334.6802064040018,333.1630038453633,336.19740896264034
0.030835070117117117,334.84239568124354,333.3971826723917,336.2876086900954
0.031198107432432433,335.01642948877463,333.61706727081764,336.4157917067316
0.03156114474774775,335.30180740277956,333.9102814840784,336.69333332148074
0.031924182063063064,335.4962624587956,334.0658473331657,336.92667758442553
0.032287219378378376,335.6075567923248,334.1740741534601,337.04103943118946
0.032650256693693695,335.7911498602374,334.3765254898471,337.2057742306277
0.03301329400900901,336.01849430358953,334.57144038356336,337.4655482236157
0.033376331324324326,336.17956860404894,334.7110638007729,337.648073407325
0.03373936863963964,336.37243295602417,334.94193316873856,337.8029327433098
0.03410240595495496,336.6213483258648,335.2943668649613,337.9483297867683
0.03446544327027027,336.7371601245592,335.37841241469437,338.095907834424
0.03482848058558559,337.0287515394822,335.5576610389382,338.4998420400262
0.0351915179009009,337.1439547086032,335.7646951459514,338.523214271255
0.03555455521621622,337.23346111530526,335.9227164848442,338.5442057457663
0.03591759253153153,337.39836076278687,336.03281528805803,338.7639062375157
0.03628062984684685,337.6455031375634,336.1767263368594,339.11427993826743
0.03664366716216216,337.8035314491804,336.27451841998857,339.33254447837226
0.037006704477477476,338.0011355228369,336.538267735165,339.46400331050876
0.037369741792792795,338.1797717249778,336.7854403492128,339.5741031007428
0.03773277910810811,338.280532488778,336.9059362313213,339.65512874623477
0.038095816423423426,338.40080827892416,337.0006790163108,339.8009375415375
0.03845885373873874,338.6024691107513,337.1143011601216,340.090637061381
0.03882189105405406,338.88778477694797,337.42393827512524,340.3516312787707
0.03918492836936937,339.0505083729352,337.5495132021287,340.5515035437417
0.03954796568468469,339.164148006067,337.63004522032355,340.6982507918105
0.039911003,339.3259935557769,337.8068545226557,340.8451325888981
0.04027404031531532,339.4211339420372,337.9885047857712,340.8537630983032
0.04063707763063063,339.547663654941,338.08513005147574,341.01019725840627
0.04100011494594595,339.758345365944,338.3673220710755,341.14936866081257
0.04136315226126126,339.892357324314,338.4232246800018,341.3614899686262
0.041726189576576575,340.0635400182044,338.5321949334984,341.5948851029104
0.042089226891891894,340.21719055369255,338.73760421516016,341.69677689222493
0.042452264207207206,340.30669743265423,338.9167105156115,341.69668434969697
0.042815301522522525,340.5200299404102,339.1281561490465,341.9119037317739
0.04317833883783784,340.6284979065225,339.05270955157005,342.204286261475
0.043541376153153157,340.75473906798004,339.23673319468986,342.2727449412702
0.04390441346846847,340.95817286224974,339.5157070842416,342.40063864025785
0.04426745078378379,341.1238142794669,339.7149681944815,342.5326603644523
0.0446304880990991,341.2333621890293,339.7847046245685,342.6820197534901
0.04499352541441442,341.37675652350543,339.89632951349626,342.8571835335146
0.04535656272972973,341.5304302801609,340.02516088365485,343.0356996766669
0.04571960004504505,341.6130346188055,340.1202607925699,343.1058084450411
0.04608263736036036,341.7816017430095,340.29223366328785,343.27096982273116
0.046445674675675674,341.9114972256833,340.47529469905663,343.34769975231
0.046808711990990994,342.070559312634,340.5692134277618,343.57190519750617
0.047171749306306306,342.2965850704355,340.7619577531974,343.83121238767365
0.047534786621621625,342.4355454005471,340.9751564952427,343.8959343058515
0.04789782393693694,342.51685138711355,341.09528070111025,343.93842207311684
0.048260861252252256,342.67529250809355,341.2796898660298,344.0708951501573
0.04862389856756757,342.82874546670826,341.43386326914055,344.22362766427597
0.04898693588288289,342.92802768662466,341.49054602957546,344.36550934367386
0.0493499731981982,343.0975463709002,341.6302885894533,344.5648041523471
0.04971301051351352,343.25193082109803,341.7422320766125,344.7616295655836
0.05007604782882883,343.3509753541408,341.83746117955496,344.86448952872666
0.05043908514414415,343.47069533648494,341.99978061348304,344.94161005948683
0.05080212245945946,343.5785348935799,342.1090782026255,345.0479915845343
0.051165159774774774,343.62623152950147,342.1450708973902,345.1073921616127
0.05152819709009009,343.7240688159407,342.2186149211595,345.22952271072194
0.051891234405405405,343.90363196332856,342.3692372968886,345.4380266297685
0.052254271720720724,343.9564632157214,342.41221425763354,345.50071217380923
0.052617309036036036,344.03356714507464,342.55482098209836,345.5123133080509
0.052980346351351355,344.15318820446174,342.67216564210867,345.6342107668148
0.05334338366666667,344.2385281342802,342.72811670192567,345.74893956663476
0.05370642098198199,344.34421810047127,342.81200336841357,345.87643283252896
0.0540694582972973,344.4531749011325,342.9493718576959,345.95697794456913
0.05443249561261262,344.55443152026436,343.0870846596798,346.0217783808489
0.05479553292792793,344.71023319483044,343.2502367827792,346.17022960688166
0.05515857024324325,344.7700682905617,343.31673446384406,346.22340211727936
0.05552160755855856,344.867406098388,343.3767376635674,346.35807453320865
0.05588464487387387,345.0346630116231,343.5140947880677,346.55523123517844
0.05624768218918919,345.11619766283417,343.6019687728418,346.6304265528265
0.056610719504504504,345.2531729439632,343.7264647308444,346.779881157082
0.056973756819819824,345.31761807796136,343.84718941579627,346.78804674012645
0.057336794135135136,345.4183378117833,343.94450067836925,346.8921749451974
0.057699831450450455,345.4463002475111,343.98669949937846,346.9059009956437
0.05806286876576577,345.49126892894174,344.05915677605117,346.9233810818323
0.058425906081081086,345.56561211515225,344.08135947964394,347.04986475066056
0.0587889433963964,345.7396135607984,344.24926421396043,347.2299629076363
0.05915198071171172,345.84862503338957,344.35352591810863,347.3437241486705
0.05951501802702703,345.9945651284155,344.42238889691976,347.56674135991125
0.05987805534234235,345.9977983093597,344.33978983927005,347.6558067794494
0.06024109265765766,346.0419006267046,344.4583207900723,347.6254804633369
0.06060412997297297,346.1561274088934,344.63204574256235,347.6802090752244
0.06096716728828829,346.275758641348,344.6736527837815,347.87786449891445
0.061330204603603604,346.2999023040923,344.7217513033538,347.8780533048308
0.06169324191891892,346.36488116861403,344.7488861584042,347.98087617882385
0.062056279234234235,346.4802271490642,344.850180592355,348.1102737057734
0.062419316549549554,346.5491796759008,345.0456297705609,348.0527295812407
0.06278235386486487,346.5515309039878,344.98507943016483,348.11798237781073
0.06314539118018019,346.60132316468275,344.93283012188374,348.26981620748177
0.06350842849549551,346.6859641337336,345.03272406832644,348.33920419914074
0.06387146581081082,346.76267298402826,345.11426826765916,348.41107770039736
0.06423450312612614,346.87810960074347,345.1996925717303,348.55652662975666
0.06459754044144145,346.86779038207385,345.20150001417625,348.53408074997145
0.06496057775675676,346.90735688808786,345.25818750511496,348.55652627106076
0.06532361507207209,347.07211152303023,345.4156264126986,348.72859663336186
0.0656866523873874,347.0732448248049,345.3617019366111,348.78478771299865
0.06604968970270271,347.0987936744027,345.3901953325081,348.80739201629734
0.06641272701801802,347.16327714451137,345.3913786987711,348.9351755902516
0.06677576433333335,347.27020332554815,345.46009365493734,349.08031299615897
0.06713880164864866,347.341516521825,345.47468328302523,349.20834976062474
0.06750183896396397,347.4174424081536,345.6502425982801,349.1846422180271
0.06786487627927928,347.5874580125628,345.69347697430453,349.4814390508211
0.06822791359459461,347.675739590186,345.79998949935646,349.5514896810156
0.06859095090990992,347.74855425924625,345.88063693493234,349.61647158356016
0.06895398822522524,347.793108269963,345.9005427492188,349.6856737907072
0.06931702554054055,347.7991038749636,345.9595374449011,349.63867030502604
0.06968006285585586,347.7896068020182,345.97200508465244,349.607208519384
0.07004310017117119,347.9114505279311,346.1176826534661,349.7052184023961
0.0704061374864865,347.9424624717073,346.1164513339967,349.7684736094179
0.07076917480180181,347.99045705405786,346.146498116767,349.8344159913487
0.07113221211711712,348.0831065336851,346.22584211770373,349.9403709496665
0.07149524943243245,348.08452873544593,346.2400217736373,349.92903569725456
0.07185828674774776,348.11268142238737,346.2675977675104,349.95776507726436
0.07222132406306307,348.14518508037906,346.28740890022584,350.0029612605323
0.07258436137837838,348.14526971533394,346.25166811123285,350.03887131943503
0.07294739869369371,348.24185847116286,346.34850663961686,350.13521030270886
0.07331043600900902,348.2273722887035,346.35778622929985,350.0969583481072
0.07367347332432433,348.26207494778816,346.24673792343424,350.2774119721421
0.07403651063963965,348.2964952283686,346.347027222136,350.2459632346012
0.07439954795495496,348.2695240649215,346.3312985713596,350.2077495584834
0.07476258527027028,348.34969671238025,346.3066734103202,350.39272001444033
0.0751256225855856,348.4100027523117,346.3801453637998,350.4398601408236
0.07548865990090091,348.5192320379487,346.51600373281997,350.52246034307746
0.07585169721621622,348.6327961250869,346.61931506913214,350.6462771810416
0.07621473453153155,348.58089687817085,346.5094114285335,350.6523823278082
0.07657777184684686,348.6169328072607,346.56546894533824,350.66839666918315
0.07694080916216217,348.7723777698556,346.66890031069363,350.8758552290176
0.07730384647747748,348.7961378770863,346.7169225525442,350.87535320162846
0.07766688379279281,348.71512791350625,346.5939135880796,350.8363422389329
0.07802992110810812,348.7322000513504,346.6032922743026,350.8611078283982
0.07839295842342343,348.78584467015173,346.67317184844455,350.8985174918589
0.07875599573873875,348.7654100641988,346.65398959841895,350.8768305299787
0.07911903305405406,348.6583932359666,346.5731439997534,350.74364247217983
0.07948207036936938,348.6399995308813,346.5335196645882,350.7464793971744
0.0798451076846847,348.80063178764425,346.61255835193884,350.98870522334965
0.08020814500000001,348.8878171969663,346.74853995410643,351.02709443982616
0.08057118231531532,348.8226882833023,346.63756725215114,351.0078093144534
0.08093421963063065,348.939593465975,346.67612560434077,351.20306132760925
0.08129725694594596,348.92623437746084,346.6511511776458,351.2013175772759
0.08166029426126127,349.1054338380935,346.98610159228997,351.22476608389707
0.08202333157657658,349.08487064725716,346.8585137577063,351.311227536808
0.08238636889189191,349.19807569013904,346.91597378303004,351.48017759724803
0.08274940620720722,349.0319246613085,346.7016460020285,351.3622033205885
0.08311244352252253,349.16578555169417,346.85055620210915,351.4810149012792
0.08347548083783785,349.2339405754905,346.84492565643313,351.6229554945479
0.08383851815315316,349.17413356311994,346.8626266851425,351.48564044109736
0.08420155546846848,349.28886042186286,347.022999106107,351.5547217376187
0.0845645927837838,349.3260220874921,347.036984341674,351.6150598333102
0.08492763009909911,349.3231650908539,347.03217882141325,351.6141513602945
0.08529066741441442,349.2184102278592,346.94894295731467,351.4878774984037
0.08565370472972975,349.3424954006158,347.14861122886595,351.53637957236566
0.08601674204504506,349.3716975133727,347.083354381067,351.66004064567835
0.08637977936036037,349.22383209022433,346.9460295448086,351.5016346356401
0.08674281667567568,349.1374940795602,346.8804575382766,351.39453062084385
0.08710585399099101,349.3048085650028,346.9729961559922,351.63662097401345
0.08746889130630632,349.228160573906,346.9234784545772,351.5328426932348
0.08783192862162163,349.219383882913,346.9717379721252,351.4670297937008
0.08819496593693694,349.3275646702999,347.00434307479844,351.6507862658014
0.08855800325225226,349.20183031050937,346.93761466138227,351.46604595963646
0.08892104056756758,349.21203077729916,346.97308468117296,351.45097687342536
0.0892840778828829,349.351294962309,346.9583361355689,351.7442537890491
0.08964711519819821,349.196159422134,346.9942447287563,351.39807411551163
0.09001015251351352,349.2735426163779,347.0479185038564,351.49916672889935
0.09037318982882885,349.2530563192728,346.91921616944467,351.5868964691009
0.09073622714414416,349.28486491373025,347.01748938397617,351.5522404434843
0.09109926445945947,349.35066809829397,347.04681568284883,351.6545205137391
0.09146230177477478,349.32988104365563,347.11185668153,351.54790540578125
0.09182533909009011,349.32132169357004,347.0899852057126,351.5526581814275
0.09218837640540542,349.28930773346366,347.01653833446056,351.56207713246675
0.09255141372072073,349.24481476901695,346.9703138041311,351.51931573390283
0.09291445103603604,349.26959598127746,346.9772451407005,351.5619468218544
0.09327748835135136,349.2850330830994,346.9614801714409,351.6085859947579
0.09364052566666668,349.3593265731047,347.0643222508687,351.65433089534065
0.094003562981982,349.37812454962597,347.11587470903436,351.6403743902176
0.0943666002972973,349.35733524883705,347.04010834818445,351.67456214948965
0.09472963761261262,349.3816771860729,346.96764310093073,351.7957112712151
0.09509267492792794,349.38822538592893,346.8978282085415,351.87862256331636
0.09545571224324326,349.4038630131803,346.9427495677636,351.86497645859697
0.09581874955855857,349.37359923582864,346.9964960640843,351.750702407573
0.09618178687387388,349.3746868422578,347.03027823818957,351.71909544632604
0.09654482418918921,349.4236672935659,347.09625949281644,351.7510750943154
0.09690786150450452,349.4133357932513,347.10871009400347,351.7179614924991
0.09727089881981983,349.4698872380112,347.1729233137524,351.76685116227003
0.09763393613513514,349.5661692790942,347.2523261609743,351.8800123972141
0.09799697345045046,349.4997467988512,347.20996481020217,351.7895287875003
0.09836001076576578,349.37678557441086,346.99811409200555,351.75545705681617
0.0987230480810811,349.39748040613733,346.879080829364,351.91587998291067
0.0990860853963964,349.39935282049544,346.8700845768138,351.9286210641771
0.09944912271171172,349.36227184219297,346.89801175021927,351.82653193416667
0.09981216002702704,349.29646667767116,346.8142611798852,351.77867217545713
0.10017519734234236,349.28269681669127,346.86757889211674,351.6978147412658
0.10053823465765767,349.2613494084343,346.87100763665205,351.6516911802165
0.10090127197297298,349.28414131614466,346.90523627890553,351.6630463533838
0.1012643092882883,349.3231683374338,346.93368890238355,351.71264777248405
0.10162734660360362,349.3064918900833,346.879719686068,351.7332640940986
0.10199038391891893,349.2813385484136,346.9040424279293,351.6586346688979
0.10235342123423424,349.258411010028,346.8644911655639,351.6523308544921
0.10271645854954956,349.1989438489771,346.77831994475747,351.6195677531967
0.10307949586486488,349.21670938216175,346.7354104420212,351.6980083223023
0.1034425331801802,349.1567630783817,346.66733897460017,351.6461871821632
0.1038055704954955,349.0963133283532,346.6283968261449,351.56422983056143
0.10416860781081082,349.1228975000401,346.6080940197552,351.637700980325
0.10453164512612614,349.1185742849035,346.5972828181141,351.6398657516929
0.10489468244144146,349.1070341588144,346.57735226073726,351.6367160568915
0.10525771975675677,349.077808780104,346.53976792623064,351.6158496339774
0.10562075707207208,349.08377070855477,346.5294445389399,351.6380968781696
0.1059837943873874,349.10277118641886,346.52798865567064,351.6775537171671
0.10634683170270272,349.03869066346823,346.4779943124787,351.59938701445776
0.10670986901801803,349.0055136627901,346.4698343377879,351.54119298779233
0.10707290633333334,348.97840155607497,346.4546832630849,351.502119849065
0.10743594364864865,349.03247244542007,346.4227666395532,351.64217825128696
0.10779898096396398,349.07024344339555,346.3881382335644,351.7523486532267
0.10816201827927929,349.09877735906406,346.4260116804723,351.7715430376558
0.1085250555945946,349.1632907428333,346.4932320664635,351.83334941920305
0.10888809290990992,349.05896645691126,346.43959936205545,351.6783335517671
0.10925113022522524,348.97138121460256,346.34370526973936,351.59905715946576
0.10961416754054056,348.99556434325416,346.17408856481444,351.8170401216939
0.10997720485585587,348.90199434699724,346.17024495713576,351.6337437368587
0.11034024217117118,348.8537167045764,346.24601747428954,351.4614159348633
0.1107032794864865,348.63873708321046,346.1517229544654,351.1257512119555
0.11106631680180182,348.65964759675046,346.1747549829628,351.14454021053814
0.11142935411711713,348.80273185949005,346.2112725346366,351.3941911843435
0.11179239143243244,348.8750969654898,346.2643651636849,351.48582876729466
0.11215542874774775,348.74972844632714,346.28614363979904,351.21331325285524
0.11251846606306308,348.8066567955306,346.247618268583,351.36569532247825
0.11288150337837839,348.80504152627657,346.1355607026394,351.47452234991374
0.1132445406936937,348.7344517068253,345.9825506091121,351.48635280453857
0.11360757800900902,348.6815002802754,345.8640208787697,351.49897968178107
0.11397061532432434,348.6420427691181,345.7550103794466,351.5290751587896
0.11433365263963965,348.7082204874149,345.9028726084382,351.5135683663916
0.11469668995495497,348.57161396107614,345.90372304751446,351.2395048746378
0.11505972727027028,348.3896264293682,345.8096054780178,350.96964738071864
0.1154227645855856,348.4132457494467,345.63663941818527,351.1898520807081
0.11578580190090092,348.6742845046096,345.82449113033977,351.52407787887944
0.11614883921621623,348.52518377075495,345.7153225006736,351.3350450408363
0.11651187653153154,348.25939748142935,345.6760369018182,350.8427580610405
0.11687491384684685,348.3436280870793,345.6950260501518,350.9922301240068
0.11723795116216218,348.5303990706775,345.6668284608964,351.3939696804586
0.11760098847747749,348.4316674462205,345.7127527953311,351.1505820971099
0.1179640257927928,348.1191770813957,345.50812063701807,350.7302335257734
0.11832706310810812,348.223647145055,345.4787181800719,350.9685761100381
0.11869010042342344,348.386378240736,345.4679965264115,351.3047599550605
0.11905313773873875,348.3702277364916,345.4979504169354,351.2425050560478
0.11941617505405407,348.35118907876205,345.51545309351746,351.18692506400663
0.11977921236936938,348.06080033122055,345.27770872207026,350.84389194037084
0.1201422496846847,348.2470312906913,345.38383558435385,351.1102269970288
0.12050528700000002,348.15872497190196,345.1206088666245,351.19684107717944
0.12086832431531533,347.7480018220972,345.03028010266144,350.46572354153295
0.12123136163063064,347.7237660610168,345.01842978390675,350.4291023381269
0.12159439894594595,347.8736219431572,344.93810582492387,350.80913806139057
0.12195743626126128,347.70842114870163,344.87848664793864,350.5383556494646
0.12232047357657659,347.53053614693806,344.8314973999884,350.22957489388773
0.1226835108918919,347.6012873346756,344.94718153478647,350.2553931345647
0.12304654820720722,347.4936686553354,344.8482061846287,350.1391311260421
0.12340958552252254,347.42619676358174,344.8019197735043,350.05047375365916
0.12377262283783785,347.3758055346869,344.76553104449175,349.986080024882
0.12413566015315317,347.3698533254039,344.70682476868666,350.0328818821211
0.12449869746846848,347.5020881917404,344.61621005332626,350.3879663301546
0.1248617347837838,347.5405726154963,344.5303212919297,350.55082393906287
0.1252247720990991,347.1627007996791,344.3817104695048,349.9436911298534
0.12558780941441441,347.16365497992103,344.4350212390675,349.89228872077456
0.12595084672972973,347.44101501674555,344.46602785168824,350.41600218180287
0.12631388404504504,347.63346377841697,344.42563029129514,350.8412972655388
0.12667692136036035,347.478258068892,344.45199175163293,350.50452438615105
0.12703995867567566,347.0614930609566,344.2389351768803,349.88405094503287
0.127402995990991,347.12568234504727,344.2710561287616,349.98030856133295
0.12776603330630631,347.4408872531089,344.3551412150106,350.5266332912072
0.12812907062162163,347.48976302623714,344.4567046228541,350.5228214296202
0.12849210793693694,347.0141613993695,344.2060035178918,349.82231928084724
0.12885514525225225,346.9904141663025,344.03831103162264,349.9425173009824
0.12921818256756756,347.26011475760106,344.01438528404924,350.5058442311529
0.12958121988288288,347.135432686437,344.05321249231366,350.21765288056037
0.1299442571981982,346.96251873929856,344.00080282043103,349.9242346581661
0.1303072945135135,346.766128507379,343.88589759553065,349.64635941922734
0.13067033182882884,346.97445433478254,343.94186435624465,350.0070443133204
0.13103336914414415,347.0974152014439,343.94434729040825,350.2504831124795
0.13139640645945946,346.886211211321,343.8053122283704,349.9671101942716
0.13175944377477478,346.6357175250365,343.66531484430953,349.6061202057635
0.1321224810900901,346.6363805592851,343.5584366172059,349.7143245013643
0.1324855184054054,346.73412793845864,343.44008778253635,350.02816809438093
0.1328485557207207,346.6159434390686,343.52040395947523,349.71148291866194
0.13321159303603602,346.44708655196536,343.46783871473065,349.42633438920006
0.13357463035135136,346.44704431308116,343.4142379924272,349.4798506337351
0.13393766766666668,346.30887147639834,343.03688063363995,349.5808623191567
0.134300704981982,346.26690070545317,342.96397642426064,349.5698249866457
0.1346637422972973,346.0644475402082,342.9512375216298,349.1776575587866
0.1350267796126126,345.9308493882845,342.9254954430885,348.93620333348053
0.13538981692792793,346.08433599063073,342.81696984941135,349.3517021318501
0.13575285424324324,346.0934473937326,342.74701830554164,349.4398764819236
0.13611589155855855,345.9154201156457,342.7333272303911,349.0975130009003
0.13647892887387386,345.7848382697257,342.68134325071566,348.88833328873574
0.1368419661891892,345.96370760987355,342.71832736851235,349.20908785123476
0.1372050035045045,345.864505033029,342.4378697989017,349.29114026715627
0.13756804081981983,345.6069916865951,342.27942085140603,348.9345625217842
0.13793107813513514,345.34362798741137,342.1542002031385,348.53305577168425
0.13829411545045045,345.53647449593734,342.19656343064935,348.87638556122533
0.13865715276576576,345.7702243839399,342.1654496284141,349.3749991394657
0.13902019008108107,345.70655111212733,342.13888690332664,349.274215320928
0.1393832273963964,345.5069761035475,342.09329669369725,348.9206555133978
0.1397462647117117,345.1646732778013,341.74193601920547,348.5874105363971
0.14010930202702704,345.2860587943909,341.65749755296196,348.91462003581984
0.14047233934234235,345.30559965509656,341.62107927992616,348.99012003026695
0.14083537665765766,345.1207756619368,341.643368950036,348.59818237383763
0.14119841397297297,344.68288077099197,341.41731772452954,347.9484438174544
0.1415614512882883,344.6163452980794,341.29669979395493,347.9359908022039
0.1419244886036036,344.6812990623102,341.10340256639597,348.2591955582244
0.1422875259189189,344.5590531044849,341.0839273185418,348.03417889042805
0.14265056323423422,344.6187225570114,341.26410009883773,347.97334501518503
0.14301360054954956,344.6386446324174,341.2650796527037,348.01220961213113
0.14337663786486488,344.69295248954325,341.1666854910913,348.2192194879952
0.1437396751801802,344.62161035931615,341.1397016409565,348.1035190776758
0.1441027124954955,344.4146803220332,341.05131783742115,347.7780428066452
0.1444657498108108,344.15970037242744,340.82537304777867,347.4940276970762
0.14482878712612612,344.1297033136955,340.55898652992056,347.7004200974704
0.14519182444144144,344.21761867418627,340.55257182047177,347.88266552790077
0.14555486175675675,343.9391033007056,340.3057511392887,347.5724554621225
0.14591789907207206,343.80493444227784,340.13997682821173,347.46989205634395
0.1462809363873874,343.71899105570674,339.9084132891816,347.52956882223185
0.1466439737027027,343.68960829399384,339.6602357262135,347.7189808617742
0.14700701101801802,343.5344779301177,339.45105517285106,347.61790068738435
0.14737004833333334,343.3157383743704,339.27239654089726,347.3590802078436
0.14773308564864865,343.2116437013332,339.07942482111855,347.3438625815478
0.14809612296396396,343.1873602517382,338.7985874834803,347.5761330199961
0.14845916027927927,343.1681280312624,338.680542403211,347.65571365931385
0.14882219759459459,342.94760764591905,338.50399568758525,347.39121960425285
0.1491852349099099,342.7474134132714,338.37082663810173,347.124000188441
0.14954827222522524,342.7557809964241,338.07999843762855,347.43156355521967
0.14991130954054055,342.50140457646125,337.7643641547422,347.2384449981803
0.15027434685585586,342.29911322045234,337.60174229408204,346.99648414682264
0.15063738417117117,342.00209748331974,337.443564579306,346.5606303873335
0.15100042148648649,341.8810784592596,337.19928499655475,346.5628719219644
0.1513634588018018,341.69827696435374,336.881757757312,346.51479617139546
0.1517264961171171,341.46219681038076,336.6102112983002,346.3141823224613
0.15208953343243242,341.1441633860687,336.3909171042657,345.8974096678717
0.15245257074774776,340.9119488625455,336.07995398401835,345.74394374107266
0.15281560806306307,340.7926704100196,335.7719374206663,345.8134033993729
0.1531786453783784,340.71680806449444,335.4850687189172,345.9485474100717
0.1535416826936937,340.46900886141674,335.284322026463,345.6536956963705
0.153904720009009,340.24627022110457,334.99954047932397,345.49299996288516
0.15426775732432432,340.1329387564958,334.65546607112844,345.6104114418631
0.15463079463963963,340.0145879643595,334.3079055483556,345.7212703803634
0.15499383195495495,339.66592838076303,333.93733480988647,345.3945219516396
0.15535686927027026,339.24545245343563,333.5925565353521,344.89834837151915
0.1557199065855856,339.46317189326004,333.42872643578835,345.49761735073173
0.1560829439009009,339.34929190473895,333.06842145654974,345.63016235292815
0.15644598121621622,339.0105918646988,332.66396733069496,345.3572163987027
0.15680901853153154,338.6167428014514,332.3084434475254,344.92504215537735
0.15717205584684685,338.29430589132784,332.0491809256412,344.53943085701445
0.15753509316216216,338.2502883219382,331.74600698772105,344.7545696561554
0.15789813047747747,338.06378925850896,331.46206933071784,344.6655091863001
0.15826116779279278,337.8274427805986,331.2059548722038,344.44893068899336
0.1586242051081081,337.4365186827804,330.8447802628019,344.02825710275886
0.15898724242342344,337.222848498516,330.4614040601064,343.98429293692556
0.15935027973873875,337.2443942462328,330.15146538864803,344.33732310381754
0.15971331705405406,337.0454035714429,329.86208820660494,344.2287189362808
0.16007635436936937,336.62219611107923,329.4661773057849,343.77821491637354
0.16043939168468468,336.1885259735572,329.0666255849777,343.3104263621367
0.160802429,335.95213436262213,328.69326117480927,343.211007550435
0.1611654663153153,335.9173681527483,328.38515625230076,343.4495800531958
0.16152850363063062,338.73314276465453,333.6001282473159,343.86615728199314
0.16189154094594596,338.515155554605,333.4362462676942,343.5940648415158
0.16225457826126127,338.0262764118371,333.14783106029256,342.90472176338164
0.16261761557657659,337.77448902241053,332.77877535552113,342.77020268929994
0.1629806528918919,337.5680274365771,332.3408953066725,342.7951595664817
0.1633436902072072,340.14313162877846,337.86601229695975,342.4202509605972
0.16370672752252252,340.06732786976994,338.4040212723979,341.73063446714195
0.16406976483783783,339.36521112662376,337.04155005341386,341.68887219983367
0.16443280215315315,339.5039808713395,337.17102053056936,341.8369412121096
0.16479583946846846,339.5584212602374,337.00318024530935,342.1136622751655
0.1651588767837838,339.1644437169593,336.62509093061294,341.7037965033056
0.1655219140990991,338.59448189747474,336.0778050234896,341.1111587714599
0.16588495141441442,338.2215411095762,335.65452146524575,340.78856075390667
0.16624798872972973,337.89604574780697,335.20952421102163,340.5825672845923
0.16661102604504505,337.85405947298403,335.02947584805264,340.6786430979154
0.16697406336036036,337.80718513421203,335.1568203299046,340.4575499385195
0.16733710067567567,337.64710800749606,335.2785610217916,340.01565499320054
0.16770013799099098,337.0745420482626,335.4666498610164,338.68243423550877
0.1680631753063063,337.06182725231764,334.78789025088537,339.3357642537499
0.16842621262162163,336.98203753450076,334.54346049316274,339.4206145758388
0.16878924993693695,336.94084474939797,334.68443287738455,339.1972566214114
0.16915228725225226,335.7789387255055,332.88582950852475,338.67204794248624
0.16951532456756757,335.07877138454484,332.0755289428934,338.08201382619626
0.16987836188288288,335.38264035379217,332.6320800359031,338.13320067168127
0.1702413991981982,335.56986350625556,333.1935771894086,337.94614982310253
0.1706044365135135,334.3358023774517,330.9875828879025,337.684021867001
0.17096747382882882,334.2634382263936,331.78425314720045,336.74262330558673
0.17133051114414416,333.74977079533534,331.8301272290672,335.66941436160346